Workbook

Sheet Hoja4
D14: SUELDO ACTUAL | E14: CARGA PATRONAL
D15: =+'sueldo actual '!O51 -> 683260.39 | E15: =+'sueldo actual '!T51 -> 304151.85
D17: SUELDO 12,000 | E17: CARGA PATRONAL
D18: =+'sueldo 12000'!O47 -> 757157.48 | E18: =+'sueldo 12000'!T47 -> 317009.33
D20: SUELDO 13,000 | E20: CARGA PATRONAL
D21: =+'sueldo 13000'!O47 -> 796643.12 | E21: =+'sueldo 13000'!T47 -> 318389.3

Sheet sueldo actual 
B2: PROYECCIÓN SUELDOS PARA PRESUPUESTO 2026
B5: CLAVE | C5: NOMBRE | D5: PUESTO | E5: Fecha inicial | F5: Fecha atual | G5: Años | H5: Dias Correspondientes | I5: SALARIO | J5: SUELDO | K5: PRIMA VACACIONAL | L5: DIAS FESTIVOS | M5: PRIMA DOMINICAL | N5: AGUINALDO | O5: TOTAL | P5: RETIRO, CESANTIA Y VEJEZ | Q5: INFONAVIT | R5: CUOTA IMSS | S5: IMPUESTO SOBRE NOMINA | T5: CARGA LABORAL
B6: 1 | C6: JORGE ALTAMIRANO ROMERO | D6: ADMINISTRACION | E6: 41827 | F6: 46387 | G6: =YEAR(F6)-YEAR(E6) -> 12 | H6: =VLOOKUP(G6,Hoja5!$A$3:$B$38,2,0) -> 24 | I6: 742.96 | J6: =I6*30.4166 -> 22598.317 | K6: =I6*H6*0.25/12 -> 371.48 | L6: 0 | M6: 0 | N6: =J6/2/12 -> 941.59655 | O6: =+(J6+K6+L6+M6+N6+U6) -> 23911.394 | P6: 3972.5717 | Q6: 2482.8573 | R6: 6164.5185 | S6: =(K6+L6+M6+N6+J6)*0.04 -> 956.45575 | T6: =+P6+Q6+R6+S6 -> 13576.403 | V6: 2000
B7: =B6+1 -> 2 | C7: ANGEL ISMAEL MERIDA FLORES | D7: JEFE CONSERJE | E7: 43831 | F7: 46387 | G7: =YEAR(F7)-YEAR(E7) -> 6 | H7: =VLOOKUP(G7,Hoja5!$A$3:$B$38,2,0) -> 22 | I7: 519.35 | J7: =I7*30.4166 -> 15796.861 | K7: =I7*H7*0.25/12 -> 238.03542 | L7: =I6*2*3/12 -> 371.48 | M7: =I7*0.25*2 -> 259.675 | N7: =J7/2/12 -> 658.20255 | O7: =+(J7+K7+L7+M7+N7+U7) -> 17324.254 | P7: 3972.5717 | Q7: 2482.8573 | R7: 6164.5185 | S7: =(K7+L7+M7+N7+J7)*0.04 -> 692.97017 | T7: =+P7+Q7+R7+S7 -> 13312.918 | V7: 2000
B8: =B7+1 -> 3 | C8: JOSE SANTOS PAZ GARCIA | D8: MANTENIMIENTO | E8: 42751 | F8: 46387 | G8: =YEAR(F8)-YEAR(E8) -> 9 | H8: =VLOOKUP(G8,Hoja5!$A$3:$B$38,2,0) -> 22 | I8: 402.62 | J8: =I8*30.4166 -> 12246.331 | K8: =I8*H8*0.25/12 -> 184.53417 | L8: =I7*2*3/12 -> 259.675 | M8: =I8*0.25*2 -> 201.31 | N8: =J8/2/12 -> 510.26381 | O8: =+(J8+K8+L8+M8+N8+U8) -> 13402.114 | P8: 3972.5717 | Q8: 2482.8573 | R8: 6164.5185 | S8: =(K8+L8+M8+N8+J8)*0.04 -> 536.08458 | T8: =+P8+Q8+R8+S8 -> 13156.032 | V8: 2000
B9: =B8+1 -> 4 | C9: SAINITE RICO VIVEROS | D9: CONSERJERIA | E9: 43831 | F9: 46387 | G9: =YEAR(F9)-YEAR(E9) -> 6 | H9: =VLOOKUP(G9,Hoja5!$A$3:$B$38,2,0) -> 22 | I9: 401.59 | J9: =I9*30.4166 -> 12215.002 | K9: =I9*H9*0.25/12 -> 184.06208 | L9: =I8*2*3/12 -> 201.31 | M9: =I9*0.25*2 -> 200.795 | N9: =J9/2/12 -> 508.95843 | O9: =+(J9+K9+L9+M9+N9+U9) -> 13310.128 | P9: 3972.5717 | Q9: 2482.8573 | R9: 6164.5185 | S9: =(K9+L9+M9+N9+J9)*0.04 -> 532.40512 | T9: =+P9+Q9+R9+S9 -> 13152.353 | V9: 2000
B10: =B9+1 -> 5 | C10: IVONNE TINOCO VEGA | D10: CONSERJERIA | E10: 43831 | F10: 46387 | G10: =YEAR(F10)-YEAR(E10) -> 6 | H10: =VLOOKUP(G10,Hoja5!$A$3:$B$38,2,0) -> 22 | I10: 382.13 | J10: =I10*30.4166 -> 11623.095 | K10: =I10*H10*0.25/12 -> 175.14292 | L10: =I9*2*3/12 -> 200.795 | M10: =I10*0.25*2 -> 191.065 | N10: =J10/2/12 -> 484.29564 | O10: =+(J10+K10+L10+M10+N10+U10) -> 12674.394 | P10: 3972.5717 | Q10: 2482.8573 | R10: 6164.5185 | S10: =(K10+L10+M10+N10+J10)*0.04 -> 506.97576 | T10: =+P10+Q10+R10+S10 -> 13126.923 | V10: 2000
B11: =B10+1 -> 6 | C11: ELIZABETH SANCHEZ MARTINEZ | D11: LUDOTECA | E11: 46189 | F11: 46387 | G11: =YEAR(F11)-YEAR(E11) -> 0 | H11: =VLOOKUP(G11,Hoja5!$A$3:$B$38,2,0) -> 12 | I11: 404.2284 | J11: =I11*30.4166 -> 12295.254 | K11: =I11*H11*0.25/12 -> 101.0571 | L11: =I10*2*3/12 -> 191.065 | M11: =I11*0.25*2 -> 202.1142 | N11: =J11/2/12 -> 512.30223 | O11: =+(J11+K11+L11+M11+N11+U11) -> 13301.792 | P11: 1358.8529 | Q11: 849.28305 | R11: 2114.8155 | S11: =(K11+L11+M11+N11+J11)*0.04 -> 532.07168 | T11: =+P11+Q11+R11+S11 -> 4855.0231 | V11: 2000
B12: =B11+1 -> 7 | C12: ANAYELI ARAUJO TAVIRA | D12: CONSERJERIA | E12: 44151 | F12: 46387 | G12: =YEAR(F12)-YEAR(E12) -> 6 | H12: =VLOOKUP(G12,Hoja5!$A$3:$B$38,2,0) -> 22 | I12: 382.13 | J12: =I12*30.4166 -> 11623.095 | K12: =I12*H12*0.25/12 -> 175.14292 | L12: =I11*2*3/12 -> 202.1142 | M12: =I12*0.25*2 -> 191.065 | N12: =J12/2/12 -> 484.29564 | O12: =+(J12+K12+L12+M12+N12+U12) -> 12675.713 | P12: 1598.52 | Q12: 999.075 | R12: 2265.9 | S12: =(K12+L12+M12+N12+J12)*0.04 -> 507.02852 | T12: =+P12+Q12+R12+S12 -> 5370.5235 | V12: 2000
B13: =B12+1 -> 8 | C13: MARIA ELENA ARREOLA SANTOYO | D13: CONSERJERIA | E13: 44278 | F13: 46387 | G13: =YEAR(F13)-YEAR(E13) -> 5 | H13: =VLOOKUP(G13,Hoja5!$A$3:$B$38,2,0) -> 20 | I13: 382.13 | J13: =I13*30.4166 -> 11623.095 | K13: =I13*H13*0.25/12 -> 159.22083 | L13: =I12*2*3/12 -> 191.065 | M13: =I13*0.25*2 -> 191.065 | N13: =J13/2/12 -> 484.29564 | O13: =+(J13+K13+L13+M13+N13+U13) -> 12648.742 | P13: 1598.52 | Q13: 999.075 | R13: 2265.9 | S13: =(K13+L13+M13+N13+J13)*0.04 -> 505.94967 | T13: =+P13+Q13+R13+S13 -> 5369.4447 | V13: 2000
B14: =B13+1 -> 9 | C14: ARTURO IVAN ORDOÑEZ ESPINOSA | D14: ADMINISTRACION | E14: 44698 | F14: 46387 | G14: =YEAR(F14)-YEAR(E14) -> 4 | H14: =VLOOKUP(G14,Hoja5!$A$3:$B$38,2,0) -> 18 | I14: 489.56 | J14: =I14*30.4166 -> 14890.751 | K14: =I14*H14*0.25/12 -> 183.585 | L14: =I13*2*3/12 -> 191.065 | M14: =I14*0.25*2 -> 244.78 | N14: =J14/2/12 -> 620.44795 | O14: =+(J14+K14+L14+M14+N14+U14) -> 16130.629 | P14: 1358.8529 | Q14: 849.28305 | R14: 2114.8155 | S14: =(K14+L14+M14+N14+J14)*0.04 -> 645.22515 | T14: =+P14+Q14+R14+S14 -> 4968.1766 | V14: 2000
B15: =B14+1 -> 10 | C15: ALEJANDRO CERDA GOMEZ | D15: JEFE MANTENIMIENTO | E15: 44758 | F15: 46387 | G15: =YEAR(F15)-YEAR(E15) -> 4 | H15: =VLOOKUP(G15,Hoja5!$A$3:$B$38,2,0) -> 18 | I15: 685.5704 | J15: =I15*30.4166 -> 20852.721 | K15: =I15*H15*0.25/12 -> 257.0889 | L15: 0 | M15: 0 | N15: =J15/2/12 -> 868.86336 | O15: =+(J15+K15+L15+M15+N15+U15) -> 21978.673 | P15: 1358.8529 | Q15: 849.28305 | R15: 2114.8155 | S15: =(K15+L15+M15+N15+J15)*0.04 -> 879.14692 | T15: =+P15+Q15+R15+S15 -> 5202.0983 | V15: 2000
B16: =B15+1 -> 11 | C16: RODRIGO SANCHEZ SALVADOR | D16: BELLBOY | E16: 44789 | F16: 46387 | G16: =YEAR(F16)-YEAR(E16) -> 4 | H16: =VLOOKUP(G16,Hoja5!$A$3:$B$38,2,0) -> 18 | I16: 345.63 | J16: =I16*30.4166 -> 10512.889 | K16: =I16*H16*0.25/12 -> 129.61125 | L16: =I6*2*3/12 -> 371.48 | M16: =I16*0.25*2 -> 172.815 | N16: =J16/2/12 -> 438.03706 | O16: =+(J16+K16+L16+M16+N16+U16) -> 11624.833 | P16: 1358.8529 | Q16: 849.28305 | R16: 2114.8155 | S16: =(K16+L16+M16+N16+J16)*0.04 -> 464.99331 | T16: =+P16+Q16+R16+S16 -> 4787.9447 | V16: 2000
B17: =B16+1 -> 12 | C17: JORGE ALEJANDRO LEZAMA FLORES | D17: SISTEMAS | E17: 45979 | F17: 46387 | G17: =YEAR(F17)-YEAR(E17) -> 1 | H17: =VLOOKUP(G17,Hoja5!$A$3:$B$38,2,0) -> 12 | I17: 576.9667 | J17: =I17*30.4166 -> 17549.365 | K17: =I17*H17*0.25/12 -> 144.24167 | L17: =I7*2*3/12 -> 259.675 | M17: =I17*0.25*2 -> 288.48335 | N17: =J17/2/12 -> 731.22356 | O17: =+(J17+K17+L17+M17+N17+U17) -> 18972.989 | P17: 1358.8529 | Q17: 849.28305 | R17: 2114.8155 | S17: =(K17+L17+M17+N17+J17)*0.04 -> 758.91956 | T17: =+P17+Q17+R17+S17 -> 5081.871 | V17: 2000
B18: =B17+1 -> 13 | C18: PABLO LOPEZ CRUZ | D18: ADMINISTRACION | E18: 45017 | F18: 46387 | G18: =YEAR(F18)-YEAR(E18) -> 3 | H18: =VLOOKUP(G18,Hoja5!$A$3:$B$38,2,0) -> 16 | I18: 917.93 | J18: =I18*30.4166 -> 27920.31 | K18: =I18*H18*0.25/12 -> 305.97667 | L18: =I8*2*3/12 -> 201.31 | M18: =I18*0.25*2 -> 458.965 | N18: =J18/2/12 -> 1163.3462 | O18: =+(J18+K18+L18+M18+N18+U18) -> 30049.908 | P18: 1358.8529 | Q18: 849.28305 | R18: 2114.8155 | S18: =(K18+L18+M18+N18+J18)*0.04 -> 1201.9963 | T18: =+P18+Q18+R18+S18 -> 5524.9477 | V18: 2000
B19: =B18+1 -> 14 | C19: DIEGO ARMANDO LOPEZ GONZALEZ | D19: BELLBOY | E19: 45083 | F19: 46387 | G19: =YEAR(F19)-YEAR(E19) -> 3 | H19: =VLOOKUP(G19,Hoja5!$A$3:$B$38,2,0) -> 16 | I19: 345.63 | J19: =I19*30.4166 -> 10512.889 | K19: =I19*H19*0.25/12 -> 115.21 | L19: =I9*2*3/12 -> 200.795 | M19: =I19*0.25*2 -> 172.815 | N19: =J19/2/12 -> 438.03706 | O19: =+(J19+K19+L19+M19+N19+U19) -> 11439.747 | P19: 1358.8529 | Q19: 849.28305 | R19: 2114.8155 | S19: =(K19+L19+M19+N19+J19)*0.04 -> 457.58986 | T19: =+P19+Q19+R19+S19 -> 4780.5413 | V19: 2000
B20: =B19+1 -> 15 | C20: LISSETTE GONZALEZ ESTRADA | D20: ADMINISTRACION | E20: 45114 | F20: 46387 | G20: =YEAR(F20)-YEAR(E20) -> 3 | H20: =VLOOKUP(G20,Hoja5!$A$3:$B$38,2,0) -> 16 | I20: 449.4714 | J20: =I20*30.4166 -> 13671.392 | K20: =I20*H20*0.25/12 -> 149.8238 | L20: 0 | M20: 0 | N20: =J20/2/12 -> 569.64132 | O20: =+(J20+K20+L20+M20+N20+U20) -> 14390.857 | P20: 3972.5717 | Q20: 2482.8573 | R20: 6164.5185 | S20: =(K20+L20+M20+N20+J20)*0.04 -> 575.63428 | T20: =+P20+Q20+R20+S20 -> 13195.582 | V20: 2000
B21: =B20+1 -> 16 | C21: MIGUEL ROBELO MORELOS | D21: MANTENIMIENTO | E21: 45145 | F21: 46387 | G21: =YEAR(F21)-YEAR(E21) -> 3 | H21: =VLOOKUP(G21,Hoja5!$A$3:$B$38,2,0) -> 16 | I21: 413 | J21: =I21*30.4166 -> 12562.056 | K21: =I21*H21*0.25/12 -> 137.66667 | L21: =I6*2*3/12 -> 371.48 | M21: =I21*0.25*2 -> 206.5 | N21: =J21/2/12 -> 523.41899 | O21: =+(J21+K21+L21+M21+N21+U21) -> 13801.121 | P21: 1358.8529 | Q21: 849.28305 | R21: 2114.8155 | S21: =(K21+L21+M21+N21+J21)*0.04 -> 552.04486 | T21: =+P21+Q21+R21+S21 -> 4874.9963 | V21: 2000
B22: =B21+1 -> 17 | C22: BENJAMIN MACEDONIO MEJIA | D22: MANTENIMIENTO | E22: 45253 | F22: 46387 | G22: =YEAR(F22)-YEAR(E22) -> 3 | H22: =VLOOKUP(G22,Hoja5!$A$3:$B$38,2,0) -> 16 | I22: 362.9618 | J22: =I22*30.4166 -> 11040.064 | K22: =I22*H22*0.25/12 -> 120.98727 | L22: 0 | M22: =I22*0.25*2 -> 181.4809 | N22: =J22/2/12 -> 460.00266 | O22: =+(J22+K22+L22+M22+N22+U22) -> 11802.535 | P22: 1358.8529 | Q22: 849.28305 | R22: 2114.8155 | S22: =(K22+L22+M22+N22+J22)*0.04 -> 472.10139 | T22: =+P22+Q22+R22+S22 -> 4795.0528 | V22: 2000
B23: =B22+1 -> 18 | C23: JAVIER LOPEZ SANTOS | D23: MANTENIMIENTO | E23: 45505 | F23: 46387 | G23: =YEAR(F23)-YEAR(E23) -> 2 | H23: =VLOOKUP(G23,Hoja5!$A$3:$B$38,2,0) -> 14 | I23: 383.24 | J23: =I23*30.4166 -> 11656.858 | K23: =I23*H23*0.25/12 -> 111.77833 | L23: =I6*2*3/12 -> 371.48 | M23: =I23*0.25*2 -> 191.62 | N23: =J23/2/12 -> 485.70241 | O23: =+(J23+K23+L23+M23+N23+U23) -> 12817.439 | P23: 1358.8529 | Q23: 849.28305 | R23: 2114.8155 | S23: =(K23+L23+M23+N23+J23)*0.04 -> 512.69754 | T23: =+P23+Q23+R23+S23 -> 4835.649 | V23: 2000
B24: =B23+1 -> 19 | C24: ANGEL MAURICIO MIRELES ROMERO | D24: CONSERJERIA | E24: 45541 | F24: 46387 | G24: =YEAR(F24)-YEAR(E24) -> 2 | H24: =VLOOKUP(G24,Hoja5!$A$3:$B$38,2,0) -> 14 | I24: 383.24 | J24: =I24*30.4166 -> 11656.858 | K24: =I24*H24*0.25/12 -> 111.77833 | L24: =I7*2*3/12 -> 259.675 | M24: =I24*0.25*2 -> 191.62 | N24: =J24/2/12 -> 485.70241 | O24: =+(J24+K24+L24+M24+N24+U24) -> 12705.634 | P24: 1358.8529 | Q24: 849.28305 | R24: 2114.8155 | S24: =(K24+L24+M24+N24+J24)*0.04 -> 508.22534 | T24: =+P24+Q24+R24+S24 -> 4831.1768 | V24: 2000
B25: =B24+1 -> 20 | C25: NISSIM YADIHEL MORA OLMOS | D25: ADMINISTRACION | E25: 45551 | F25: 46387 | G25: =YEAR(F25)-YEAR(E25) -> 2 | H25: =VLOOKUP(G25,Hoja5!$A$3:$B$38,2,0) -> 14 | I25: 1055.3154 | J25: =I25*30.4166 -> 32099.106 | K25: =I25*H25*0.25/12 -> 307.80032 | L25: =I8*2*3/12 -> 201.31 | M25: =I25*0.25*2 -> 527.6577 | N25: =J25/2/12 -> 1337.4628 | O25: =+(J25+K25+L25+M25+N25+U25) -> 34473.337 | P25: 1358.8529 | Q25: 849.28305 | R25: 2114.8155 | S25: =(K25+L25+M25+N25+J25)*0.04 -> 1378.9335 | T25: =+P25+Q25+R25+S25 -> 5701.8849 | V25: 2000
B26: =B25+1 -> 21 | C26: ALFREDO ANDRES RESENDIZ | D26: ADMINISTRACION | E26: 45618 | F26: 46387 | G26: =YEAR(F26)-YEAR(E26) -> 2 | H26: =VLOOKUP(G26,Hoja5!$A$3:$B$38,2,0) -> 14 | I26: 383.24 | J26: =I26*30.4166 -> 11656.858 | K26: =I26*H26*0.25/12 -> 111.77833 | L26: =I9*2*3/12 -> 200.795 | M26: =I26*0.25*2 -> 191.62 | N26: =J26/2/12 -> 485.70241 | O26: =+(J26+K26+L26+M26+N26+U26) -> 12646.754 | P26: 994.85232 | Q26: 621.7827 | R26: 1505.9835 | S26: =(K26+L26+M26+N26+J26)*0.04 -> 505.87014 | T26: =+P26+Q26+R26+S26 -> 3628.4887 | V26: 2000
B27: =B26+1 -> 22 | C27: LEONARDO ISMAEL SANCHEZ MARTINEZ | D27: ADMINISTRACION | E27: 45717 | F27: 46387 | G27: =YEAR(F27)-YEAR(E27) -> 1 | H27: =VLOOKUP(G27,Hoja5!$A$3:$B$38,2,0) -> 12 | I27: 966.58 | J27: =I27*30.4166 -> 29400.077 | K27: =I27*H27*0.25/12 -> 241.645 | L27: =I10*2*3/12 -> 191.065 | M27: =I27*0.25*2 -> 483.29 | N27: =J27/2/12 -> 1225.0032 | O27: =+(J27+K27+L27+M27+N27+U27) -> 31541.08 | P27: 1358.8529 | Q27: 849.28305 | R27: 2114.8155 | S27: =(K27+L27+M27+N27+J27)*0.04 -> 1261.6432 | T27: =+P27+Q27+R27+S27 -> 5584.5946 | V27: 2000
B28: =B27+1 -> 23 | C28: ANGELA MEZA VINIEGRA | D28: LUDOTECA | E28: 46174 | F28: 46387 | G28: =YEAR(F28)-YEAR(E28) -> 0 | H28: =VLOOKUP(G28,Hoja5!$A$3:$B$38,2,0) -> 12 | I28: 575.3449 | J28: =I28*30.4166 -> 17500.036 | K28: =I28*H28*0.25/12 -> 143.83623 | L28: =I11*2*3/12 -> 202.1142 | M28: =I28*0.25*2 -> 287.67245 | N28: =J28/2/12 -> 729.16815 | O28: =+(J28+K28+L28+M28+N28+U28) -> 18862.827 | P28: 1358.8529 | Q28: 849.28305 | R28: 2114.8155 | S28: =(K28+L28+M28+N28+J28)*0.04 -> 754.51307 | T28: =+P28+Q28+R28+S28 -> 5077.4645 | V28: 2000
B29: =B28+1 -> 24 | C29: EDWIN DE JESUS CIAU MAZUM | D29: ADMINISTRACION | E29: 45763 | F29: 46387 | G29: =YEAR(F29)-YEAR(E29) -> 1 | H29: =VLOOKUP(G29,Hoja5!$A$3:$B$38,2,0) -> 12 | I29: 794.07 | J29: =I29*30.4166 -> 24152.91 | K29: =I29*H29*0.25/12 -> 198.5175 | L29: =I12*2*3/12 -> 191.065 | M29: =I29*0.25*2 -> 397.035 | N29: =J29/2/12 -> 1006.3712 | O29: =+(J29+K29+L29+M29+N29+U29) -> 25945.898 | P29: 1358.8529 | Q29: 849.28305 | R29: 2114.8155 | S29: =(K29+L29+M29+N29+J29)*0.04 -> 1037.8359 | T29: =+P29+Q29+R29+S29 -> 5360.7874 | V29: 2000
B30: =B29+1 -> 25 | C30: ALEJANDRO REYES PEDRAZA GONZALEZ | D30: MANTENIMIENTO | E30: 45877 | F30: 46387 | G30: =YEAR(F30)-YEAR(E30) -> 1 | H30: =VLOOKUP(G30,Hoja5!$A$3:$B$38,2,0) -> 12 | I30: 367.7954 | J30: =I30*30.4166 -> 11187.086 | K30: =I30*H30*0.25/12 -> 91.94885 | L30: 0 | M30: 0 | N30: =J30/2/12 -> 466.12857 | O30: =+(J30+K30+L30+M30+N30+U30) -> 11745.163 | P30: 3972.5717 | Q30: 2482.8573 | R30: 6164.5185 | S30: =(K30+L30+M30+N30+J30)*0.04 -> 469.80652 | T30: =+P30+Q30+R30+S30 -> 13089.754 | V30: 2000
B31: =B30+1 -> 26 | C31: LILIA KARINA SANDOVAL RODRIGUEZ | D31: LUDOTECA | E31: 46235 | F31: 46387 | G31: =YEAR(F31)-YEAR(E31) -> 0 | H31: =VLOOKUP(G31,Hoja5!$A$3:$B$38,2,0) -> 12 | I31: 575.3426 | J31: =I31*30.4166 -> 17499.966 | K31: =I31*H31*0.25/12 -> 143.83565 | L31: =I6*2*3/12 -> 371.48 | M31: =I31*0.25*2 -> 287.6713 | N31: =J31/2/12 -> 729.16524 | O31: =+(J31+K31+L31+M31+N31+U31) -> 19032.118 | P31: 941.44512 | Q31: 588.4032 | R31: 1456.35 | S31: =(K31+L31+M31+N31+J31)*0.04 -> 761.28472 | T31: =+P31+Q31+R31+S31 -> 3747.483 | V31: 2000
B32: =B31+1 -> 27 | C32: MARIA DEL CARMEN HERNANDEZ DE ANDA | D32: LUDOTECA | E32: 45983 | F32: 46387 | G32: =YEAR(F32)-YEAR(E32) -> 1 | H32: =VLOOKUP(G32,Hoja5!$A$3:$B$38,2,0) -> 12 | I32: 575.3426 | J32: =I32*30.4166 -> 17499.966 | K32: =I32*H32*0.25/12 -> 143.83565 | L32: =I7*2*3/12 -> 259.675 | M32: =I32*0.25*2 -> 287.6713 | N32: =J32/2/12 -> 729.16524 | O32: =+(J32+K32+L32+M32+N32+U32) -> 18920.313 | P32: 3972.5717 | Q32: 2482.8573 | R32: 6164.5185 | S32: =(K32+L32+M32+N32+J32)*0.04 -> 756.81252 | T32: =+P32+Q32+R32+S32 -> 13376.76 | V32: 2000
B33: =B32+1 -> 28 | C33: JAZMIN SORIANO BARRERA | D33: LUDOTECA | E33: 46054 | F33: 46387 | G33: =YEAR(F33)-YEAR(E33) -> 0 | H33: =VLOOKUP(G33,Hoja5!$A$3:$B$38,2,0) -> 12 | I33: 401.5565 | J33: =I33*30.4166 -> 12213.983 | K33: =I33*H33*0.25/12 -> 100.38912 | L33: 0 | M33: 0 | N33: =J33/2/12 -> 508.91598 | O33: =+(J33+K33+L33+M33+N33+U33) -> 12823.289 | P33: 1657.656 | Q33: 1036.035 | R33: 2486.4 | S33: =(K33+L33+M33+N33+J33)*0.04 -> 512.93154 | T33: =+P33+Q33+R33+S33 -> 5693.0225 | V33: 2000
B34: =B33+1 -> 29 | C34: OSCAR RAYMUNDO GRAJALES | D34: MANTENIMIENTO | E34: 46054 | F34: 46387 | G34: =YEAR(F34)-YEAR(E34) -> 0 | H34: =VLOOKUP(G34,Hoja5!$A$3:$B$38,2,0) -> 12 | I34: 345.63 | J34: =I34*30.4166 -> 10512.889 | K34: =I34*H34*0.25/12 -> 86.4075 | L34: =I9*2*3/12 -> 200.795 | M34: =I34*0.25*2 -> 172.815 | N34: =J34/2/12 -> 438.03706 | O34: =+(J34+K34+L34+M34+N34+U34) -> 11410.944 | P34: 1358.8529 | Q34: 849.28305 | R34: 2114.8155 | S34: =(K34+L34+M34+N34+J34)*0.04 -> 456.43776 | T34: =+P34+Q34+R34+S34 -> 4779.3892 | V34: 2000
B35: =B34+1 -> 30 | C35: REY DAVID MELGAR TAPIA | D35: MANTENIMIENTO | E35: 46063 | F35: 46387 | G35: =YEAR(F35)-YEAR(E35) -> 0 | H35: =VLOOKUP(G35,Hoja5!$A$3:$B$38,2,0) -> 12 | I35: 345.63 | J35: =I35*30.4166 -> 10512.889 | K35: =I35*H35*0.25/12 -> 86.4075 | L35: =I10*2*3/12 -> 191.065 | M35: =I35*0.25*2 -> 172.815 | N35: =J35/2/12 -> 438.03706 | O35: =+(J35+K35+L35+M35+N35+U35) -> 11401.214 | P35: 941.44512 | Q35: 588.4032 | R35: 1456.35 | S35: =(K35+L35+M35+N35+J35)*0.04 -> 456.04856 | T35: =+P35+Q35+R35+S35 -> 3442.2469 | V35: 2000
B36: =B35+1 -> 31 | C36: RICARDO ROSALES MARTINEZ | D36: MANTENIMIENTO | E36: 46062 | F36: 46387 | G36: =YEAR(F36)-YEAR(E36) -> 0 | H36: =VLOOKUP(G36,Hoja5!$A$3:$B$38,2,0) -> 12 | I36: 345.63 | J36: =I36*30.4166 -> 10512.889 | K36: =I36*H36*0.25/12 -> 86.4075 | L36: 0 | M36: =I36*0.25*2 -> 172.815 | N36: =J36/2/12 -> 438.03706 | O36: =+(J36+K36+L36+M36+N36+U36) -> 11210.149 | P36: 3972.5717 | Q36: 2482.8573 | R36: 6164.5185 | S36: =(K36+L36+M36+N36+J36)*0.04 -> 448.40596 | T36: =+P36+Q36+R36+S36 -> 13068.353 | V36: 2000
B37: =B36+1 -> 32 | C37: ELIAS LOPEZ LINA | D37: MANTENIMIENTO | E37: 46082 | F37: 46387 | G37: =YEAR(F37)-YEAR(E37) -> 0 | H37: =VLOOKUP(G37,Hoja5!$A$3:$B$38,2,0) -> 12 | I37: 345.63 | J37: =I37*30.4166 -> 10512.889 | K37: =I37*H37*0.25/12 -> 86.4075 | L37: =I12*2*3/12 -> 191.065 | M37: =I37*0.25*2 -> 172.815 | N37: =J37/2/12 -> 438.03706 | O37: =+(J37+K37+L37+M37+N37+U37) -> 11401.214 | P37: 1358.8529 | Q37: 849.28305 | R37: 2114.8155 | S37: =(K37+L37+M37+N37+J37)*0.04 -> 456.04856 | T37: =+P37+Q37+R37+S37 -> 4779 | V37: 2000
B38: =B37+1 -> 33 | C38: ISRAEL ANGELES RIOS | D38: MANTENIMIENTO | E38: 46174 | F38: 46387 | G38: =YEAR(F38)-YEAR(E38) -> 0 | H38: =VLOOKUP(G38,Hoja5!$A$3:$B$38,2,0) -> 12 | I38: 345.63 | J38: =I38*30.4166 -> 10512.889 | K38: =I38*H38*0.25/12 -> 86.4075 | L38: =I13*2*3/12 -> 191.065 | M38: =I38*0.25*2 -> 172.815 | N38: =J38/2/12 -> 438.03706 | O38: =+(J38+K38+L38+M38+N38+U38) -> 11401.214 | P38: 1358.8529 | Q38: 849.28305 | R38: 2114.8155 | S38: =(K38+L38+M38+N38+J38)*0.04 -> 456.04856 | T38: =+P38+Q38+R38+S38 -> 4779 | V38: 2000
B39: =B38+1 -> 34 | C39: RICARDO ARTURO AGUIRRE RIVERA | D39: MANTENIMIENTO | E39: 46204 | F39: 46387 | G39: =YEAR(F39)-YEAR(E39) -> 0 | H39: =VLOOKUP(G39,Hoja5!$A$3:$B$38,2,0) -> 12 | I39: 345.63 | J39: =I39*30.4166 -> 10512.889 | K39: =I39*H39*0.25/12 -> 86.4075 | L39: =I14*2*3/12 -> 244.78 | M39: =I39*0.25*2 -> 172.815 | N39: =J39/2/12 -> 438.03706 | O39: =+(J39+K39+L39+M39+N39+U39) -> 11454.929 | P39: 1358.8529 | Q39: 849.28305 | R39: 2114.8155 | S39: =(K39+L39+M39+N39+J39)*0.04 -> 458.19716 | T39: =+P39+Q39+R39+S39 -> 4781.1486 | V39: 2000
B40: =B39+1 -> 35 | C40: VICTOR HUGO CORONA ALVARADO | D40: CONSERJERIA | E40: 46209 | F40: 46387 | G40: =YEAR(F40)-YEAR(E40) -> 0 | H40: =VLOOKUP(G40,Hoja5!$A$3:$B$38,2,0) -> 12 | I40: 345.63 | J40: =I40*30.4166 -> 10512.889 | K40: =I40*H40*0.25/12 -> 86.4075 | L40: =I15*2*3/12 -> 342.7852 | M40: =I40*0.25*2 -> 172.815 | N40: =J40/2/12 -> 438.03706 | O40: =+(J40+K40+L40+M40+N40+U40) -> 11552.934 | P40: 1358.8529 | Q40: 849.28305 | R40: 2114.8155 | S40: =(K40+L40+M40+N40+J40)*0.04 -> 462.11737 | T40: =+P40+Q40+R40+S40 -> 4785.0688 | V40: 2000
B41: =B40+1 -> 36 | C41: MARCELINO ROMERO ALBA | D41: CONSERJERIA | E41: 46210 | F41: 46387 | G41: =YEAR(F41)-YEAR(E41) -> 0 | H41: =VLOOKUP(G41,Hoja5!$A$3:$B$38,2,0) -> 12 | I41: 345.63 | J41: =I41*30.4166 -> 10512.889 | K41: =I41*H41*0.25/12 -> 86.4075 | L41: =I16*2*3/12 -> 172.815 | M41: =I41*0.25*2 -> 172.815 | N41: =J41/2/12 -> 438.03706 | O41: =+(J41+K41+L41+M41+N41+U41) -> 11382.964 | P41: 1358.8529 | Q41: 849.28305 | R41: 2114.8155 | S41: =(K41+L41+M41+N41+J41)*0.04 -> 455.31856 | T41: =+P41+Q41+R41+S41 -> 4778.27 | V41: 2000
B42: =B41+1 -> 37 | C42: JOSE LUIS CARBO ROSAS | D42: CONSERJERIA | E42: 46219 | F42: 46387 | G42: =YEAR(F42)-YEAR(E42) -> 0 | H42: =VLOOKUP(G42,Hoja5!$A$3:$B$38,2,0) -> 12 | I42: 345.63 | J42: =I42*30.4166 -> 10512.889 | K42: =I42*H42*0.25/12 -> 86.4075 | L42: =I17*2*3/12 -> 288.48335 | M42: =I42*0.25*2 -> 172.815 | N42: =J42/2/12 -> 438.03706 | O42: =+(J42+K42+L42+M42+N42+U42) -> 11498.632 | P42: 1358.8529 | Q42: 849.28305 | R42: 2114.8155 | S42: =(K42+L42+M42+N42+J42)*0.04 -> 459.94529 | T42: =+P42+Q42+R42+S42 -> 4782.8967 | V42: 2000
B43: =B42+1 -> 38 | C43: JOSE ALBERTO GONZALEZ LOPEZ | D43: MANTENIMIENTO | E43: 46235 | F43: 46387 | G43: =YEAR(F43)-YEAR(E43) -> 0 | H43: =VLOOKUP(G43,Hoja5!$A$3:$B$38,2,0) -> 12 | I43: 526.21 | J43: =I43*30.4166 -> 16005.519 | K43: =I43*H43*0.25/12 -> 131.5525 | L43: =I18*2*3/12 -> 458.965 | M43: =I43*0.25*2 -> 263.105 | N43: =J43/2/12 -> 666.89663 | O43: =+(J43+K43+L43+M43+N43+U43) -> 17526.038 | P43: 1894.2 | Q43: 1183.875 | R43: 3062.85 | S43: =(K43+L43+M43+N43+J43)*0.04 -> 701.04153 | T43: =+P43+Q43+R43+S43 -> 6841.9665 | V43: 2000
...

Sheet sueldo 12000
B1: CLAVE | C1: NOMBRE | D1: PUESTO | E1: Fecha inicial | F1: Fecha atual | G1: Años | H1: Dias Correspondientes | I1: SALARIO | J1: SUELDO | K1: PRIMA VACACIONAL | L1: DIAS FESTIVOS | M1: PRIMA DOMINICAL | N1: AGUINALDO | O1: TOTAL | P1: RETIRO, CESANTIA Y VEJEZ | Q1: INFONAVIT | R1: CUOTA IMSS | S1: IMPUESTO SOBRE NOMINA | T1: CARGA LABORAL
B2: 1 | C2: JORGE ALTAMIRANO ROMERO | D2: ADMINISTRACION | E2: 41827 | F2: 46387 | G2: =YEAR(F2)-YEAR(E2) -> 12 | H2: =VLOOKUP(G2,Hoja5!$A$3:$B$38,2,0) -> 24 | I2: 742.96 | J2: =I2*30.4166 -> 22598.317 | K2: =I2*H2*0.25/12 -> 371.48 | L2: 0 | M2: 0 | N2: =J2/2/12 -> 941.59655 | O2: =+(J2+K2+L2+M2+N2+U2) -> 23911.394 | P2: 3972.5717 | Q2: 2482.8573 | R2: 6164.5185 | S2: =(K2+L2+M2+N2+J2)*0.04 -> 956.45575 | T2: =+P2+Q2+R2+S2 -> 13576.403 | V2: 2000
B3: =B2+1 -> 2 | C3: ARTURO IVAN ORDOÑEZ ESPINOSA | D3: ADMINISTRACION | E3: 44698 | F3: 46387 | G3: =YEAR(F3)-YEAR(E3) -> 4 | H3: =VLOOKUP(G3,Hoja5!$A$3:$B$38,2,0) -> 18 | I3: 489.56 | J3: =I3*30.4166 -> 14890.751 | K3: =I3*H3*0.25/12 -> 183.585 | L3: =I2*2*3/12 -> 371.48 | M3: =I3*0.25*2 -> 244.78 | N3: =J3/2/12 -> 620.44795 | O3: =+(J3+K3+L3+M3+N3+U3) -> 16311.044 | P3: 3972.5717 | Q3: 2482.8573 | R3: 6164.5185 | S3: =(K3+L3+M3+N3+J3)*0.04 -> 652.44175 | T3: =+P3+Q3+R3+S3 -> 13272.389 | V3: 2000
B4: =B3+1 -> 3 | C4: PABLO LOPEZ CRUZ | D4: ADMINISTRACION | E4: 45017 | F4: 46387 | G4: =YEAR(F4)-YEAR(E4) -> 3 | H4: =VLOOKUP(G4,Hoja5!$A$3:$B$38,2,0) -> 16 | I4: 917.93 | J4: =I4*30.4166 -> 27920.31 | K4: =I4*H4*0.25/12 -> 305.97667 | L4: =I3*2*3/12 -> 244.78 | M4: =I4*0.25*2 -> 458.965 | N4: =J4/2/12 -> 1163.3462 | O4: =+(J4+K4+L4+M4+N4+U4) -> 30093.378 | P4: 3972.5717 | Q4: 2482.8573 | R4: 6164.5185 | S4: =(K4+L4+M4+N4+J4)*0.04 -> 1203.7351 | T4: =+P4+Q4+R4+S4 -> 13823.683 | V4: 2000
B5: =B4+1 -> 4 | C5: LISSETTE GONZALEZ ESTRADA | D5: ADMINISTRACION | E5: 45114 | F5: 46387 | G5: =YEAR(F5)-YEAR(E5) -> 3 | H5: =VLOOKUP(G5,Hoja5!$A$3:$B$38,2,0) -> 16 | I5: 449.4714 | J5: =I5*30.4166 -> 13671.392 | K5: =I5*H5*0.25/12 -> 149.8238 | L5: =I4*2*3/12 -> 458.965 | M5: 0 | N5: =J5/2/12 -> 569.64132 | O5: =+(J5+K5+L5+M5+N5+U5) -> 14849.822 | P5: 3972.5717 | Q5: 2482.8573 | R5: 6164.5185 | S5: =(K5+L5+M5+N5+J5)*0.04 -> 593.99288 | T5: =+P5+Q5+R5+S5 -> 13213.94 | V5: 2000
B6: =B5+1 -> 5 | C6: NISSIM YADIHEL MORA OLMOS | D6: ADMINISTRACION | E6: 45551 | F6: 46387 | G6: =YEAR(F6)-YEAR(E6) -> 2 | H6: =VLOOKUP(G6,Hoja5!$A$3:$B$38,2,0) -> 14 | I6: 1055.3154 | J6: =I6*30.4166 -> 32099.106 | K6: =I6*H6*0.25/12 -> 307.80032 | L6: =I5*2*3/12 -> 224.7357 | M6: =I6*0.25*2 -> 527.6577 | N6: =J6/2/12 -> 1337.4628 | O6: =+(J6+K6+L6+M6+N6+U6) -> 34496.763 | P6: 3972.5717 | Q6: 2482.8573 | R6: 6164.5185 | S6: =(K6+L6+M6+N6+J6)*0.04 -> 1379.8705 | T6: =+P6+Q6+R6+S6 -> 13999.818 | V6: 2000
B7: =B6+1 -> 6 | C7: LEONARDO ISMAEL SANCHEZ MARTINEZ | D7: ADMINISTRACION | E7: 45717 | F7: 46387 | G7: =YEAR(F7)-YEAR(E7) -> 1 | H7: =VLOOKUP(G7,Hoja5!$A$3:$B$38,2,0) -> 12 | I7: 966.58 | J7: =I7*30.4166 -> 29400.077 | K7: =I7*H7*0.25/12 -> 241.645 | L7: =I6*2*3/12 -> 527.6577 | M7: =I7*0.25*2 -> 483.29 | N7: =J7/2/12 -> 1225.0032 | O7: =+(J7+K7+L7+M7+N7+U7) -> 31877.673 | P7: 3972.5717 | Q7: 2482.8573 | R7: 6164.5185 | S7: =(K7+L7+M7+N7+J7)*0.04 -> 1275.1069 | T7: =+P7+Q7+R7+S7 -> 13895.054 | V7: 2000
B8: =B7+1 -> 7 | C8: EDWIN DE JESUS CIAU MAZUM | D8: ADMINISTRACION | E8: 45763 | F8: 46387 | G8: =YEAR(F8)-YEAR(E8) -> 1 | H8: =VLOOKUP(G8,Hoja5!$A$3:$B$38,2,0) -> 12 | I8: 794.07 | J8: =I8*30.4166 -> 24152.91 | K8: =I8*H8*0.25/12 -> 198.5175 | L8: =I7*2*3/12 -> 483.29 | M8: =I8*0.25*2 -> 397.035 | N8: =J8/2/12 -> 1006.3712 | O8: =+(J8+K8+L8+M8+N8+U8) -> 26238.123 | P8: 3972.5717 | Q8: 2482.8573 | R8: 6164.5185 | S8: =(K8+L8+M8+N8+J8)*0.04 -> 1049.5249 | T8: =+P8+Q8+R8+S8 -> 13669.472 | V8: 2000
B9: =B8+1 -> 8 | C9: ALFREDO ANDRES RESENDIZ | D9: CHOFER | E9: 45618 | F9: 46387 | G9: =YEAR(F9)-YEAR(E9) -> 2 | H9: =VLOOKUP(G9,Hoja5!$A$3:$B$38,2,0) -> 14 | I9: 444.13 | J9: =I9*30.4166 -> 13508.925 | K9: =I9*H9*0.25/12 -> 129.53792 | L9: =I8*2*3/12 -> 397.035 | M9: =I9*0.25*2 -> 222.065 | N9: =J9/2/12 -> 562.87186 | O9: =+(J9+K9+L9+M9+N9+U9) -> 14820.434 | P9: 1358.8529 | Q9: 1145.4828 | R9: 2114.8155 | S9: 588.77944 | T9: =+P9+Q9+R9+S9 -> 5207.9306 | V9: 2000
B10: =B9+1 -> 9 | C10: RODRIGO SANCHEZ SALVADOR | D10: BELLBOY | E10: 44789 | F10: 46387 | G10: =YEAR(F10)-YEAR(E10) -> 4 | H10: =VLOOKUP(G10,Hoja5!$A$3:$B$38,2,0) -> 18 | I10: 444.13 | J10: =I10*30.4166 -> 13508.925 | K10: =I10*H10*0.25/12 -> 166.54875 | L10: =I9*2*3/12 -> 222.065 | M10: =I10*0.25*2 -> 222.065 | N10: =J10/2/12 -> 562.87186 | O10: =+(J10+K10+L10+M10+N10+U10) -> 14682.475 | P10: 1358.8529 | Q10: 1145.4828 | R10: 2114.8155 | S10: 588.77944 | T10: =+P10+Q10+R10+S10 -> 5207.9306 | V10: 2000
B11: =B10+1 -> 10 | C11: DIEGO ARMANDO LOPEZ GONZALEZ | D11: BELLBOY | E11: 45083 | F11: 46387 | G11: =YEAR(F11)-YEAR(E11) -> 3 | H11: =VLOOKUP(G11,Hoja5!$A$3:$B$38,2,0) -> 16 | I11: 444.13 | J11: =I11*30.4166 -> 13508.925 | K11: =I11*H11*0.25/12 -> 148.04333 | L11: =I10*2*3/12 -> 222.065 | M11: =I11*0.25*2 -> 222.065 | N11: =J11/2/12 -> 562.87186 | O11: =+(J11+K11+L11+M11+N11+U11) -> 14663.97 | P11: 1358.8529 | Q11: 1145.4828 | R11: 2114.8155 | S11: 588.77944 | T11: =+P11+Q11+R11+S11 -> 5207.9306 | V11: 2000
B12: =B11+1 -> 11 | C12: JAIME GIBRAN RIVERA SANDOVAL | D12: BELLBOY | E12: 46237 | F12: 46387 | G12: =YEAR(F12)-YEAR(E12) -> 0 | H12: =VLOOKUP(G12,Hoja5!$A$3:$B$38,2,0) -> 12 | I12: 444.13 | J12: =I12*30.4166 -> 13508.925 | K12: =I12*H12*0.25/12 -> 111.0325 | L12: =I11*2*3/12 -> 222.065 | M12: =I12*0.25*2 -> 222.065 | N12: =J12/2/12 -> 562.87186 | O12: =+(J12+K12+L12+M12+N12+U12) -> 14626.959 | P12: 1358.8529 | Q12: 1145.4828 | R12: 2114.8155 | S12: 588.77944 | T12: =+P12+Q12+R12+S12 -> 5207.9306 | V12: 2000
B13: =B12+1 -> 12 | C13: SAINITE RICO VIVEROS | D13: CONSERJERIA | E13: 43831 | F13: 46387 | G13: =YEAR(F13)-YEAR(E13) -> 6 | H13: =VLOOKUP(G13,Hoja5!$A$3:$B$38,2,0) -> 22 | I13: 444.13 | J13: =I13*30.4166 -> 13508.925 | K13: =I13*H13*0.25/12 -> 203.55958 | L13: =I12*2*3/12 -> 222.065 | M13: =I13*0.25*2 -> 222.065 | N13: =J13/2/12 -> 562.87186 | O13: =+(J13+K13+L13+M13+N13+U13) -> 14719.486 | P13: 1358.8529 | Q13: 1145.4828 | R13: 2114.8155 | S13: 588.77944 | T13: =+P13+Q13+R13+S13 -> 5207.9306 | V13: 3500
B14: =B13+1 -> 13 | C14: IVONNE TINOCO VEGA | D14: CONSERJERIA | E14: 43831 | F14: 46387 | G14: =YEAR(F14)-YEAR(E14) -> 6 | H14: =VLOOKUP(G14,Hoja5!$A$3:$B$38,2,0) -> 22 | I14: 444.13 | J14: =I14*30.4166 -> 13508.925 | K14: =I14*H14*0.25/12 -> 203.55958 | L14: =I13*2*3/12 -> 222.065 | M14: =I14*0.25*2 -> 222.065 | N14: =J14/2/12 -> 562.87186 | O14: =+(J14+K14+L14+M14+N14+U14) -> 14719.486 | P14: 1358.8529 | Q14: 1145.4828 | R14: 2114.8155 | S14: 588.77944 | T14: =+P14+Q14+R14+S14 -> 5207.9306 | V14: 3500
B15: =B14+1 -> 14 | C15: ANAYELI ARAUJO TAVIRA | D15: CONSERJERIA | E15: 44151 | F15: 46387 | G15: =YEAR(F15)-YEAR(E15) -> 6 | H15: =VLOOKUP(G15,Hoja5!$A$3:$B$38,2,0) -> 22 | I15: 444.13 | J15: =I15*30.4166 -> 13508.925 | K15: =I15*H15*0.25/12 -> 203.55958 | L15: =I14*2*3/12 -> 222.065 | M15: =I15*0.25*2 -> 222.065 | N15: =J15/2/12 -> 562.87186 | O15: =+(J15+K15+L15+M15+N15+U15) -> 14719.486 | P15: 1358.8529 | Q15: 1145.4828 | R15: 2114.8155 | S15: 588.77944 | T15: =+P15+Q15+R15+S15 -> 5207.9306 | V15: 3500
B16: =B15+1 -> 15 | C16: MARIA ELENA ARREOLA SANTOYO | D16: CONSERJERIA | E16: 44278 | F16: 46387 | G16: =YEAR(F16)-YEAR(E16) -> 5 | H16: =VLOOKUP(G16,Hoja5!$A$3:$B$38,2,0) -> 20 | I16: 444.13 | J16: =I16*30.4166 -> 13508.925 | K16: =I16*H16*0.25/12 -> 185.05417 | L16: =I15*2*3/12 -> 222.065 | M16: =I16*0.25*2 -> 222.065 | N16: =J16/2/12 -> 562.87186 | O16: =+(J16+K16+L16+M16+N16+U16) -> 14700.981 | P16: 1358.8529 | Q16: 1145.4828 | R16: 2114.8155 | S16: 588.77944 | T16: =+P16+Q16+R16+S16 -> 5207.9306 | V16: 3500
B17: =B16+1 -> 16 | C17: ANGEL MAURICIO MIRELES ROMERO | D17: CONSERJERIA | E17: 45541 | F17: 46387 | G17: =YEAR(F17)-YEAR(E17) -> 2 | H17: =VLOOKUP(G17,Hoja5!$A$3:$B$38,2,0) -> 14 | I17: 444.13 | J17: =I17*30.4166 -> 13508.925 | K17: =I17*H17*0.25/12 -> 129.53792 | L17: =I16*2*3/12 -> 222.065 | M17: =I17*0.25*2 -> 222.065 | N17: =J17/2/12 -> 562.87186 | O17: =+(J17+K17+L17+M17+N17+U17) -> 14645.464 | P17: 1358.8529 | Q17: 1145.4828 | R17: 2114.8155 | S17: 588.77944 | T17: =+P17+Q17+R17+S17 -> 5207.9306 | V17: 2000
B18: =B17+1 -> 17 | C18: VICTOR HUGO CORONA ALVARADO | D18: CONSERJERIA | E18: 46209 | F18: 46387 | G18: =YEAR(F18)-YEAR(E18) -> 0 | H18: =VLOOKUP(G18,Hoja5!$A$3:$B$38,2,0) -> 12 | I18: 444.13 | J18: =I18*30.4166 -> 13508.925 | K18: =I18*H18*0.25/12 -> 111.0325 | L18: =I17*2*3/12 -> 222.065 | M18: =I18*0.25*2 -> 222.065 | N18: =J18/2/12 -> 562.87186 | O18: =+(J18+K18+L18+M18+N18+U18) -> 14626.959 | P18: 1358.8529 | Q18: 1145.4828 | R18: 2114.8155 | S18: 588.77944 | T18: =+P18+Q18+R18+S18 -> 5207.9306 | V18: 2000
B19: =B18+1 -> 18 | C19: MARCELINO ROMERO ALBA | D19: CONSERJERIA | E19: 46210 | F19: 46387 | G19: =YEAR(F19)-YEAR(E19) -> 0 | H19: =VLOOKUP(G19,Hoja5!$A$3:$B$38,2,0) -> 12 | I19: 444.13 | J19: =I19*30.4166 -> 13508.925 | K19: =I19*H19*0.25/12 -> 111.0325 | L19: =I18*2*3/12 -> 222.065 | M19: =I19*0.25*2 -> 222.065 | N19: =J19/2/12 -> 562.87186 | O19: =+(J19+K19+L19+M19+N19+U19) -> 14626.959 | P19: 1358.8529 | Q19: 1145.4828 | R19: 2114.8155 | S19: 588.77944 | T19: =+P19+Q19+R19+S19 -> 5207.9306 | V19: 2000
B20: =B19+1 -> 19 | C20: JOSE LUIS CARBO ROSAS | D20: CONSERJERIA | E20: 46219 | F20: 46387 | G20: =YEAR(F20)-YEAR(E20) -> 0 | H20: =VLOOKUP(G20,Hoja5!$A$3:$B$38,2,0) -> 12 | I20: 444.13 | J20: =I20*30.4166 -> 13508.925 | K20: =I20*H20*0.25/12 -> 111.0325 | L20: =I19*2*3/12 -> 222.065 | M20: =I20*0.25*2 -> 222.065 | N20: =J20/2/12 -> 562.87186 | O20: =+(J20+K20+L20+M20+N20+U20) -> 14626.959 | P20: 1358.8529 | Q20: 1145.4828 | R20: 2114.8155 | S20: 588.77944 | T20: =+P20+Q20+R20+S20 -> 5207.9306 | V20: 2000
B21: =B20+1 -> 20 | C21: ANGEL ISMAEL MERIDA FLORES | D21: JFE CONSERJERIA | E21: 43831 | F21: 46387 | G21: =YEAR(F21)-YEAR(E21) -> 6 | H21: =VLOOKUP(G21,Hoja5!$A$3:$B$38,2,0) -> 22 | I21: 519.35 | J21: =I21*30.4166 -> 15796.861 | K21: =I21*H21*0.25/12 -> 238.03542 | L21: =I20*2*3/12 -> 222.065 | M21: =I21*0.25*2 -> 259.675 | N21: =J21/2/12 -> 658.20255 | O21: =+(J21+K21+L21+M21+N21+U21) -> 17174.839 | P21: 1358.8529 | Q21: 849.28305 | R21: 2114.8155 | S21: =(K21+L21+M21+N21+J21)*0.04 -> 686.99357 | T21: =+P21+Q21+R21+S21 -> 5009.945 | V21: 3500
B22: =B21+1 -> 21 | C22: ALEJANDRO CERDA GOMEZ | D22: JEFE MANTENIMIENTO | E22: 44758 | F22: 46387 | G22: =YEAR(F22)-YEAR(E22) -> 4 | H22: =VLOOKUP(G22,Hoja5!$A$3:$B$38,2,0) -> 18 | I22: 685.5704 | J22: =I22*30.4166 -> 20852.721 | K22: =I22*H22*0.25/12 -> 257.0889 | L22: =I21*2*3/12 -> 259.675 | M22: 0 | N22: =J22/2/12 -> 868.86336 | O22: =+(J22+K22+L22+M22+N22+U22) -> 22238.348 | P22: 1358.8529 | Q22: 849.28305 | R22: 2114.8155 | S22: =(K22+L22+M22+N22+J22)*0.04 -> 889.53392 | T22: =+P22+Q22+R22+S22 -> 5212.4853 | V22: 2000
B23: =B22+1 -> 22 | C23: ELIZABETH SANCHEZ MARTINEZ | D23: LUDOTECA | E23: 46189 | F23: 46387 | G23: =YEAR(F23)-YEAR(E23) -> 0 | H23: =VLOOKUP(G23,Hoja5!$A$3:$B$38,2,0) -> 12 | I23: 404.2284 | J23: =I23*30.4166 -> 12295.254 | K23: =I23*H23*0.25/12 -> 101.0571 | L23: =I22*2*3/12 -> 342.7852 | M23: =I23*0.25*2 -> 202.1142 | N23: =J23/2/12 -> 512.30223 | O23: =+(J23+K23+L23+M23+N23+U23) -> 13453.512 | P23: 1358.8529 | Q23: 849.28305 | R23: 2114.8155 | S23: =(K23+L23+M23+N23+J23)*0.04 -> 538.14049 | T23: =+P23+Q23+R23+S23 -> 4861.0919 | V23: 2000
B24: =B23+1 -> 23 | C24: ANGELA MEZA VINIEGRA | D24: LUDOTECA | E24: 46174 | F24: 46387 | G24: =YEAR(F24)-YEAR(E24) -> 0 | H24: =VLOOKUP(G24,Hoja5!$A$3:$B$38,2,0) -> 12 | I24: 575.3449 | J24: =I24*30.4166 -> 17500.036 | K24: =I24*H24*0.25/12 -> 143.83623 | L24: =I23*2*3/12 -> 202.1142 | M24: =I24*0.25*2 -> 287.67245 | N24: =J24/2/12 -> 729.16815 | O24: =+(J24+K24+L24+M24+N24+U24) -> 18862.827 | P24: 1358.8529 | Q24: 849.28305 | R24: 2114.8155 | S24: =(K24+L24+M24+N24+J24)*0.04 -> 754.51307 | T24: =+P24+Q24+R24+S24 -> 5077.4645 | V24: 2000
B25: =B24+1 -> 24 | C25: LILIA KARINA SANDOVAL RODRIGUEZ | D25: LUDOTECA | E25: 46235 | F25: 46387 | G25: =YEAR(F25)-YEAR(E25) -> 0 | H25: =VLOOKUP(G25,Hoja5!$A$3:$B$38,2,0) -> 12 | I25: 575.3426 | J25: =I25*30.4166 -> 17499.966 | K25: =I25*H25*0.25/12 -> 143.83565 | L25: =I24*2*3/12 -> 287.67245 | M25: =I25*0.25*2 -> 287.6713 | N25: =J25/2/12 -> 729.16524 | O25: =+(J25+K25+L25+M25+N25+U25) -> 18948.31 | P25: 1358.8529 | Q25: 849.28305 | R25: 2114.8155 | S25: =(K25+L25+M25+N25+J25)*0.04 -> 757.93241 | T25: =+P25+Q25+R25+S25 -> 5080.8838 | V25: 2000
B26: =B25+1 -> 25 | C26: MARIA DEL CARMEN HERNANDEZ DE ANDA | D26: LUDOTECA | E26: 45983 | F26: 46387 | G26: =YEAR(F26)-YEAR(E26) -> 1 | H26: =VLOOKUP(G26,Hoja5!$A$3:$B$38,2,0) -> 12 | I26: 575.3426 | J26: =I26*30.4166 -> 17499.966 | K26: =I26*H26*0.25/12 -> 143.83565 | L26: =I25*2*3/12 -> 287.6713 | M26: =I26*0.25*2 -> 287.6713 | N26: =J26/2/12 -> 729.16524 | O26: =+(J26+K26+L26+M26+N26+U26) -> 18948.309 | P26: 3972.5717 | Q26: 2482.8573 | R26: 6164.5185 | S26: =(K26+L26+M26+N26+J26)*0.04 -> 757.93237 | T26: =+P26+Q26+R26+S26 -> 13377.88 | V26: 2000
B27: =B26+1 -> 26 | C27: JAZMIN SORIANO BARRERA | D27: LUDOTECA | E27: 46054 | F27: 46387 | G27: =YEAR(F27)-YEAR(E27) -> 0 | H27: =VLOOKUP(G27,Hoja5!$A$3:$B$38,2,0) -> 12 | I27: 401.5565 | J27: =I27*30.4166 -> 12213.983 | K27: =I27*H27*0.25/12 -> 100.38912 | L27: =I26*2*3/12 -> 287.6713 | M27: 0 | N27: =J27/2/12 -> 508.91598 | O27: =+(J27+K27+L27+M27+N27+U27) -> 13110.96 | P27: 1657.656 | Q27: 1036.035 | R27: 2486.4 | S27: =(K27+L27+M27+N27+J27)*0.04 -> 524.43839 | T27: =+P27+Q27+R27+S27 -> 5704.5294 | V27: 2000
B28: =B27+1 -> 27 | C28: BRENDA SEGURA DAVILA | D28: LUDOTECA | E28: 46235 | F28: 46387 | G28: =YEAR(F28)-YEAR(E28) -> 0 | H28: =VLOOKUP(G28,Hoja5!$A$3:$B$38,2,0) -> 12 | I28: 404.18 | J28: =I28*30.4166 -> 12293.781 | K28: =I28*H28*0.25/12 -> 101.045 | L28: =I27*2*3/12 -> 200.77825 | M28: =I28*0.25*2 -> 202.09 | N28: =J28/2/12 -> 512.24089 | O28: =+(J28+K28+L28+M28+N28+U28) -> 13309.936 | P28: 1358.8529 | Q28: 1145.4828 | R28: 3062.85 | S28: 588.77944 | T28: =+P28+Q28+R28+S28 -> 6155.9651 | U28: =SUM(U1:U27) -> 0 | V28: 2000
B29: =B28+1 -> 28 | C29: JOSE SANTOS PAZ GARCIA | D29: MANTENIMIENTO | E29: 42751 | F29: 46387 | G29: =YEAR(F29)-YEAR(E29) -> 9 | H29: =VLOOKUP(G29,Hoja5!$A$3:$B$38,2,0) -> 22 | I29: 444.13 | J29: =I29*30.4166 -> 13508.925 | K29: =I29*H29*0.25/12 -> 203.55958 | L29: =I28*2*3/12 -> 202.09 | M29: =I29*0.25*2 -> 222.065 | N29: =J29/2/12 -> 562.87186 | O29: =+(J29+K29+L29+M29+N29+U29) -> 14699.511 | P29: 1358.8529 | Q29: 1145.4828 | R29: 2114.8155 | S29: 588.77944 | T29: =+P29+Q29+R29+S29 -> 5207.9306 | V29: 3500
B30: =B29+1 -> 29 | C30: MIGUEL ROBELO MORELOS | D30: MANTENIMIENTO | E30: 45145 | F30: 46387 | G30: =YEAR(F30)-YEAR(E30) -> 3 | H30: =VLOOKUP(G30,Hoja5!$A$3:$B$38,2,0) -> 16 | I30: 444.13 | J30: =I30*30.4166 -> 13508.925 | K30: =I30*H30*0.25/12 -> 148.04333 | L30: =I29*2*3/12 -> 222.065 | M30: =I30*0.25*2 -> 222.065 | N30: =J30/2/12 -> 562.87186 | O30: =+(J30+K30+L30+M30+N30+U30) -> 14663.97 | P30: 1358.8529 | Q30: 1145.4828 | R30: 2265.9 | S30: 588.77944 | T30: =+P30+Q30+R30+S30 -> 5359.0151 | V30: 2000
B31: =B30+1 -> 30 | C31: BENJAMIN MACEDONIO MEJIA | D31: MANTENIMIENTO | E31: 45253 | F31: 46387 | G31: =YEAR(F31)-YEAR(E31) -> 3 | H31: =VLOOKUP(G31,Hoja5!$A$3:$B$38,2,0) -> 16 | I31: 444.13 | J31: =I31*30.4166 -> 13508.925 | K31: =I31*H31*0.25/12 -> 148.04333 | L31: =I30*2*3/12 -> 222.065 | M31: =I31*0.25*2 -> 222.065 | N31: =J31/2/12 -> 562.87186 | O31: =+(J31+K31+L31+M31+N31+U31) -> 14663.97 | P31: 1358.8529 | Q31: 1145.4828 | R31: 2114.8155 | S31: 588.03922 | T31: =+P31+Q31+R31+S31 -> 5207.1904 | V31: 2000
B32: =B31+1 -> 31 | C32: JAVIER LOPEZ SANTOS | D32: MANTENIMIENTO | E32: 45505 | F32: 46387 | G32: =YEAR(F32)-YEAR(E32) -> 2 | H32: =VLOOKUP(G32,Hoja5!$A$3:$B$38,2,0) -> 14 | I32: 444.13 | J32: =I32*30.4166 -> 13508.925 | K32: =I32*H32*0.25/12 -> 129.53792 | L32: =I31*2*3/12 -> 222.065 | M32: =I32*0.25*2 -> 222.065 | N32: =J32/2/12 -> 562.87186 | O32: =+(J32+K32+L32+M32+N32+U32) -> 14645.464 | P32: 1358.8529 | Q32: 1145.4828 | R32: 2114.8155 | S32: 585.81857 | T32: =+P32+Q32+R32+S32 -> 5204.9698 | V32: 2000
B33: =B32+1 -> 32 | C33: ALEJANDRO REYES PEDRAZA GONZALEZ | D33: MANTENIMIENTO | E33: 45877 | F33: 46387 | G33: =YEAR(F33)-YEAR(E33) -> 1 | H33: =VLOOKUP(G33,Hoja5!$A$3:$B$38,2,0) -> 12 | I33: 444.13 | J33: =I33*30.4166 -> 13508.925 | K33: =I33*H33*0.25/12 -> 111.0325 | L33: =I32*2*3/12 -> 222.065 | M33: 0 | N33: =J33/2/12 -> 562.87186 | O33: =+(J33+K33+L33+M33+N33+U33) -> 14404.894 | P33: 1358.8529 | Q33: 1145.4828 | R33: 3062.85 | S33: 588.77944 | T33: =+P33+Q33+R33+S33 -> 6155.9651 | V33: 2000
B34: =B33+1 -> 33 | C34: OSCAR RAYMUNDO GRAJALES | D34: MANTENIMIENTO | E34: 46054 | F34: 46387 | G34: =YEAR(F34)-YEAR(E34) -> 0 | H34: =VLOOKUP(G34,Hoja5!$A$3:$B$38,2,0) -> 12 | I34: 444.13 | J34: =I34*30.4166 -> 13508.925 | K34: =I34*H34*0.25/12 -> 111.0325 | L34: =I33*2*3/12 -> 222.065 | M34: =I34*0.25*2 -> 222.065 | N34: =J34/2/12 -> 562.87186 | O34: =+(J34+K34+L34+M34+N34+U34) -> 14626.959 | P34: 1358.8529 | Q34: 1145.4828 | R34: 3062.85 | S34: 588.77944 | T34: =+P34+Q34+R34+S34 -> 6155.9651 | V34: 2000
B35: =B34+1 -> 34 | C35: REY DAVID MELGAR TAPIA | D35: MANTENIMIENTO | E35: 46063 | F35: 46387 | G35: =YEAR(F35)-YEAR(E35) -> 0 | H35: =VLOOKUP(G35,Hoja5!$A$3:$B$38,2,0) -> 12 | I35: 444.13 | J35: =I35*30.4166 -> 13508.925 | K35: =I35*H35*0.25/12 -> 111.0325 | L35: =I34*2*3/12 -> 222.065 | M35: =I35*0.25*2 -> 222.065 | N35: =J35/2/12 -> 562.87186 | O35: =+(J35+K35+L35+M35+N35+U35) -> 14626.959 | P35: 1358.8529 | Q35: 1145.4828 | R35: 3062.85 | S35: 588.77944 | T35: =+P35+Q35+R35+S35 -> 6155.9651 | V35: 2000
B36: =B35+1 -> 35 | C36: RICARDO ROSALES MARTINEZ | D36: MANTENIMIENTO | E36: 46062 | F36: 46387 | G36: =YEAR(F36)-YEAR(E36) -> 0 | H36: =VLOOKUP(G36,Hoja5!$A$3:$B$38,2,0) -> 12 | I36: 444.13 | J36: =I36*30.4166 -> 13508.925 | K36: =I36*H36*0.25/12 -> 111.0325 | L36: =I35*2*3/12 -> 222.065 | M36: =I36*0.25*2 -> 222.065 | N36: =J36/2/12 -> 562.87186 | O36: =+(J36+K36+L36+M36+N36+U36) -> 14626.959 | P36: 1358.8529 | Q36: 1145.4828 | R36: 3062.85 | S36: 588.77944 | T36: =+P36+Q36+R36+S36 -> 6155.9651 | V36: 2000
B37: =B36+1 -> 36 | C37: ELIAS LOPEZ LINA | D37: MANTENIMIENTO | E37: 46082 | F37: 46387 | G37: =YEAR(F37)-YEAR(E37) -> 0 | H37: =VLOOKUP(G37,Hoja5!$A$3:$B$38,2,0) -> 12 | I37: 444.13 | J37: =I37*30.4166 -> 13508.925 | K37: =I37*H37*0.25/12 -> 111.0325 | L37: =I36*2*3/12 -> 222.065 | M37: =I37*0.25*2 -> 222.065 | N37: =J37/2/12 -> 562.87186 | O37: =+(J37+K37+L37+M37+N37+U37) -> 14626.959 | P37: 1358.8529 | Q37: 1145.4828 | R37: 3062.85 | S37: 588.77944 | T37: =+P37+Q37+R37+S37 -> 6155.9651 | V37: 2000
B38: =B37+1 -> 37 | C38: ISRAEL ANGELES RIOS | D38: MANTENIMIENTO | E38: 46174 | F38: 46387 | G38: =YEAR(F38)-YEAR(E38) -> 0 | H38: =VLOOKUP(G38,Hoja5!$A$3:$B$38,2,0) -> 12 | I38: 444.13 | J38: =I38*30.4166 -> 13508.925 | K38: =I38*H38*0.25/12 -> 111.0325 | L38: =I37*2*3/12 -> 222.065 | M38: =I38*0.25*2 -> 222.065 | N38: =J38/2/12 -> 562.87186 | O38: =+(J38+K38+L38+M38+N38+U38) -> 14626.959 | P38: 1358.8529 | Q38: 1145.4828 | R38: 3062.85 | S38: 588.77944 | T38: =+P38+Q38+R38+S38 -> 6155.9651 | V38: 2000
B39: =B38+1 -> 38 | C39: RICARDO ARTURO AGUIRRE RIVERA | D39: MANTENIMIENTO | E39: 46204 | F39: 46387 | G39: =YEAR(F39)-YEAR(E39) -> 0 | H39: =VLOOKUP(G39,Hoja5!$A$3:$B$38,2,0) -> 12 | I39: 444.13 | J39: =I39*30.4166 -> 13508.925 | K39: =I39*H39*0.25/12 -> 111.0325 | L39: =I38*2*3/12 -> 222.065 | M39: =I39*0.25*2 -> 222.065 | N39: =J39/2/12 -> 562.87186 | O39: =+(J39+K39+L39+M39+N39+U39) -> 14626.959 | P39: 1358.8529 | Q39: 1145.4828 | R39: 3062.85 | S39: 588.77944 | T39: =+P39+Q39+R39+S39 -> 6155.9651 | V39: 2000
B40: =B39+1 -> 39 | C40: JUAN ADRIAN ZARAGOZA REYES | D40: MANTENIMIENTO | E40: 46238 | F40: 46387 | G40: =YEAR(F40)-YEAR(E40) -> 0 | H40: =VLOOKUP(G40,Hoja5!$A$3:$B$38,2,0) -> 12 | I40: 444.13 | J40: =I40*30.4166 -> 13508.925 | K40: =I40*H40*0.25/12 -> 111.0325 | L40: =I39*2*3/12 -> 222.065 | M40: =I40*0.25*2 -> 222.065 | N40: =J40/2/12 -> 562.87186 | O40: =+(J40+K40+L40+M40+N40+U40) -> 14626.959 | P40: 1358.8529 | Q40: 1145.4828 | R40: 3062.85 | S40: 588.77944 | T40: =+P40+Q40+R40+S40 -> 6155.9651 | V40: 2000
...

Sheet sueldo 13000
B1: CLAVE | C1: NOMBRE | D1: PUESTO | E1: Fecha inicial | F1: Fecha atual | G1: Años | H1: Dias Correspondientes | I1: SALARIO | J1: SUELDO | K1: PRIMA VACACIONAL | L1: DIAS FESTIVOS | M1: PRIMA DOMINICAL | N1: AGUINALDO | O1: TOTAL | P1: RETIRO, CESANTIA Y VEJEZ | Q1: INFONAVIT | R1: CUOTA IMSS | S1: IMPUESTO SOBRE NOMINA | T1: CARGA LABORAL
B2: 1 | C2: JORGE ALTAMIRANO ROMERO | D2: ADMINISTRACION | E2: 41827 | F2: 46387 | G2: =YEAR(F2)-YEAR(E2) -> 12 | H2: =VLOOKUP(G2,Hoja5!$A$3:$B$38,2,0) -> 24 | I2: 742.96 | J2: =I2*30.4166 -> 22598.317 | K2: =I2*H2*0.25/12 -> 371.48 | L2: 0 | M2: 0 | N2: =J2/2/12 -> 941.59655 | O2: =+(J2+K2+L2+M2+N2+U2) -> 23911.394 | P2: 3972.5717 | Q2: 2482.8573 | R2: 6164.5185 | S2: =(K2+L2+M2+N2+J2)*0.04 -> 956.45575 | T2: =+P2+Q2+R2+S2 -> 13576.403 | V2: 2000
B3: =B2+1 -> 2 | C3: ARTURO IVAN ORDOÑEZ ESPINOSA | D3: ADMINISTRACION | E3: 44698 | F3: 46387 | G3: =YEAR(F3)-YEAR(E3) -> 4 | H3: =VLOOKUP(G3,Hoja5!$A$3:$B$38,2,0) -> 18 | I3: 489.56 | J3: =I3*30.4166 -> 14890.751 | K3: =I3*H3*0.25/12 -> 183.585 | L3: =I2*2*3/12 -> 371.48 | M3: =I3*0.25*2 -> 244.78 | N3: =J3/2/12 -> 620.44795 | O3: =+(J3+K3+L3+M3+N3+U3) -> 16311.044 | P3: 3972.5717 | Q3: 2482.8573 | R3: 6164.5185 | S3: =(K3+L3+M3+N3+J3)*0.04 -> 652.44175 | T3: =+P3+Q3+R3+S3 -> 13272.389 | V3: 2000
B4: =B3+1 -> 3 | C4: PABLO LOPEZ CRUZ | D4: ADMINISTRACION | E4: 45017 | F4: 46387 | G4: =YEAR(F4)-YEAR(E4) -> 3 | H4: =VLOOKUP(G4,Hoja5!$A$3:$B$38,2,0) -> 16 | I4: 917.93 | J4: =I4*30.4166 -> 27920.31 | K4: =I4*H4*0.25/12 -> 305.97667 | L4: =I3*2*3/12 -> 244.78 | M4: =I4*0.25*2 -> 458.965 | N4: =J4/2/12 -> 1163.3462 | O4: =+(J4+K4+L4+M4+N4+U4) -> 30093.378 | P4: 3972.5717 | Q4: 2482.8573 | R4: 6164.5185 | S4: =(K4+L4+M4+N4+J4)*0.04 -> 1203.7351 | T4: =+P4+Q4+R4+S4 -> 13823.683 | V4: 2000
B5: =B4+1 -> 4 | C5: LISSETTE GONZALEZ ESTRADA | D5: ADMINISTRACION | E5: 45114 | F5: 46387 | G5: =YEAR(F5)-YEAR(E5) -> 3 | H5: =VLOOKUP(G5,Hoja5!$A$3:$B$38,2,0) -> 16 | I5: 449.4714 | J5: =I5*30.4166 -> 13671.392 | K5: =I5*H5*0.25/12 -> 149.8238 | L5: =I4*2*3/12 -> 458.965 | M5: 0 | N5: =J5/2/12 -> 569.64132 | O5: =+(J5+K5+L5+M5+N5+U5) -> 14849.822 | P5: 3972.5717 | Q5: 2482.8573 | R5: 6164.5185 | S5: =(K5+L5+M5+N5+J5)*0.04 -> 593.99288 | T5: =+P5+Q5+R5+S5 -> 13213.94 | V5: 2000
B6: =B5+1 -> 5 | C6: NISSIM YADIHEL MORA OLMOS | D6: ADMINISTRACION | E6: 45551 | F6: 46387 | G6: =YEAR(F6)-YEAR(E6) -> 2 | H6: =VLOOKUP(G6,Hoja5!$A$3:$B$38,2,0) -> 14 | I6: 1055.3154 | J6: =I6*30.4166 -> 32099.106 | K6: =I6*H6*0.25/12 -> 307.80032 | L6: =I5*2*3/12 -> 224.7357 | M6: =I6*0.25*2 -> 527.6577 | N6: =J6/2/12 -> 1337.4628 | O6: =+(J6+K6+L6+M6+N6+U6) -> 34496.763 | P6: 3972.5717 | Q6: 2482.8573 | R6: 6164.5185 | S6: =(K6+L6+M6+N6+J6)*0.04 -> 1379.8705 | T6: =+P6+Q6+R6+S6 -> 13999.818 | V6: 2000
B7: =B6+1 -> 6 | C7: LEONARDO ISMAEL SANCHEZ MARTINEZ | D7: ADMINISTRACION | E7: 45717 | F7: 46387 | G7: =YEAR(F7)-YEAR(E7) -> 1 | H7: =VLOOKUP(G7,Hoja5!$A$3:$B$38,2,0) -> 12 | I7: 966.58 | J7: =I7*30.4166 -> 29400.077 | K7: =I7*H7*0.25/12 -> 241.645 | L7: =I6*2*3/12 -> 527.6577 | M7: =I7*0.25*2 -> 483.29 | N7: =J7/2/12 -> 1225.0032 | O7: =+(J7+K7+L7+M7+N7+U7) -> 31877.673 | P7: 3972.5717 | Q7: 2482.8573 | R7: 6164.5185 | S7: =(K7+L7+M7+N7+J7)*0.04 -> 1275.1069 | T7: =+P7+Q7+R7+S7 -> 13895.054 | V7: 2000
B8: =B7+1 -> 7 | C8: EDWIN DE JESUS CIAU MAZUM | D8: ADMINISTRACION | E8: 45763 | F8: 46387 | G8: =YEAR(F8)-YEAR(E8) -> 1 | H8: =VLOOKUP(G8,Hoja5!$A$3:$B$38,2,0) -> 12 | I8: 794.07 | J8: =I8*30.4166 -> 24152.91 | K8: =I8*H8*0.25/12 -> 198.5175 | L8: =I7*2*3/12 -> 483.29 | M8: =I8*0.25*2 -> 397.035 | N8: =J8/2/12 -> 1006.3712 | O8: =+(J8+K8+L8+M8+N8+U8) -> 26238.123 | P8: 3972.5717 | Q8: 2482.8573 | R8: 6164.5185 | S8: =(K8+L8+M8+N8+J8)*0.04 -> 1049.5249 | T8: =+P8+Q8+R8+S8 -> 13669.472 | V8: 2000
B9: =B8+1 -> 8 | C9: ALFREDO ANDRES RESENDIZ | D9: CHOFER | E9: 45618 | F9: 46387 | G9: =YEAR(F9)-YEAR(E9) -> 2 | H9: =VLOOKUP(G9,Hoja5!$A$3:$B$38,2,0) -> 14 | I9: 488.51 | J9: =I9*30.4166 -> 14858.813 | K9: =I9*H9*0.25/12 -> 142.48208 | L9: =I8*2*3/12 -> 397.035 | M9: =I9*0.25*2 -> 244.255 | N9: =J9/2/12 -> 619.11722 | O9: =+(J9+K9+L9+M9+N9+U9) -> 16261.703 | P9: 1358.8529 | Q9: 1145.4828 | R9: 2114.8155 | S9: =O9*0.04 -> 650.4681 | T9: =+P9+Q9+R9+S9 -> 5269.6193 | V9: 2000
B10: =B9+1 -> 9 | C10: RODRIGO SANCHEZ SALVADOR | D10: BELLBOY | E10: 44789 | F10: 46387 | G10: =YEAR(F10)-YEAR(E10) -> 4 | H10: =VLOOKUP(G10,Hoja5!$A$3:$B$38,2,0) -> 18 | I10: 488.51 | J10: =I10*30.4166 -> 14858.813 | K10: =I10*H10*0.25/12 -> 183.19125 | L10: =I9*2*3/12 -> 244.255 | M10: =I10*0.25*2 -> 244.255 | N10: =J10/2/12 -> 619.11722 | O10: =+(J10+K10+L10+M10+N10+U10) -> 16149.632 | P10: 1358.8529 | Q10: 1145.4828 | R10: 2114.8155 | S10: =O10*0.04 -> 645.98527 | T10: =+P10+Q10+R10+S10 -> 5265.1364 | V10: 2000
B11: =B10+1 -> 10 | C11: DIEGO ARMANDO LOPEZ GONZALEZ | D11: BELLBOY | E11: 45083 | F11: 46387 | G11: =YEAR(F11)-YEAR(E11) -> 3 | H11: =VLOOKUP(G11,Hoja5!$A$3:$B$38,2,0) -> 16 | I11: 488.51 | J11: =I11*30.4166 -> 14858.813 | K11: =I11*H11*0.25/12 -> 162.83667 | L11: =I10*2*3/12 -> 244.255 | M11: =I11*0.25*2 -> 244.255 | N11: =J11/2/12 -> 619.11722 | O11: =+(J11+K11+L11+M11+N11+U11) -> 16129.277 | P11: 1358.8529 | Q11: 1145.4828 | R11: 2114.8155 | S11: =O11*0.04 -> 645.17109 | T11: =+P11+Q11+R11+S11 -> 5264.3223 | V11: 2000
B12: =B11+1 -> 11 | C12: JAIME GIBRAN RIVERA SANDOVAL | D12: BELLBOY | E12: 46237 | F12: 46387 | G12: =YEAR(F12)-YEAR(E12) -> 0 | H12: =VLOOKUP(G12,Hoja5!$A$3:$B$38,2,0) -> 12 | I12: 488.51 | J12: =I12*30.4166 -> 14858.813 | K12: =I12*H12*0.25/12 -> 122.1275 | L12: =I11*2*3/12 -> 244.255 | M12: =I12*0.25*2 -> 244.255 | N12: =J12/2/12 -> 619.11722 | O12: =+(J12+K12+L12+M12+N12+U12) -> 16088.568 | P12: 1358.8529 | Q12: 1145.4828 | R12: 2114.8155 | S12: =O12*0.04 -> 643.54272 | T12: =+P12+Q12+R12+S12 -> 5262.6939 | V12: 2000
B13: =B12+1 -> 12 | C13: SAINITE RICO VIVEROS | D13: CONSERJERIA | E13: 43831 | F13: 46387 | G13: =YEAR(F13)-YEAR(E13) -> 6 | H13: =VLOOKUP(G13,Hoja5!$A$3:$B$38,2,0) -> 22 | I13: 488.51 | J13: =I13*30.4166 -> 14858.813 | K13: =I13*H13*0.25/12 -> 223.90042 | L13: =I12*2*3/12 -> 244.255 | M13: =I13*0.25*2 -> 244.255 | N13: =J13/2/12 -> 619.11722 | O13: =+(J13+K13+L13+M13+N13+U13) -> 16190.341 | P13: 1358.8529 | Q13: 1145.4828 | R13: 2114.8155 | S13: =O13*0.04 -> 647.61364 | T13: =+P13+Q13+R13+S13 -> 5266.7648 | V13: 3500
B14: =B13+1 -> 13 | C14: IVONNE TINOCO VEGA | D14: CONSERJERIA | E14: 43831 | F14: 46387 | G14: =YEAR(F14)-YEAR(E14) -> 6 | H14: =VLOOKUP(G14,Hoja5!$A$3:$B$38,2,0) -> 22 | I14: 488.51 | J14: =I14*30.4166 -> 14858.813 | K14: =I14*H14*0.25/12 -> 223.90042 | L14: =I13*2*3/12 -> 244.255 | M14: =I14*0.25*2 -> 244.255 | N14: =J14/2/12 -> 619.11722 | O14: =+(J14+K14+L14+M14+N14+U14) -> 16190.341 | P14: 1358.8529 | Q14: 1145.4828 | R14: 2114.8155 | S14: =O14*0.04 -> 647.61364 | T14: =+P14+Q14+R14+S14 -> 5266.7648 | V14: 3500
B15: =B14+1 -> 14 | C15: ANAYELI ARAUJO TAVIRA | D15: CONSERJERIA | E15: 44151 | F15: 46387 | G15: =YEAR(F15)-YEAR(E15) -> 6 | H15: =VLOOKUP(G15,Hoja5!$A$3:$B$38,2,0) -> 22 | I15: 488.51 | J15: =I15*30.4166 -> 14858.813 | K15: =I15*H15*0.25/12 -> 223.90042 | L15: =I14*2*3/12 -> 244.255 | M15: =I15*0.25*2 -> 244.255 | N15: =J15/2/12 -> 619.11722 | O15: =+(J15+K15+L15+M15+N15+U15) -> 16190.341 | P15: 1358.8529 | Q15: 1145.4828 | R15: 2114.8155 | S15: =O15*0.04 -> 647.61364 | T15: =+P15+Q15+R15+S15 -> 5266.7648 | V15: 3500
B16: =B15+1 -> 15 | C16: MARIA ELENA ARREOLA SANTOYO | D16: CONSERJERIA | E16: 44278 | F16: 46387 | G16: =YEAR(F16)-YEAR(E16) -> 5 | H16: =VLOOKUP(G16,Hoja5!$A$3:$B$38,2,0) -> 20 | I16: 488.51 | J16: =I16*30.4166 -> 14858.813 | K16: =I16*H16*0.25/12 -> 203.54583 | L16: =I15*2*3/12 -> 244.255 | M16: =I16*0.25*2 -> 244.255 | N16: =J16/2/12 -> 619.11722 | O16: =+(J16+K16+L16+M16+N16+U16) -> 16169.986 | P16: 1358.8529 | Q16: 1145.4828 | R16: 2114.8155 | S16: =O16*0.04 -> 646.79945 | T16: =+P16+Q16+R16+S16 -> 5265.9506 | V16: 3500
B17: =B16+1 -> 16 | C17: ANGEL MAURICIO MIRELES ROMERO | D17: CONSERJERIA | E17: 45541 | F17: 46387 | G17: =YEAR(F17)-YEAR(E17) -> 2 | H17: =VLOOKUP(G17,Hoja5!$A$3:$B$38,2,0) -> 14 | I17: 488.51 | J17: =I17*30.4166 -> 14858.813 | K17: =I17*H17*0.25/12 -> 142.48208 | L17: =I16*2*3/12 -> 244.255 | M17: =I17*0.25*2 -> 244.255 | N17: =J17/2/12 -> 619.11722 | O17: =+(J17+K17+L17+M17+N17+U17) -> 16108.923 | P17: 1358.8529 | Q17: 1145.4828 | R17: 2114.8155 | S17: =O17*0.04 -> 644.3569 | T17: =+P17+Q17+R17+S17 -> 5263.5081 | V17: 2000
B18: =B17+1 -> 17 | C18: VICTOR HUGO CORONA ALVARADO | D18: CONSERJERIA | E18: 46209 | F18: 46387 | G18: =YEAR(F18)-YEAR(E18) -> 0 | H18: =VLOOKUP(G18,Hoja5!$A$3:$B$38,2,0) -> 12 | I18: 488.51 | J18: =I18*30.4166 -> 14858.813 | K18: =I18*H18*0.25/12 -> 122.1275 | L18: =I17*2*3/12 -> 244.255 | M18: =I18*0.25*2 -> 244.255 | N18: =J18/2/12 -> 619.11722 | O18: =+(J18+K18+L18+M18+N18+U18) -> 16088.568 | P18: 1358.8529 | Q18: 1145.4828 | R18: 2114.8155 | S18: =O18*0.04 -> 643.54272 | T18: =+P18+Q18+R18+S18 -> 5262.6939 | V18: 2000
B19: =B18+1 -> 18 | C19: MARCELINO ROMERO ALBA | D19: CONSERJERIA | E19: 46210 | F19: 46387 | G19: =YEAR(F19)-YEAR(E19) -> 0 | H19: =VLOOKUP(G19,Hoja5!$A$3:$B$38,2,0) -> 12 | I19: 488.51 | J19: =I19*30.4166 -> 14858.813 | K19: =I19*H19*0.25/12 -> 122.1275 | L19: =I18*2*3/12 -> 244.255 | M19: =I19*0.25*2 -> 244.255 | N19: =J19/2/12 -> 619.11722 | O19: =+(J19+K19+L19+M19+N19+U19) -> 16088.568 | P19: 1358.8529 | Q19: 1145.4828 | R19: 2114.8155 | S19: =O19*0.04 -> 643.54272 | T19: =+P19+Q19+R19+S19 -> 5262.6939 | V19: 2000
B20: =B19+1 -> 19 | C20: JOSE LUIS CARBO ROSAS | D20: CONSERJERIA | E20: 46219 | F20: 46387 | G20: =YEAR(F20)-YEAR(E20) -> 0 | H20: =VLOOKUP(G20,Hoja5!$A$3:$B$38,2,0) -> 12 | I20: 488.51 | J20: =I20*30.4166 -> 14858.813 | K20: =I20*H20*0.25/12 -> 122.1275 | L20: =I19*2*3/12 -> 244.255 | M20: =I20*0.25*2 -> 244.255 | N20: =J20/2/12 -> 619.11722 | O20: =+(J20+K20+L20+M20+N20+U20) -> 16088.568 | P20: 1358.8529 | Q20: 1145.4828 | R20: 2114.8155 | S20: =O20*0.04 -> 643.54272 | T20: =+P20+Q20+R20+S20 -> 5262.6939 | V20: 2000
B21: =B20+1 -> 20 | C21: ANGEL ISMAEL MERIDA FLORES | D21: JFE CONSERJERIA | E21: 43831 | F21: 46387 | G21: =YEAR(F21)-YEAR(E21) -> 6 | H21: =VLOOKUP(G21,Hoja5!$A$3:$B$38,2,0) -> 22 | I21: 519.35 | J21: =I21*30.4166 -> 15796.861 | K21: =I21*H21*0.25/12 -> 238.03542 | L21: =I20*2*3/12 -> 244.255 | M21: =I21*0.25*2 -> 259.675 | N21: =J21/2/12 -> 658.20255 | O21: =+(J21+K21+L21+M21+N21+U21) -> 17197.029 | P21: 1358.8529 | Q21: 849.28305 | R21: 2114.8155 | S21: =(K21+L21+M21+N21+J21)*0.04 -> 687.88117 | T21: =+P21+Q21+R21+S21 -> 5010.8326 | V21: 3500
B22: =B21+1 -> 21 | C22: ALEJANDRO CERDA GOMEZ | D22: JEFE MANTENIMIENTO | E22: 44758 | F22: 46387 | G22: =YEAR(F22)-YEAR(E22) -> 4 | H22: =VLOOKUP(G22,Hoja5!$A$3:$B$38,2,0) -> 18 | I22: 685.5704 | J22: =I22*30.4166 -> 20852.721 | K22: =I22*H22*0.25/12 -> 257.0889 | L22: =I21*2*3/12 -> 259.675 | M22: 0 | N22: =J22/2/12 -> 868.86336 | O22: =+(J22+K22+L22+M22+N22+U22) -> 22238.348 | P22: 1358.8529 | Q22: 849.28305 | R22: 2114.8155 | S22: =(K22+L22+M22+N22+J22)*0.04 -> 889.53392 | T22: =+P22+Q22+R22+S22 -> 5212.4853 | V22: 2000
B23: =B22+1 -> 22 | C23: ELIZABETH SANCHEZ MARTINEZ | D23: LUDOTECA | E23: 46189 | F23: 46387 | G23: =YEAR(F23)-YEAR(E23) -> 0 | H23: =VLOOKUP(G23,Hoja5!$A$3:$B$38,2,0) -> 12 | I23: 404.2284 | J23: =I23*30.4166 -> 12295.254 | K23: =I23*H23*0.25/12 -> 101.0571 | L23: =I22*2*3/12 -> 342.7852 | M23: =I23*0.25*2 -> 202.1142 | N23: =J23/2/12 -> 512.30223 | O23: =+(J23+K23+L23+M23+N23+U23) -> 13453.512 | P23: 1358.8529 | Q23: 849.28305 | R23: 2114.8155 | S23: =(K23+L23+M23+N23+J23)*0.04 -> 538.14049 | T23: =+P23+Q23+R23+S23 -> 4861.0919 | V23: 2000
B24: =B23+1 -> 23 | C24: ANGELA MEZA VINIEGRA | D24: LUDOTECA | E24: 46174 | F24: 46387 | G24: =YEAR(F24)-YEAR(E24) -> 0 | H24: =VLOOKUP(G24,Hoja5!$A$3:$B$38,2,0) -> 12 | I24: 575.3449 | J24: =I24*30.4166 -> 17500.036 | K24: =I24*H24*0.25/12 -> 143.83623 | L24: =I23*2*3/12 -> 202.1142 | M24: =I24*0.25*2 -> 287.67245 | N24: =J24/2/12 -> 729.16815 | O24: =+(J24+K24+L24+M24+N24+U24) -> 18862.827 | P24: 1358.8529 | Q24: 849.28305 | R24: 2114.8155 | S24: =(K24+L24+M24+N24+J24)*0.04 -> 754.51307 | T24: =+P24+Q24+R24+S24 -> 5077.4645 | V24: 2000
B25: =B24+1 -> 24 | C25: LILIA KARINA SANDOVAL RODRIGUEZ | D25: LUDOTECA | E25: 46235 | F25: 46387 | G25: =YEAR(F25)-YEAR(E25) -> 0 | H25: =VLOOKUP(G25,Hoja5!$A$3:$B$38,2,0) -> 12 | I25: 575.3426 | J25: =I25*30.4166 -> 17499.966 | K25: =I25*H25*0.25/12 -> 143.83565 | L25: =I24*2*3/12 -> 287.67245 | M25: =I25*0.25*2 -> 287.6713 | N25: =J25/2/12 -> 729.16524 | O25: =+(J25+K25+L25+M25+N25+U25) -> 18948.31 | P25: 1358.8529 | Q25: 849.28305 | R25: 2114.8155 | S25: =(K25+L25+M25+N25+J25)*0.04 -> 757.93241 | T25: =+P25+Q25+R25+S25 -> 5080.8838 | V25: 2000
B26: =B25+1 -> 25 | C26: MARIA DEL CARMEN HERNANDEZ DE ANDA | D26: LUDOTECA | E26: 45983 | F26: 46387 | G26: =YEAR(F26)-YEAR(E26) -> 1 | H26: =VLOOKUP(G26,Hoja5!$A$3:$B$38,2,0) -> 12 | I26: 575.3426 | J26: =I26*30.4166 -> 17499.966 | K26: =I26*H26*0.25/12 -> 143.83565 | L26: =I25*2*3/12 -> 287.6713 | M26: =I26*0.25*2 -> 287.6713 | N26: =J26/2/12 -> 729.16524 | O26: =+(J26+K26+L26+M26+N26+U26) -> 18948.309 | P26: 3972.5717 | Q26: 2482.8573 | R26: 6164.5185 | S26: =(K26+L26+M26+N26+J26)*0.04 -> 757.93237 | T26: =+P26+Q26+R26+S26 -> 13377.88 | V26: 2000
B27: =B26+1 -> 26 | C27: JAZMIN SORIANO BARRERA | D27: LUDOTECA | E27: 46054 | F27: 46387 | G27: =YEAR(F27)-YEAR(E27) -> 0 | H27: =VLOOKUP(G27,Hoja5!$A$3:$B$38,2,0) -> 12 | I27: 401.5565 | J27: =I27*30.4166 -> 12213.983 | K27: =I27*H27*0.25/12 -> 100.38912 | L27: =I26*2*3/12 -> 287.6713 | M27: 0 | N27: =J27/2/12 -> 508.91598 | O27: =+(J27+K27+L27+M27+N27+U27) -> 13110.96 | P27: 1657.656 | Q27: 1036.035 | R27: 2486.4 | S27: =(K27+L27+M27+N27+J27)*0.04 -> 524.43839 | T27: =+P27+Q27+R27+S27 -> 5704.5294 | V27: 2000
B28: =B27+1 -> 27 | C28: BRENDA SEGURA DAVILA | D28: LUDOTECA | E28: 46235 | F28: 46387 | G28: =YEAR(F28)-YEAR(E28) -> 0 | H28: =VLOOKUP(G28,Hoja5!$A$3:$B$38,2,0) -> 12 | I28: 404.18 | J28: =I28*30.4166 -> 12293.781 | K28: =I28*H28*0.25/12 -> 101.045 | L28: =I27*2*3/12 -> 200.77825 | M28: =I28*0.25*2 -> 202.09 | N28: =J28/2/12 -> 512.24089 | O28: =+(J28+K28+L28+M28+N28+U28) -> 13309.936 | P28: 1358.8529 | Q28: 1145.4828 | R28: 3062.85 | S28: 588.77944 | T28: =+P28+Q28+R28+S28 -> 6155.9651 | U28: =SUM(U1:U27) -> 0 | V28: 2000
B29: =B28+1 -> 28 | C29: JOSE SANTOS PAZ GARCIA | D29: MANTENIMIENTO | E29: 42751 | F29: 46387 | G29: =YEAR(F29)-YEAR(E29) -> 9 | H29: =VLOOKUP(G29,Hoja5!$A$3:$B$38,2,0) -> 22 | I29: 488.51 | J29: =I29*30.4166 -> 14858.813 | K29: =I29*H29*0.25/12 -> 223.90042 | L29: =I28*2*3/12 -> 202.09 | M29: =I29*0.25*2 -> 244.255 | N29: =J29/2/12 -> 619.11722 | O29: =+(J29+K29+L29+M29+N29+U29) -> 16148.176 | P29: 1358.8529 | Q29: 1145.4828 | R29: 2114.8155 | S29: =O29*0.04 -> 645.92704 | T29: =+P29+Q29+R29+S29 -> 5265.0782 | V29: 3500
B30: =B29+1 -> 29 | C30: MIGUEL ROBELO MORELOS | D30: MANTENIMIENTO | E30: 45145 | F30: 46387 | G30: =YEAR(F30)-YEAR(E30) -> 3 | H30: =VLOOKUP(G30,Hoja5!$A$3:$B$38,2,0) -> 16 | I30: 488.51 | J30: =I30*30.4166 -> 14858.813 | K30: =I30*H30*0.25/12 -> 162.83667 | L30: =I29*2*3/12 -> 244.255 | M30: =I30*0.25*2 -> 244.255 | N30: =J30/2/12 -> 619.11722 | O30: =+(J30+K30+L30+M30+N30+U30) -> 16129.277 | P30: 1358.8529 | Q30: 1145.4828 | R30: 2265.9 | S30: =O30*0.04 -> 645.17109 | T30: =+P30+Q30+R30+S30 -> 5415.4068 | V30: 2000
B31: =B30+1 -> 30 | C31: BENJAMIN MACEDONIO MEJIA | D31: MANTENIMIENTO | E31: 45253 | F31: 46387 | G31: =YEAR(F31)-YEAR(E31) -> 3 | H31: =VLOOKUP(G31,Hoja5!$A$3:$B$38,2,0) -> 16 | I31: 488.51 | J31: =I31*30.4166 -> 14858.813 | K31: =I31*H31*0.25/12 -> 162.83667 | L31: =I30*2*3/12 -> 244.255 | M31: =I31*0.25*2 -> 244.255 | N31: =J31/2/12 -> 619.11722 | O31: =+(J31+K31+L31+M31+N31+U31) -> 16129.277 | P31: 1358.8529 | Q31: 1145.4828 | R31: 2114.8155 | S31: =O31*0.04 -> 645.17109 | T31: =+P31+Q31+R31+S31 -> 5264.3223 | V31: 2000
B32: =B31+1 -> 31 | C32: JAVIER LOPEZ SANTOS | D32: MANTENIMIENTO | E32: 45505 | F32: 46387 | G32: =YEAR(F32)-YEAR(E32) -> 2 | H32: =VLOOKUP(G32,Hoja5!$A$3:$B$38,2,0) -> 14 | I32: 488.51 | J32: =I32*30.4166 -> 14858.813 | K32: =I32*H32*0.25/12 -> 142.48208 | L32: =I31*2*3/12 -> 244.255 | M32: =I32*0.25*2 -> 244.255 | N32: =J32/2/12 -> 619.11722 | O32: =+(J32+K32+L32+M32+N32+U32) -> 16108.923 | P32: 1358.8529 | Q32: 1145.4828 | R32: 2114.8155 | S32: =O32*0.04 -> 644.3569 | T32: =+P32+Q32+R32+S32 -> 5263.5081 | V32: 2000
B33: =B32+1 -> 32 | C33: ALEJANDRO REYES PEDRAZA GONZALEZ | D33: MANTENIMIENTO | E33: 45877 | F33: 46387 | G33: =YEAR(F33)-YEAR(E33) -> 1 | H33: =VLOOKUP(G33,Hoja5!$A$3:$B$38,2,0) -> 12 | I33: 488.51 | J33: =I33*30.4166 -> 14858.813 | K33: =I33*H33*0.25/12 -> 122.1275 | L33: =I32*2*3/12 -> 244.255 | M33: 0 | N33: =J33/2/12 -> 619.11722 | O33: =+(J33+K33+L33+M33+N33+U33) -> 15844.313 | P33: 1358.8529 | Q33: 1145.4828 | R33: 3062.85 | S33: =O33*0.04 -> 633.77252 | T33: =+P33+Q33+R33+S33 -> 6200.9582 | V33: 2000
B34: =B33+1 -> 33 | C34: OSCAR RAYMUNDO GRAJALES | D34: MANTENIMIENTO | E34: 46054 | F34: 46387 | G34: =YEAR(F34)-YEAR(E34) -> 0 | H34: =VLOOKUP(G34,Hoja5!$A$3:$B$38,2,0) -> 12 | I34: 488.51 | J34: =I34*30.4166 -> 14858.813 | K34: =I34*H34*0.25/12 -> 122.1275 | L34: =I33*2*3/12 -> 244.255 | M34: =I34*0.25*2 -> 244.255 | N34: =J34/2/12 -> 619.11722 | O34: =+(J34+K34+L34+M34+N34+U34) -> 16088.568 | P34: 1358.8529 | Q34: 1145.4828 | R34: 3062.85 | S34: =O34*0.04 -> 643.54272 | T34: =+P34+Q34+R34+S34 -> 6210.7284 | V34: 2000
B35: =B34+1 -> 34 | C35: REY DAVID MELGAR TAPIA | D35: MANTENIMIENTO | E35: 46063 | F35: 46387 | G35: =YEAR(F35)-YEAR(E35) -> 0 | H35: =VLOOKUP(G35,Hoja5!$A$3:$B$38,2,0) -> 12 | I35: 488.51 | J35: =I35*30.4166 -> 14858.813 | K35: =I35*H35*0.25/12 -> 122.1275 | L35: =I34*2*3/12 -> 244.255 | M35: =I35*0.25*2 -> 244.255 | N35: =J35/2/12 -> 619.11722 | O35: =+(J35+K35+L35+M35+N35+U35) -> 16088.568 | P35: 1358.8529 | Q35: 1145.4828 | R35: 3062.85 | S35: =O35*0.04 -> 643.54272 | T35: =+P35+Q35+R35+S35 -> 6210.7284 | V35: 2000
