Workbook

Sheet 1. CIERRE COBRANZA
K4: PT INTERNO
K5: CUOTAS ANTICIPADAS | M5: =+'PT7'!D272 -> -2442352
B6: CIERRE COBRANZA | E6: =[1]!'@PERIODO[A]' -> Abril/2026 | K6: SALDO SEGÚN BALANZA | M6: =+D14+M5 -> -1759205
B8: NUM | C8: CLASIFICACIÓN | D8: SALDO | E8: %
B11: 1 | C11: =+'PT3'!B2 -> COBRANZA JUDICIAL | D11: =+'PT3'!D272 -> 386066 | E11: =+D11/$D$14 -> 0.56512874
B12: 2 | C12: =+'PT4'!B2 -> MOROSOS | D12: =+'PT4'!D272 -> 203314 | E12: =+D12/$D$14 -> 0.29761384
B13: 3 | C13: =+'PT5'!B2 -> DEUDA CORRIENTE | D13: =+'PT5'!D272 -> 93767 | E13: =+D13/$D$14 -> 0.13725743 | M13: NO AGREGAR A PRESENTACIÓN
C14: DEUDA CONDOMINOS | D14: =SUM(D11:D13) -> 683147 | E14: =SUM(E11:E13) -> 1
C17: NOTA:
C18: C PERFECTA MENSUAL | D18: 1449000

Sheet 1. ANALISIS COB
L1: =[1]!'@PERIODO[A]' -> Abril/2026
B2: CONJUNTO RESIDENCIAL AVIVIA 58, A.C.
B4: Analisis de cobranza mensual
B5: ="Al " & DAY(EOMONTH(L1,0))&" "&L1 -> Al 30 Abril/2026
B9: ID | C9: CLASIFICACIÓN | D9: SALDO | E9: %
B11: COBRANZA PERFECTA | D11: =+B18*B19 -> 3960656 | E11: 1
B13: 2 | C13: =+'PT4'!B2 -> MOROSOS | D13: =+'PT4'!D272 -> 203314 | E13: =+D13/$D$11 -> 0.051333415
B14: 3 | C14: =+'PT5'!B2 -> DEUDA CORRIENTE | D14: =+'PT5'!D272 -> 93767 | E14: =+D14/$D$11 -> 0.023674613
C15: COBRADO | D15: =+D11-D13-D14 -> 3663575 | E15: =+D15/$D$11 -> 0.92499197
B17: NOTAS:
B18: 312 | C18: DEPTOS
B19: 12694.41 | C19: CUOTA MENSUAL
B22: DEUDA CONDOMINOS (EF)
B23: 1 | C23: =+'PT2 (FILTRAR)'!I5 -> COBRANZA JUDICIAL | D23: =+'PT3'!D272 -> 386066 | E23: =+D23/D26 -> 0.56512874
B24: 2 | C24: =+'PT2 (FILTRAR)'!I6 -> MOROSOS | D24: =+'PT4'!D272 -> 203314 | E24: =+D24/D26 -> 0.29761384
B25: 3 | C25: =+'PT2 (FILTRAR)'!I7 -> DEUDA CORRIENTE | D25: =+'PT5'!D272 -> 93767 | E25: =+D25/D26 -> 0.13725743
C26: TOTAL | D26: =+D23+D24+D25 -> 683147 | E26: =SUM(E23:E25) -> 1
J28: NO AGREGAR A PRESENTACIÓN
J31: PT INTERNO
J32: CUOTAS ANTICIPADAS | K32: =+'PT7'!D272-'PT1'!D318 -> -2442352
J33: NO IDENTIFICADOS | K33: =+'PT1'!D318 -> 3.6379788e-12
J34: SALDO SEGÚN BALANZA | K34: =+D26+K32+K33 -> -1759205

Sheet 2. INTEGRACIÓN
B2: INTEGRACIÓN DE DEUDA
B3: =[1]!'@PERIODO[A]' -> Abril/2026
B5: 1. C JUDICIAL | C5: SALDO | D5: STATUS LEGAL | F5: 2. MOROSOS | G5: SALDO | H5: OBSERVACIONES | J5: 3. DEUDA CORRIENTE | K5: SALDO | M5: SIN ADEUDO | N5: SALDO | P5: ANTICIPOS | Q5: SALDO | U5: MOROSOS | V5: JUDICIAL
B6: =LEFT('PT3'!C5,6) -> C3-211 | C6: =+'PT3'!D5 -> 112266 | D6: AGREGAR STATUS | F6: =LEFT('PT4'!C5,6) -> O2-120 | G6: =+'PT4'!D5 -> 39841 | H6: AGREGAR STATUS | J6: =LEFT('PT5'!C5,6) -> O1-230 | K6: =+'PT5'!D5 -> 13694 | M6: =LEFT('PT6'!C5,6) -> C2-141 | N6: =+'PT6'!D5 -> 0 | P6: =LEFT('PT7'!C5,6) -> O2-210 | Q6: =+'PT7'!D5 -> -2.910383e-11 | U6: AGREGAR STATUS | V6: AGREGAR STATUS
B7: =LEFT('PT3'!C6,6) -> O1-240 | C7: =+'PT3'!D6 -> 180472 | D7: AGREGAR STATUS | F7: =LEFT('PT4'!C6,6) -> O2-220 | G7: =+'PT4'!D6 -> 27288 | H7: AGREGAR STATUS | J7: =LEFT('PT5'!C6,6) -> C1-707 | K7: =+'PT5'!D6 -> 13694 | M7: =LEFT('PT6'!C6,6) -> C3-121 | N7: =+'PT6'!D6 -> 0 | P7: =LEFT('PT7'!C6,6) -> O1-100 | Q7: =+'PT7'!D6 -> -2.910383e-11 | U7: SERVICIOS CERRADOS | V7: PENDIENTE APROBACIÓN COMITÉ
B8: =LEFT('PT3'!C7,6) -> O2-100 | C8: =+'PT3'!D7 -> 93328 | D8: AGREGAR STATUS | F8: =LEFT('PT4'!C7,6) -> A-501 | G8: =+'PT4'!D7 -> 25000 | H8: AGREGAR STATUS | J8: =LEFT('PT5'!C7,6) -> O2-PH0 | K8: =+'PT5'!D7 -> 300 | M8: =LEFT('PT6'!C7,6) -> O1-404 | N8: =+'PT6'!D7 -> 0 | P8: =LEFT('PT7'!C7,6) -> C3-161 | Q8: =+'PT7'!D7 -> -98504 | U8: EN CONVENIO | V8: EN CONVENIO
B9: =LEFT('PT3'!C8,6) | C9: =+'PT3'!D8 | D9: AGREGAR STATUS | F9: =LEFT('PT4'!C8,6) -> A-2201 | G9: =+'PT4'!D8 -> 28188 | H9: AGREGAR STATUS | J9: =LEFT('PT5'!C8,6) -> C1-250 | K9: =+'PT5'!D8 -> 13694 | M9: =LEFT('PT6'!C8,6) -> A-1802 | N9: =+'PT6'!D8 -> 0 | P9: =LEFT('PT7'!C8,6) -> A-2301 | Q9: =+'PT7'!D8 -> -2.910383e-11 | U9: EN ACLARACIÓN POR PARTE DE CONDOMINO | V9: FASE 1 - DEMANDA
B10: =LEFT('PT3'!C9,6) | C10: =+'PT3'!D9 | D10: AGREGAR STATUS | F10: =LEFT('PT4'!C9,6) -> O2-190 | G10: =+'PT4'!D9 -> 27153 | H10: AGREGAR STATUS | J10: =LEFT('PT5'!C9,6) -> O2-220 | K10: =+'PT5'!D9 -> 500 | M10: =LEFT('PT6'!C9,6) -> A-2402 | N10: =+'PT6'!D9 -> 0 | P10: =LEFT('PT7'!C9,6) -> A-102 | Q10: =+'PT7'!D9 -> -12694 | V10: FASE 2 - ADMISIÓN DE DEMANDA
B11: =LEFT('PT3'!C10,6) | C11: =+'PT3'!D10 | D11: AGREGAR STATUS | F11: =LEFT('PT4'!C10,6) -> C1-507 | G11: =+'PT4'!D10 -> 27888 | H11: AGREGAR STATUS | J11: =LEFT('PT5'!C10,6) -> C1-150 | K11: =+'PT5'!D10 -> 13694 | M11: =LEFT('PT6'!C10,6) -> O2-170 | N11: =+'PT6'!D10 -> 0 | P11: =LEFT('PT7'!C10,6) -> A-202 | Q11: =+'PT7'!D10 -> -12694 | V11: FASE 3 - EMPLAZAMIENTO DE EMBARGO
B12: =LEFT('PT3'!C11,6) | C12: =+'PT3'!D11 | D12: AGREGAR STATUS | F12: =LEFT('PT4'!C11,6) -> C3-111 | G12: =+'PT4'!D11 -> 27956 | H12: AGREGAR STATUS | J12: =LEFT('PT5'!C11,6) -> C3-512 | K12: =+'PT5'!D11 -> 300 | M12: =LEFT('PT6'!C11,6) -> C1-207 | N12: =+'PT6'!D11 -> 0 | P12: =LEFT('PT7'!C11,6) -> A-301 | Q12: =+'PT7'!D11 -> -38082 | V12: FASE 4 - CONTESTACIÓN DE DEMANDA
B13: =LEFT('PT3'!C12,6) | C13: =+'PT3'!D12 | D13: AGREGAR STATUS | F13: =LEFT('PT4'!C12,6) | G13: =+'PT4'!D12 | H13: AGREGAR STATUS | J13: =LEFT('PT5'!C12,6) -> C2-220 | K13: =+'PT5'!D12 -> 1.4551915e-11 | M13: =LEFT('PT6'!C12,6) -> C1-140 | N13: =+'PT6'!D12 -> 0 | P13: =LEFT('PT7'!C12,6) -> A-402 | Q13: =+'PT7'!D12 -> -12694 | V13: FASE 5 - SENTENCIA
B14: =LEFT('PT3'!C13,6) | C14: =+'PT3'!D13 | D14: AGREGAR STATUS | F14: =LEFT('PT4'!C13,6) | G14: =+'PT4'!D13 | H14: AGREGAR STATUS | J14: =LEFT('PT5'!C13,6) -> A-1702 | K14: =+'PT5'!D13 -> 500 | M14: =LEFT('PT6'!C13,6) -> C1-170 | N14: =+'PT6'!D13 -> 0 | P14: =LEFT('PT7'!C13,6) -> A-702 | Q14: =+'PT7'!D13 -> -2.910383e-11 | V14: TRIBUNALES EN RECESO
B15: =LEFT('PT3'!C14,6) | C15: =+'PT3'!D14 | D15: AGREGAR STATUS | F15: =LEFT('PT4'!C14,6) | G15: =+'PT4'!D14 | H15: AGREGAR STATUS | J15: =LEFT('PT5'!C14,6) -> O1-503 | K15: =+'PT5'!D14 -> 7.9580786e-13 | M15: =LEFT('PT6'!C14,6) -> O2-405 | N15: =+'PT6'!D14 -> 0 | P15: =LEFT('PT7'!C14,6) -> A-802 | Q15: =+'PT7'!D14 -> -1000 | V15: OTRO
B16: =LEFT('PT3'!C15,6) | C16: =+'PT3'!D15 | D16: AGREGAR STATUS | F16: =LEFT('PT4'!C15,6) | G16: =+'PT4'!D15 | H16: AGREGAR STATUS | J16: =LEFT('PT5'!C15,6) -> O1-140 | K16: =+'PT5'!D15 -> 500 | M16: =LEFT('PT6'!C15,6) -> C1-100 | N16: =+'PT6'!D15 -> 0 | P16: =LEFT('PT7'!C15,6) -> A-1602 | Q16: =+'PT7'!D15 -> -98504
B17: =LEFT('PT3'!C16,6) | C17: =+'PT3'!D16 | D17: AGREGAR STATUS | F17: =LEFT('PT4'!C16,6) | G17: =+'PT4'!D16 | H17: AGREGAR STATUS | J17: =LEFT('PT5'!C16,6) -> O1-200 | K17: =+'PT5'!D16 -> 300 | M17: =LEFT('PT6'!C16,6) -> C1-160 | N17: =+'PT6'!D16 -> 0 | P17: =LEFT('PT7'!C16,6) -> O1-403 | Q17: =+'PT7'!D16 -> -12694
B18: =LEFT('PT3'!C17,6) | C18: =+'PT3'!D17 | D18: AGREGAR STATUS | F18: =LEFT('PT4'!C17,6) | G18: =+'PT4'!D17 | H18: AGREGAR STATUS | J18: =LEFT('PT5'!C17,6) -> O2-206 | K18: =+'PT5'!D17 -> 500 | M18: =LEFT('PT6'!C17,6) -> C2-309 | N18: =+'PT6'!D17 -> 0 | P18: =LEFT('PT7'!C17,6) -> O1-604 | Q18: =+'PT7'!D17 -> -12694
B19: =LEFT('PT3'!C18,6) | C19: =+'PT3'!D18 | D19: AGREGAR STATUS | F19: =LEFT('PT4'!C18,6) | G19: =+'PT4'!D18 | H19: AGREGAR STATUS | J19: =LEFT('PT5'!C18,6) -> O2-305 | K19: =+'PT5'!D18 -> 300 | M19: =LEFT('PT6'!C18,6) -> C3-712 | N19: =+'PT6'!D18 -> 0 | P19: =LEFT('PT7'!C18,6) -> O1-704 | Q19: =+'PT7'!D18 -> -10000
B20: =LEFT('PT3'!C19,6) | C20: =+'PT3'!D19 | D20: AGREGAR STATUS | F20: =LEFT('PT4'!C19,6) | G20: =+'PT4'!D19 | H20: AGREGAR STATUS | J20: =LEFT('PT5'!C19,6) -> O2-120 | K20: =+'PT5'!D19 -> 7039 | M20: =LEFT('PT6'!C19,6) -> A-1401 | N20: =+'PT6'!D19 -> 0 | P20: =LEFT('PT7'!C19,6) -> O1-100 | Q20: =+'PT7'!D19 -> -12694
B21: =LEFT('PT3'!C20,6) | C21: =+'PT3'!D20 | D21: AGREGAR STATUS | F21: =LEFT('PT4'!C20,6) | G21: =+'PT4'!D20 | H21: AGREGAR STATUS | J21: =LEFT('PT5'!C20,6) -> O2-PH0 | K21: =+'PT5'!D20 -> 7039 | M21: =LEFT('PT6'!C20,6) -> O1-120 | N21: =+'PT6'!D20 -> 0 | P21: =LEFT('PT7'!C20,6) -> O1-120 | Q21: =+'PT7'!D20 -> -12694
B22: =LEFT('PT3'!C21,6) | C22: =+'PT3'!D21 | D22: AGREGAR STATUS | F22: =LEFT('PT4'!C21,6) | G22: =+'PT4'!D21 | H22: AGREGAR STATUS | J22: =LEFT('PT5'!C21,6) -> C1-240 | K22: =+'PT5'!D21 -> 1000 | M22: =LEFT('PT6'!C21,6) -> O1-PH0 | N22: =+'PT6'!D21 -> 0 | P22: =LEFT('PT7'!C21,6) -> O1-170 | Q22: =+'PT7'!D21 -> -98504
B23: =LEFT('PT3'!C22,6) | C23: =+'PT3'!D22 | D23: AGREGAR STATUS | F23: =LEFT('PT4'!C22,6) | G23: =+'PT4'!D22 | H23: AGREGAR STATUS | J23: =LEFT('PT5'!C22,6) -> C1-240 | K23: =+'PT5'!D22 -> 3519 | M23: =LEFT('PT6'!C22,6) -> C3-612 | N23: =+'PT6'!D22 -> 0 | P23: =LEFT('PT7'!C22,6) -> O1-180 | Q23: =+'PT7'!D22 -> -98504
B24: =LEFT('PT3'!C23,6) | C24: =+'PT3'!D23 | D24: AGREGAR STATUS | F24: =LEFT('PT4'!C23,6) | G24: =+'PT4'!D23 | H24: AGREGAR STATUS | J24: =LEFT('PT5'!C23,6) -> C2-809 | K24: =+'PT5'!D23 -> 300 | M24: =LEFT('PT6'!C23,6) -> A-1001 | N24: =+'PT6'!D23 -> 0 | P24: =LEFT('PT7'!C23,6) -> O2-105 | Q24: =+'PT7'!D23 -> -98504
B25: =LEFT('PT3'!C24,6) | C25: =+'PT3'!D24 | D25: AGREGAR STATUS | F25: =LEFT('PT4'!C24,6) | G25: =+'PT4'!D24 | H25: AGREGAR STATUS | J25: =LEFT('PT5'!C24,6) -> C2-111 | K25: =+'PT5'!D24 -> 500 | M25: =LEFT('PT6'!C24,6) -> A-1002 | N25: =+'PT6'!D24 -> 0 | P25: =LEFT('PT7'!C24,6) -> O2-606 | Q25: =+'PT7'!D24 -> -12694
B26: =LEFT('PT3'!C25,6) | C26: =+'PT3'!D25 | D26: AGREGAR STATUS | F26: =LEFT('PT4'!C25,6) | G26: =+'PT4'!D25 | H26: AGREGAR STATUS | J26: =LEFT('PT5'!C25,6) -> C2-201 | K26: =+'PT5'!D25 -> 600 | M26: =LEFT('PT6'!C25,6) -> O1-190 | N26: =+'PT6'!D25 -> 0 | P26: =LEFT('PT7'!C25,6) -> O2-110 | Q26: =+'PT7'!D25 -> -12694
B27: =LEFT('PT3'!C26,6) | C27: =+'PT3'!D26 | F27: =LEFT('PT4'!C26,6) | G27: =+'PT4'!D26 | J27: =LEFT('PT5'!C26,6) -> C3-111 | K27: =+'PT5'!D26 -> 300 | M27: =LEFT('PT6'!C26,6) -> C2-310 | N27: =+'PT6'!D26 -> 0 | P27: =LEFT('PT7'!C26,6) -> O2-250 | Q27: =+'PT7'!D26 -> -12694
B28: =LEFT('PT3'!C27,6) | C28: =+'PT3'!D27 | F28: =LEFT('PT4'!C27,6) | G28: =+'PT4'!D27 | J28: =LEFT('PT5'!C27,6) -> A-2401 | K28: =+'PT5'!D27 -> 3.6379788e-12 | M28: =LEFT('PT6'!C27,6) -> A-101 | N28: =+'PT6'!D27 -> 0 | P28: =LEFT('PT7'!C27,6) -> C1-107 | Q28: =+'PT7'!D27 -> -98504
B29: =LEFT('PT3'!C28,6) | C29: =+'PT3'!D28 | F29: =LEFT('PT4'!C28,6) | G29: =+'PT4'!D28 | J29: =LEFT('PT5'!C28,6) -> O2-506 | K29: =+'PT5'!D28 -> 15194 | M29: =LEFT('PT6'!C28,6) -> A-201 | N29: =+'PT6'!D28 -> 0 | P29: =LEFT('PT7'!C28,6) -> C1-120 | Q29: =+'PT7'!D28 -> -306
B30: =LEFT('PT3'!C29,6) | C30: =+'PT3'!D29 | F30: =LEFT('PT4'!C29,6) | G30: =+'PT4'!D29 | J30: =LEFT('PT5'!C29,6) -> O2-150 | K30: =+'PT5'!D29 -> 300 | M30: =LEFT('PT6'!C29,6) -> A-302 | N30: =+'PT6'!D29 -> 0 | P30: =LEFT('PT7'!C29,6) -> C1-210 | Q30: =+'PT7'!D29 -> -98504
B31: =LEFT('PT3'!C30,6) | C31: =+'PT3'!D30 | F31: =LEFT('PT4'!C30,6) | G31: =+'PT4'!D30 | J31: =LEFT('PT5'!C30,6) -> NO IDE | K31: =+'PT5'!D30 -> 3.6379788e-12 | M31: =LEFT('PT6'!C30,6) -> A-401 | N31: =+'PT6'!D30 -> 0 | P31: =LEFT('PT7'!C30,6) -> C2-909 | Q31: =+'PT7'!D30 -> -12694
B32: =LEFT('PT3'!C31,6) | C32: =+'PT3'!D31 | F32: =LEFT('PT4'!C31,6) | G32: =+'PT4'!D31 | J32: =LEFT('PT5'!C31,6) | K32: =+'PT5'!D31 | M32: =LEFT('PT6'!C31,6) -> A-502 | N32: =+'PT6'!D31 -> 0 | P32: =LEFT('PT7'!C31,6) -> C2-110 | Q32: =+'PT7'!D31 -> -12694
B33: =LEFT('PT3'!C32,6) | C33: =+'PT3'!D32 | F33: =LEFT('PT4'!C32,6) | G33: =+'PT4'!D32 | J33: =LEFT('PT5'!C32,6) | K33: =+'PT5'!D32 | M33: =LEFT('PT6'!C32,6) -> A-601 | N33: =+'PT6'!D32 -> 0 | P33: =LEFT('PT7'!C32,6) -> C2-121 | Q33: =+'PT7'!D32 -> -38082
B34: =LEFT('PT3'!C33,6) | C34: =+'PT3'!D33 | F34: =LEFT('PT4'!C33,6) | G34: =+'PT4'!D33 | J34: =LEFT('PT5'!C33,6) | K34: =+'PT5'!D33 | M34: =LEFT('PT6'!C33,6) -> A-701 | N34: =+'PT6'!D33 -> 0 | P34: =LEFT('PT7'!C33,6) -> C2-PH1 | Q34: =+'PT7'!D33 -> -12694
B35: =LEFT('PT3'!C34,6) | C35: =+'PT3'!D34 | F35: =LEFT('PT4'!C34,6) | G35: =+'PT4'!D34 | J35: =LEFT('PT5'!C34,6) | K35: =+'PT5'!D34 | M35: =LEFT('PT6'!C34,6) -> A-801 | N35: =+'PT6'!D34 -> 0 | P35: =LEFT('PT7'!C34,6) -> C3-311 | Q35: =+'PT7'!D34 -> -98504
B36: =LEFT('PT3'!C35,6) | C36: =+'PT3'!D35 | F36: =LEFT('PT4'!C35,6) | G36: =+'PT4'!D35 | J36: =LEFT('PT5'!C35,6) | K36: =+'PT5'!D35 | M36: =LEFT('PT6'!C35,6) -> A-901 | N36: =+'PT6'!D35 -> 0 | P36: =LEFT('PT7'!C35,6) -> C3-312 | Q36: =+'PT7'!D35 -> -12694
B37: =LEFT('PT3'!C36,6) | C37: =+'PT3'!D36 | F37: =LEFT('PT4'!C36,6) | G37: =+'PT4'!D36 | J37: =LEFT('PT5'!C36,6) | K37: =+'PT5'!D36 | M37: =LEFT('PT6'!C36,6) -> A-902 | N37: =+'PT6'!D36 -> 0 | P37: =LEFT('PT7'!C36,6) -> C3-412 | Q37: =+'PT7'!D36 -> -200
B38: =LEFT('PT3'!C37,6) | C38: =+'PT3'!D37 | F38: =LEFT('PT4'!C37,6) | G38: =+'PT4'!D37 | J38: =LEFT('PT5'!C37,6) | K38: =+'PT5'!D37 | M38: =LEFT('PT6'!C37,6) -> A-1101 | N38: =+'PT6'!D37 -> 0 | P38: =LEFT('PT7'!C37,6) -> C3-511 | Q38: =+'PT7'!D37 -> -12694
... B271: =LEFT('PT3'!C270,6) | C271: =+'PT3'!D270 | F271: =LEFT('PT4'!C270,6) | G271: =+'PT4'!D270 | J271: =LEFT('PT5'!C270,6) | K271: =+'PT5'!D270 | M271: =LEFT('PT6'!C270,6) | N271: =+'PT6'!D270 | P271: =LEFT('PT7'!C270,6) | Q271: =+'PT7'!D270
B272: =LEFT('PT3'!C271,6) | C272: =+'PT3'!D271 | F272: =LEFT('PT4'!C271,6) | G272: =+'PT4'!D271 | M272: =LEFT('PT6'!C271,6) | N272: =+'PT6'!D271 | P272: =LEFT('PT7'!C271,6) | Q272: =+'PT7'!D271
C273: =SUM(C6:C272) -> 386066 | G273: =SUM(G6:G272) -> 203314 | K273: =SUM(K6:K272) -> 93767 | N273: =SUM(N6:N272) -> 0 | Q273: =SUM(Q6:Q272) -> -2442352

Sheet PT1
B3: SALDO CONDOMINOS
B5: CTA | C5: CONDOMINO | D5: =[1]!'@PERIODO[A]' -> Abril/2026
B6: {=[2]!'@CTA[104-001-001..104-001-052, U, N, F]'} -> 104-001-001 | C6: A-101 DANIEL DANA | D6: 0
B7: 104-001-002 | C7: A-102 ANTONIO BELLORIN | D7: -12694
B8: 104-001-003 | C8: A-201 ALBERTO TARTAKOVSKI | D8: 0
B9: 104-001-004 | C9: A-202 CAROLINA OMAÑA | D9: -12694
B10: 104-001-005 | C10: A-301 KAREN VELASQUEZ | D10: -38082
B11: 104-001-006 | C11: A-302 MANUEL DAVID | D11: 0
B12: 104-001-007 | C12: A-401 MARIO MIZRAHI | D12: 0
B13: 104-001-008 | C13: A-402 ANASTASIA BELLIS | D13: -12694
B14: 104-001-009 | C14: A-501 ALEJANDRO GOLDEBERG | D14: 25000
B15: 104-001-010 | C15: A-502 DANIEL DAVID | D15: 0
B16: 104-001-011 | C16: A-601 LUIS JIMENEZ ALFARO | D16: 0
B17: 104-001-012 | C17: A-602 EMILIO SACAL | D17: 0
B18: 104-001-013 | C18: A-701 BELORA LEVY | D18: 0
... B57: 104-001-052 | C57: A-PH02 SALOMON JASQUI | D57: 0
B58: {=[2]!'@CTA[104-002-001..104-002-052, U, N, F]'} -> 104-002-001 | C58: O1-103 BENJAMIN LOMBROZO | D58: 0
B59: 104-002-002 | C59: O1-104 JACK SASSON | D59: 0
B60: 104-002-003 | C60: O1-203 ARIELA ROSENSTEIN | D60: 0
B61: 104-002-004 | C61: O1-204 SELENE CAPDEVILA | D61: 0
B62: 104-002-005 | C62: O1-303 RAFAEL ZAGA | D62: 0
B63: 104-002-006 | C63: O1-304 JOSEF HABER | D63: 0
B64: 104-002-007 | C64: O1-403 JOSE MIZRAHI | D64: -12694
B65: 104-002-008 | C65: O1-404 IVAN ROJAS | D65: 0
B66: 104-002-009 | C66: O1-503 DAVIDE TOMASSONI | D66: 7.9580786e-13
B67: 104-002-010 | C67: O1-504 REBECA CASTRO | D67: 0
B68: 104-002-011 | C68: O1-603 JACOBO CHEREM A | D68: 0
B69: 104-002-012 | C69: O1-604 ALBERTO SAAD | D69: -12694
B70: 104-002-013 | C70: O1-703 ANA VAZQUEZ | D70: 0
... B109: 104-002-052 | C109: O1-PH04 JACOBO CHEREM HARARI | D109: 0
B110: {=[2]!'@CTA[104-003-001..104-003-052, U, N, F]'} -> 104-003-001 | C110: O2-105 YAMIL MAFUD | D110: -98504
B111: 104-003-002 | C111: O2-106 SADEGH HARARI | D111: 0
B112: 104-003-003 | C112: O2-205 ISAAC JAMMAL | D112: 0
B113: 104-003-004 | C113: O2-206 JUAN GARCIA | D113: 500
B114: 104-003-005 | C114: O2-305 MOISES HOP | D114: 300
B115: 104-003-006 | C115: O2-306 RAQUEL SHEMARIA | D115: 0
B116: 104-003-007 | C116: O2-405 MONICA COLOMER | D116: 0
B117: 104-003-008 | C117: O2-406 JOSE CHONTKOWSKY | D117: 0
B118: 104-003-009 | C118: O2-505 CINDY LEVY | D118: 0
B119: 104-003-010 | C119: O2-506 NAIRO VARGAS | D119: 15194
...

Sheet PT2 (FILTRAR)
B2: STATUS COBRANZA
B4: CTA | C4: CONDOMINO | D4: TOTAL | E4: CLASIFICACIÓN | I4: STATUS | J4: DESDE | K4: HASTA
B5: =+'PT1'!B241 -> 104-005-028 | C5: =+'PT1'!C241 -> C2-1410 SARITA AGAMI M | D5: =+'PT1'!D241 -> 0 | E5: =IF(D5<0,"ANTICIPOS",IF(D5=$J$8,"SIN ADEUDO",IF(D5<=$K$7,"DEUDA CORRIENTE",IF(D5<=$K$6,"MOROSOS",IF(D5>$J$5,"COBRANZA JUDICIAL"))))) -> SIN ADEUDO | I5: COBRANZA JUDICIAL | J5: 60000 | K5: EN ADELANTE
B6: =+'PT1'!B132 -> 104-003-023 | C6: =+'PT1'!C132 -> O2-1205 ABRAHAM ROFFE | D6: =+'PT1'!D132 -> 39841 | E6: =IF(D6<0,"ANTICIPOS",IF(D6=$J$8,"SIN ADEUDO",IF(D6<=$K$7,"DEUDA CORRIENTE",IF(D6<=$K$6,"MOROSOS",IF(D6>$J$5,"COBRANZA JUDICIAL"))))) -> MOROSOS | I6: MOROSOS | J6: 20000 | K6: 59999.99
B7: =+'PT1'!B289 -> 104-006-024 | C7: =+'PT1'!C289 -> C3-1212 FORTUNA CASSAB | D7: =+'PT1'!D289 -> 0 | E7: =IF(D7<0,"ANTICIPOS",IF(D7=$J$8,"SIN ADEUDO",IF(D7<=$K$7,"DEUDA CORRIENTE",IF(D7<=$K$6,"MOROSOS",IF(D7>$J$5,"COBRANZA JUDICIAL"))))) -> SIN ADEUDO | I7: DEUDA CORRIENTE | J7: 0.01 | K7: 19999.99
B8: =+'PT1'!B65 -> 104-002-008 | C8: =+'PT1'!C65 -> O1-404 IVAN ROJAS | D8: =+'PT1'!D65 -> 0 | E8: =IF(D8<0,"ANTICIPOS",IF(D8=$J$8,"SIN ADEUDO",IF(D8<=$K$7,"DEUDA CORRIENTE",IF(D8<=$K$6,"MOROSOS",IF(D8>$J$5,"COBRANZA JUDICIAL"))))) -> SIN ADEUDO | I8: SIN ADEUDO | J8: 0 | K8: 0
B9: =+'PT1'!B151 -> 104-003-042 | C9: =+'PT1'!C151 -> O2-2106 JACOBO MIZRAHI | D9: =+'PT1'!D151 -> -2.910383e-11 | E9: =IF(D9<0,"ANTICIPOS",IF(D9=$J$8,"SIN ADEUDO",IF(D9<=$K$7,"DEUDA CORRIENTE",IF(D9<=$K$6,"MOROSOS",IF(D9>$J$5,"COBRANZA JUDICIAL"))))) -> ANTICIPOS | I9: ANTICIPOS | J9: -0.01 | K9: EN ADELANTE
B10: =+'PT1'!B77 -> 104-002-020 | C10: =+'PT1'!C77 -> O1-1004 NISSIM MANN | D10: =+'PT1'!D77 -> -2.910383e-11 | E10: =IF(D10<0,"ANTICIPOS",IF(D10=$J$8,"SIN ADEUDO",IF(D10<=$K$7,"DEUDA CORRIENTE",IF(D10<=$K$6,"MOROSOS",IF(D10>$J$5,"COBRANZA JUDICIAL"))))) -> ANTICIPOS
B11: =+'PT1'!B102 -> 104-002-045 | C11: =+'PT1'!C102 -> O1-2303 ISAAC HOP | D11: =+'PT1'!D102 -> 13694 | E11: =IF(D11<0,"ANTICIPOS",IF(D11=$J$8,"SIN ADEUDO",IF(D11<=$K$7,"DEUDA CORRIENTE",IF(D11<=$K$6,"MOROSOS",IF(D11>$J$5,"COBRANZA JUDICIAL"))))) -> DEUDA CORRIENTE
B12: =+'PT1'!B174 -> 104-004-013 | C12: =+'PT1'!C174 -> C1-707 CLAUDIA CAMUS | D12: =+'PT1'!D174 -> 13694 | E12: =IF(D12<0,"ANTICIPOS",IF(D12=$J$8,"SIN ADEUDO",IF(D12<=$K$7,"DEUDA CORRIENTE",IF(D12<=$K$6,"MOROSOS",IF(D12>$J$5,"COBRANZA JUDICIAL"))))) -> DEUDA CORRIENTE
B13: =+'PT1'!B268 -> 104-006-003 | C13: =+'PT1'!C268 -> C3-211 ISAAC ZAYATH | D13: =+'PT1'!D268 -> 112266 | E13: =IF(D13<0,"ANTICIPOS",IF(D13=$J$8,"SIN ADEUDO",IF(D13<=$K$7,"DEUDA CORRIENTE",IF(D13<=$K$6,"MOROSOS",IF(D13>$J$5,"COBRANZA JUDICIAL"))))) -> COBRANZA JUDICIAL
B14: =+'PT1'!B41 -> 104-001-036 | C14: =+'PT1'!C41 -> A-1802 ABDO ROFFE | D14: =+'PT1'!D41 -> 0 | E14: =IF(D14<0,"ANTICIPOS",IF(D14=$J$8,"SIN ADEUDO",IF(D14<=$K$7,"DEUDA CORRIENTE",IF(D14<=$K$6,"MOROSOS",IF(D14>$J$5,"COBRANZA JUDICIAL"))))) -> SIN ADEUDO
B15: =+'PT1'!B153 -> 104-003-044 | C15: =+'PT1'!C153 -> O2-2206 MOISES ZAGA | D15: =+'PT1'!D153 -> 27288 | E15: =IF(D15<0,"ANTICIPOS",IF(D15=$J$8,"SIN ADEUDO",IF(D15<=$K$7,"DEUDA CORRIENTE",IF(D15<=$K$6,"MOROSOS",IF(D15>$J$5,"COBRANZA JUDICIAL"))))) -> MOROSOS
B16: =+'PT1'!B53 -> 104-001-048 | C16: =+'PT1'!C53 -> A-2402 SANDRA BASSINI | D16: =+'PT1'!D53 -> 0 | E16: =IF(D16<0,"ANTICIPOS",IF(D16=$J$8,"SIN ADEUDO",IF(D16<=$K$7,"DEUDA CORRIENTE",IF(D16<=$K$6,"MOROSOS",IF(D16>$J$5,"COBRANZA JUDICIAL"))))) -> SIN ADEUDO
B17: =+'PT1'!B142 -> 104-003-033 | C17: =+'PT1'!C142 -> O2-1705 DAVID SAADIA | D17: =+'PT1'!D142 -> 0 | E17: =IF(D17<0,"ANTICIPOS",IF(D17=$J$8,"SIN ADEUDO",IF(D17<=$K$7,"DEUDA CORRIENTE",IF(D17<=$K$6,"MOROSOS",IF(D17>$J$5,"COBRANZA JUDICIAL"))))) -> SIN ADEUDO
B18: =+'PT1'!B160 -> 104-003-051 | C18: =+'PT1'!C160 -> O2-PH05 ABRAHAM CHEREM C | D18: =+'PT1'!D160 -> 300 | E18: =IF(D18<0,"ANTICIPOS",IF(D18=$J$8,"SIN ADEUDO",IF(D18<=$K$7,"DEUDA CORRIENTE",IF(D18<=$K$6,"MOROSOS",IF(D18>$J$5,"COBRANZA JUDICIAL"))))) -> DEUDA CORRIENTE
B19: =+'PT1'!B164 -> 104-004-003 | C19: =+'PT1'!C164 -> C1-207 ABRAHAM CHEREM C | D19: =+'PT1'!D164 -> 0 | E19: =IF(D19<0,"ANTICIPOS",IF(D19=$J$8,"SIN ADEUDO",IF(D19<=$K$7,"DEUDA CORRIENTE",IF(D19<=$K$6,"MOROSOS",IF(D19>$J$5,"COBRANZA JUDICIAL"))))) -> SIN ADEUDO
B20: =+'PT1'!B189 -> 104-004-028 | C20: =+'PT1'!C189 -> C1-1408 ABRAHAM CHEREM C | D20: =+'PT1'!D189 -> 0 | E20: =IF(D20<0,"ANTICIPOS",IF(D20=$J$8,"SIN ADEUDO",IF(D20<=$K$7,"DEUDA CORRIENTE",IF(D20<=$K$6,"MOROSOS",IF(D20>$J$5,"COBRANZA JUDICIAL"))))) -> SIN ADEUDO
B21: =+'PT1'!B194 -> 104-004-033 | C21: =+'PT1'!C194 -> C1-1707 ABRAHAM CHEREM C | D21: =+'PT1'!D194 -> 0 | E21: =IF(D21<0,"ANTICIPOS",IF(D21=$J$8,"SIN ADEUDO",IF(D21<=$K$7,"DEUDA CORRIENTE",IF(D21<=$K$6,"MOROSOS",IF(D21>$J$5,"COBRANZA JUDICIAL"))))) -> SIN ADEUDO
B22: =+'PT1'!B116 -> 104-003-007 | C22: =+'PT1'!C116 -> O2-405 MONICA COLOMER | D22: =+'PT1'!D116 -> 0 | E22: =IF(D22<0,"ANTICIPOS",IF(D22=$J$8,"SIN ADEUDO",IF(D22<=$K$7,"DEUDA CORRIENTE",IF(D22<=$K$6,"MOROSOS",IF(D22>$J$5,"COBRANZA JUDICIAL"))))) -> SIN ADEUDO
B23: =+'PT1'!B180 -> 104-004-019 | C23: =+'PT1'!C180 -> C1-1007 AGGI FLEGMAN L | D23: =+'PT1'!D180 -> 0 | E23: =IF(D23<0,"ANTICIPOS",IF(D23=$J$8,"SIN ADEUDO",IF(D23<=$K$7,"DEUDA CORRIENTE",IF(D23<=$K$6,"MOROSOS",IF(D23>$J$5,"COBRANZA JUDICIAL"))))) -> SIN ADEUDO
B24: =+'PT1'!B211 -> 104-004-050 | C24: =+'PT1'!C211 -> C1-2508 SALOMON AMBE | D24: =+'PT1'!D211 -> 13694 | E24: =IF(D24<0,"ANTICIPOS",IF(D24=$J$8,"SIN ADEUDO",IF(D24<=$K$7,"DEUDA CORRIENTE",IF(D24<=$K$6,"MOROSOS",IF(D24>$J$5,"COBRANZA JUDICIAL"))))) -> DEUDA CORRIENTE
B25: =+'PT1'!B297 -> 104-006-032 | C25: =+'PT1'!C297 -> C3-1612 RAQUEL SHABOT | D25: =+'PT1'!D297 -> -98504 | E25: =IF(D25<0,"ANTICIPOS",IF(D25=$J$8,"SIN ADEUDO",IF(D25<=$K$7,"DEUDA CORRIENTE",IF(D25<=$K$6,"MOROSOS",IF(D25>$J$5,"COBRANZA JUDICIAL"))))) -> ANTICIPOS
B26: =+'PT1'!B193 -> 104-004-032 | C26: =+'PT1'!C193 -> C1-1608 HUGO I. PEREZ | D26: =+'PT1'!D193 -> 0 | E26: =IF(D26<0,"ANTICIPOS",IF(D26=$J$8,"SIN ADEUDO",IF(D26<=$K$7,"DEUDA CORRIENTE",IF(D26<=$K$6,"MOROSOS",IF(D26>$J$5,"COBRANZA JUDICIAL"))))) -> SIN ADEUDO
B27: =+'PT1'!B218 -> 104-005-005 | C27: =+'PT1'!C218 -> C2-309 DAVID SAAD | D27: =+'PT1'!D218 -> 0 | E27: =IF(D27<0,"ANTICIPOS",IF(D27=$J$8,"SIN ADEUDO",IF(D27<=$K$7,"DEUDA CORRIENTE",IF(D27<=$K$6,"MOROSOS",IF(D27>$J$5,"COBRANZA JUDICIAL"))))) -> SIN ADEUDO
B28: =+'PT1'!B279 -> 104-006-014 | C28: =+'PT1'!C279 -> C3-712 ALICIA ORTEGA | D28: =+'PT1'!D279 -> 0 | E28: =IF(D28<0,"ANTICIPOS",IF(D28=$J$8,"SIN ADEUDO",IF(D28<=$K$7,"DEUDA CORRIENTE",IF(D28<=$K$6,"MOROSOS",IF(D28>$J$5,"COBRANZA JUDICIAL"))))) -> SIN ADEUDO
B29: =+'PT1'!B152 -> 104-003-043 | C29: =+'PT1'!C152 -> O2-2205 JORGE WATTY | D29: =+'PT1'!D152 -> 500 | E29: =IF(D29<0,"ANTICIPOS",IF(D29=$J$8,"SIN ADEUDO",IF(D29<=$K$7,"DEUDA CORRIENTE",IF(D29<=$K$6,"MOROSOS",IF(D29>$J$5,"COBRANZA JUDICIAL"))))) -> DEUDA CORRIENTE
B30: =+'PT1'!B32 -> 104-001-027 | C30: =+'PT1'!C32 -> A-1401 JESSICA SIDAUY | D30: =+'PT1'!D32 -> 0 | E30: =IF(D30<0,"ANTICIPOS",IF(D30=$J$8,"SIN ADEUDO",IF(D30<=$K$7,"DEUDA CORRIENTE",IF(D30<=$K$6,"MOROSOS",IF(D30>$J$5,"COBRANZA JUDICIAL"))))) -> SIN ADEUDO
B31: =+'PT1'!B50 -> 104-001-045 | C31: =+'PT1'!C50 -> A-2301 DANIEL BETECH | D31: =+'PT1'!D50 -> -2.910383e-11 | E31: =IF(D31<0,"ANTICIPOS",IF(D31=$J$8,"SIN ADEUDO",IF(D31<=$K$7,"DEUDA CORRIENTE",IF(D31<=$K$6,"MOROSOS",IF(D31>$J$5,"COBRANZA JUDICIAL"))))) -> ANTICIPOS
B32: =+'PT1'!B81 -> 104-002-024 | C32: =+'PT1'!C81 -> O1-1204 CARLOS KIBRIT | D32: =+'PT1'!D81 -> 0 | E32: =IF(D32<0,"ANTICIPOS",IF(D32=$J$8,"SIN ADEUDO",IF(D32<=$K$7,"DEUDA CORRIENTE",IF(D32<=$K$6,"MOROSOS",IF(D32>$J$5,"COBRANZA JUDICIAL"))))) -> SIN ADEUDO
B33: =+'PT1'!B108 -> 104-002-051 | C33: =+'PT1'!C108 -> O1-PH03 SERGIO FASCOVICH | D33: =+'PT1'!D108 -> 0 | E33: =IF(D33<0,"ANTICIPOS",IF(D33=$J$8,"SIN ADEUDO",IF(D33<=$K$7,"DEUDA CORRIENTE",IF(D33<=$K$6,"MOROSOS",IF(D33>$J$5,"COBRANZA JUDICIAL"))))) -> SIN ADEUDO
B34: =+'PT1'!B191 -> 104-004-030 | C34: =+'PT1'!C191 -> C1-1508 ALBERTO NEHMAD | D34: =+'PT1'!D191 -> 13694 | E34: =IF(D34<0,"ANTICIPOS",IF(D34=$J$8,"SIN ADEUDO",IF(D34<=$K$7,"DEUDA CORRIENTE",IF(D34<=$K$6,"MOROSOS",IF(D34>$J$5,"COBRANZA JUDICIAL"))))) -> DEUDA CORRIENTE
B35: =+'PT1'!B275 -> 104-006-010 | C35: =+'PT1'!C275 -> C3-512 ALEJANDRO RABINOVITZ | D35: =+'PT1'!D275 -> 300 | E35: =IF(D35<0,"ANTICIPOS",IF(D35=$J$8,"SIN ADEUDO",IF(D35<=$K$7,"DEUDA CORRIENTE",IF(D35<=$K$6,"MOROSOS",IF(D35>$J$5,"COBRANZA JUDICIAL"))))) -> DEUDA CORRIENTE
B36: =+'PT1'!B277 -> 104-006-012 | C36: =+'PT1'!C277 -> C3-612 LORENA CARREÑO | D36: =+'PT1'!D277 -> 0 | E36: =IF(D36<0,"ANTICIPOS",IF(D36=$J$8,"SIN ADEUDO",IF(D36<=$K$7,"DEUDA CORRIENTE",IF(D36<=$K$6,"MOROSOS",IF(D36>$J$5,"COBRANZA JUDICIAL"))))) -> SIN ADEUDO
B37: =+'PT1'!B24 -> 104-001-019 | C37: =+'PT1'!C24 -> A-1001 MONICA SABA | D37: =+'PT1'!D24 -> 0 | E37: =IF(D37<0,"ANTICIPOS",IF(D37=$J$8,"SIN ADEUDO",IF(D37<=$K$7,"DEUDA CORRIENTE",IF(D37<=$K$6,"MOROSOS",IF(D37>$J$5,"COBRANZA JUDICIAL"))))) -> SIN ADEUDO
B38: =+'PT1'!B14 -> 104-001-009 | C38: =+'PT1'!C14 -> A-501 ALEJANDRO GOLDEBERG | D38: =+'PT1'!D14 -> 25000 | E38: =IF(D38<0,"ANTICIPOS",IF(D38=$J$8,"SIN ADEUDO",IF(D38<=$K$7,"DEUDA CORRIENTE",IF(D38<=$K$6,"MOROSOS",IF(D38>$J$5,"COBRANZA JUDICIAL"))))) -> MOROSOS
B39: =+'PT1'!B25 -> 104-001-020 | C39: =+'PT1'!C25 -> A-1002 MIGUEL MIZRAHI | D39: =+'PT1'!D25 -> 0 | E39: =IF(D39<0,"ANTICIPOS",IF(D39=$J$8,"SIN ADEUDO",IF(D39<=$K$7,"DEUDA CORRIENTE",IF(D39<=$K$6,"MOROSOS",IF(D39>$J$5,"COBRANZA JUDICIAL"))))) -> SIN ADEUDO
B40: =+'PT1'!B94 -> 104-002-037 | C40: =+'PT1'!C94 -> O1-1903 ELIAS CHATTAJ | D40: =+'PT1'!D94 -> 0 | E40: =IF(D40<0,"ANTICIPOS",IF(D40=$J$8,"SIN ADEUDO",IF(D40<=$K$7,"DEUDA CORRIENTE",IF(D40<=$K$6,"MOROSOS",IF(D40>$J$5,"COBRANZA JUDICIAL"))))) -> SIN ADEUDO
B41: =+'PT1'!B256 -> 104-005-043 | C41: =+'PT1'!C256 -> C2-2209 SOFIA DABBAH | D41: =+'PT1'!D256 -> 1.4551915e-11 | E41: =IF(D41<0,"ANTICIPOS",IF(D41=$J$8,"SIN ADEUDO",IF(D41<=$K$7,"DEUDA CORRIENTE",IF(D41<=$K$6,"MOROSOS",IF(D41>$J$5,"COBRANZA JUDICIAL"))))) -> DEUDA CORRIENTE
B42: =+'PT1'!B219 -> 104-005-006 | C42: =+'PT1'!C219 -> C2-310 JOSE AMKIE | D42: =+'PT1'!D219 -> 0 | E42: =IF(D42<0,"ANTICIPOS",IF(D42=$J$8,"SIN ADEUDO",IF(D42<=$K$7,"DEUDA CORRIENTE",IF(D42<=$K$6,"MOROSOS",IF(D42>$J$5,"COBRANZA JUDICIAL"))))) -> SIN ADEUDO
...

Sheet PT3
B2: COBRANZA JUDICIAL
B4: CTA | C4: CONDOMINO | D4: =[1]!'@PERIODO[A]' -> Abril/2026 | E4: CLASIFICACIÓN | F4: STATUS LEGAL | N4: STATUS AREA LEGAL
B5: {=IFERROR(INDEX(BD[],_xlfn.AGGREGATE(15,6,IF(BD[CLASIFICACIÓN]=$B$2,ROW(BD[CLASIFICACIÓN])-ROW('PT2 (FILTRAR)'!$E$5)+1,NA()),ROWS($B$5:B5)),COLUMNS($B$5:B5)),"")} -> 104-006-003 | C5: {=IFERROR(INDEX(BD[],_xlfn.AGGREGATE(15,6,IF(BD[CLASIFICACIÓN]=$B$2,ROW(BD[CLASIFICACIÓN])-ROW('PT2 (FILTRAR)'!$E$5)+1,NA()),ROWS($B$5:C5)),COLUMNS($B$5:C5)),"")} -> C3-211 ISAAC ZAYATH | D5: {=IFERROR(INDEX(BD[],_xlfn.AGGREGATE(15,6,IF(BD[CLASIFICACIÓN]=$B$2,ROW(BD[CLASIFICACIÓN])-ROW('PT2 (FILTRAR)'!$E$5)+1,NA()),ROWS($B$5:D5)),COLUMNS($B$5:D5)),"")} -> 112266 | E5: {=IFERROR(INDEX(BD[],_xlfn.AGGREGATE(15,6,IF(BD[CLASIFICACIÓN]=$B$2,ROW(BD[CLASIFICACIÓN])-ROW('PT2 (FILTRAR)'!$E$5)+1,NA()),ROWS($B$5:E5)),COLUMNS($B$5:E5)),"")} -> COBRANZA JUDICIAL | F5: PENDIENTE APROBACIÓN COMITÉ | N5: AGREGAR STATUS
B6: {=IFERROR(INDEX(BD[],_xlfn.AGGREGATE(15,6,IF(BD[CLASIFICACIÓN]=$B$2,ROW(BD[CLASIFICACIÓN])-ROW('PT2 (FILTRAR)'!$E$5)+1,NA()),ROWS($B$5:B6)),COLUMNS($B$5:B6)),"")} -> 104-002-047 | C6: {=IFERROR(INDEX(BD[],_xlfn.AGGREGATE(15,6,IF(BD[CLASIFICACIÓN]=$B$2,ROW(BD[CLASIFICACIÓN])-ROW('PT2 (FILTRAR)'!$E$5)+1,NA()),ROWS($B$5:C6)),COLUMNS($B$5:C6)),"")} -> O1-2403 SCOTIABANK INVERLAT S.A. | D6: {=IFERROR(INDEX(BD[],_xlfn.AGGREGATE(15,6,IF(BD[CLASIFICACIÓN]=$B$2,ROW(BD[CLASIFICACIÓN])-ROW('PT2 (FILTRAR)'!$E$5)+1,NA()),ROWS($B$5:D6)),COLUMNS($B$5:D6)),"")} -> 180472 | E6: {=IFERROR(INDEX(BD[],_xlfn.AGGREGATE(15,6,IF(BD[CLASIFICACIÓN]=$B$2,ROW(BD[CLASIFICACIÓN])-ROW('PT2 (FILTRAR)'!$E$5)+1,NA()),ROWS($B$5:E6)),COLUMNS($B$5:E6)),"")} -> COBRANZA JUDICIAL | F6: AGREGAR STATUS | N6: PENDIENTE APROBACIÓN COMITÉ
B7: {=IFERROR(INDEX(BD[],_xlfn.AGGREGATE(15,6,IF(BD[CLASIFICACIÓN]=$B$2,ROW(BD[CLASIFICACIÓN])-ROW('PT2 (FILTRAR)'!$E$5)+1,NA()),ROWS($B$5:B7)),COLUMNS($B$5:B7)),"")} -> 104-003-019 | C7: {=IFERROR(INDEX(BD[],_xlfn.AGGREGATE(15,6,IF(BD[CLASIFICACIÓN]=$B$2,ROW(BD[CLASIFICACIÓN])-ROW('PT2 (FILTRAR)'!$E$5)+1,NA()),ROWS($B$5:C7)),COLUMNS($B$5:C7)),"")} -> O2-1005 JOSE SACAL | D7: {=IFERROR(INDEX(BD[],_xlfn.AGGREGATE(15,6,IF(BD[CLASIFICACIÓN]=$B$2,ROW(BD[CLASIFICACIÓN])-ROW('PT2 (FILTRAR)'!$E$5)+1,NA()),ROWS($B$5:D7)),COLUMNS($B$5:D7)),"")} -> 93328 | E7: {=IFERROR(INDEX(BD[],_xlfn.AGGREGATE(15,6,IF(BD[CLASIFICACIÓN]=$B$2,ROW(BD[CLASIFICACIÓN])-ROW('PT2 (FILTRAR)'!$E$5)+1,NA()),ROWS($B$5:E7)),COLUMNS($B$5:E7)),"")} -> COBRANZA JUDICIAL | F7: AGREGAR STATUS | N7: FASE 1
B8: {=IFERROR(INDEX(BD[],_xlfn.AGGREGATE(15,6,IF(BD[CLASIFICACIÓN]=$B$2,ROW(BD[CLASIFICACIÓN])-ROW('PT2 (FILTRAR)'!$E$5)+1,NA()),ROWS($B$5:B8)),COLUMNS($B$5:B8)),"")} | C8: {=IFERROR(INDEX(BD[],_xlfn.AGGREGATE(15,6,IF(BD[CLASIFICACIÓN]=$B$2,ROW(BD[CLASIFICACIÓN])-ROW('PT2 (FILTRAR)'!$E$5)+1,NA()),ROWS($B$5:C8)),COLUMNS($B$5:C8)),"")} | D8: {=IFERROR(INDEX(BD[],_xlfn.AGGREGATE(15,6,IF(BD[CLASIFICACIÓN]=$B$2,ROW(BD[CLASIFICACIÓN])-ROW('PT2 (FILTRAR)'!$E$5)+1,NA()),ROWS($B$5:D8)),COLUMNS($B$5:D8)),"")} | E8: {=IFERROR(INDEX(BD[],_xlfn.AGGREGATE(15,6,IF(BD[CLASIFICACIÓN]=$B$2,ROW(BD[CLASIFICACIÓN])-ROW('PT2 (FILTRAR)'!$E$5)+1,NA()),ROWS($B$5:E8)),COLUMNS($B$5:E8)),"")} | F8: AGREGAR STATUS | N8: FASE 2
B9: {=IFERROR(INDEX(BD[],_xlfn.AGGREGATE(15,6,IF(BD[CLASIFICACIÓN]=$B$2,ROW(BD[CLASIFICACIÓN])-ROW('PT2 (FILTRAR)'!$E$5)+1,NA()),ROWS($B$5:B9)),COLUMNS($B$5:B9)),"")} | C9: {=IFERROR(INDEX(BD[],_xlfn.AGGREGATE(15,6,IF(BD[CLASIFICACIÓN]=$B$2,ROW(BD[CLASIFICACIÓN])-ROW('PT2 (FILTRAR)'!$E$5)+1,NA()),ROWS($B$5:C9)),COLUMNS($B$5:C9)),"")} | D9: {=IFERROR(INDEX(BD[],_xlfn.AGGREGATE(15,6,IF(BD[CLASIFICACIÓN]=$B$2,ROW(BD[CLASIFICACIÓN])-ROW('PT2 (FILTRAR)'!$E$5)+1,NA()),ROWS($B$5:D9)),COLUMNS($B$5:D9)),"")} | E9: {=IFERROR(INDEX(BD[],_xlfn.AGGREGATE(15,6,IF(BD[CLASIFICACIÓN]=$B$2,ROW(BD[CLASIFICACIÓN])-ROW('PT2 (FILTRAR)'!$E$5)+1,NA()),ROWS($B$5:E9)),COLUMNS($B$5:E9)),"")} | F9: AGREGAR STATUS | N9: FASE 3
B10: {=IFERROR(INDEX(BD[],_xlfn.AGGREGATE(15,6,IF(BD[CLASIFICACIÓN]=$B$2,ROW(BD[CLASIFICACIÓN])-ROW('PT2 (FILTRAR)'!$E$5)+1,NA()),ROWS($B$5:B10)),COLUMNS($B$5:B10)),"")} | C10: {=IFERROR(INDEX(BD[],_xlfn.AGGREGATE(15,6,IF(BD[CLASIFICACIÓN]=$B$2,ROW(BD[CLASIFICACIÓN])-ROW('PT2 (FILTRAR)'!$E$5)+1,NA()),ROWS($B$5:C10)),COLUMNS($B$5:C10)),"")} | D10: {=IFERROR(INDEX(BD[],_xlfn.AGGREGATE(15,6,IF(BD[CLASIFICACIÓN]=$B$2,ROW(BD[CLASIFICACIÓN])-ROW('PT2 (FILTRAR)'!$E$5)+1,NA()),ROWS($B$5:D10)),COLUMNS($B$5:D10)),"")} | E10: {=IFERROR(INDEX(BD[],_xlfn.AGGREGATE(15,6,IF(BD[CLASIFICACIÓN]=$B$2,ROW(BD[CLASIFICACIÓN])-ROW('PT2 (FILTRAR)'!$E$5)+1,NA()),ROWS($B$5:E10)),COLUMNS($B$5:E10)),"")} | F10: AGREGAR STATUS | N10: FASE 4
B11: {=IFERROR(INDEX(BD[],_xlfn.AGGREGATE(15,6,IF(BD[CLASIFICACIÓN]=$B$2,ROW(BD[CLASIFICACIÓN])-ROW('PT2 (FILTRAR)'!$E$5)+1,NA()),ROWS($B$5:B11)),COLUMNS($B$5:B11)),"")} | C11: {=IFERROR(INDEX(BD[],_xlfn.AGGREGATE(15,6,IF(BD[CLASIFICACIÓN]=$B$2,ROW(BD[CLASIFICACIÓN])-ROW('PT2 (FILTRAR)'!$E$5)+1,NA()),ROWS($B$5:C11)),COLUMNS($B$5:C11)),"")} | D11: {=IFERROR(INDEX(BD[],_xlfn.AGGREGATE(15,6,IF(BD[CLASIFICACIÓN]=$B$2,ROW(BD[CLASIFICACIÓN])-ROW('PT2 (FILTRAR)'!$E$5)+1,NA()),ROWS($B$5:D11)),COLUMNS($B$5:D11)),"")} | E11: {=IFERROR(INDEX(BD[],_xlfn.AGGREGATE(15,6,IF(BD[CLASIFICACIÓN]=$B$2,ROW(BD[CLASIFICACIÓN])-ROW('PT2 (FILTRAR)'!$E$5)+1,NA()),ROWS($B$5:E11)),COLUMNS($B$5:E11)),"")} | F11: AGREGAR STATUS | N11: TRIBUNALES EN RECESO
B12: {=IFERROR(INDEX(BD[],_xlfn.AGGREGATE(15,6,IF(BD[CLASIFICACIÓN]=$B$2,ROW(BD[CLASIFICACIÓN])-ROW('PT2 (FILTRAR)'!$E$5)+1,NA()),ROWS($B$5:B12)),COLUMNS($B$5:B12)),"")} | C12: {=IFERROR(INDEX(BD[],_xlfn.AGGREGATE(15,6,IF(BD[CLASIFICACIÓN]=$B$2,ROW(BD[CLASIFICACIÓN])-ROW('PT2 (FILTRAR)'!$E$5)+1,NA()),ROWS($B$5:C12)),COLUMNS($B$5:C12)),"")} | D12: {=IFERROR(INDEX(BD[],_xlfn.AGGREGATE(15,6,IF(BD[CLASIFICACIÓN]=$B$2,ROW(BD[CLASIFICACIÓN])-ROW('PT2 (FILTRAR)'!$E$5)+1,NA()),ROWS($B$5:D12)),COLUMNS($B$5:D12)),"")} | E12: {=IFERROR(INDEX(BD[],_xlfn.AGGREGATE(15,6,IF(BD[CLASIFICACIÓN]=$B$2,ROW(BD[CLASIFICACIÓN])-ROW('PT2 (FILTRAR)'!$E$5)+1,NA()),ROWS($B$5:E12)),COLUMNS($B$5:E12)),"")} | F12: AGREGAR STATUS | N12: OTRO
B13: {=IFERROR(INDEX(BD[],_xlfn.AGGREGATE(15,6,IF(BD[CLASIFICACIÓN]=$B$2,ROW(BD[CLASIFICACIÓN])-ROW('PT2 (FILTRAR)'!$E$5)+1,NA()),ROWS($B$5:B13)),COLUMNS($B$5:B13)),"")} | C13: {=IFERROR(INDEX(BD[],_xlfn.AGGREGATE(15,6,IF(BD[CLASIFICACIÓN]=$B$2,ROW(BD[CLASIFICACIÓN])-ROW('PT2 (FILTRAR)'!$E$5)+1,NA()),ROWS($B$5:C13)),COLUMNS($B$5:C13)),"")} | D13: {=IFERROR(INDEX(BD[],_xlfn.AGGREGATE(15,6,IF(BD[CLASIFICACIÓN]=$B$2,ROW(BD[CLASIFICACIÓN])-ROW('PT2 (FILTRAR)'!$E$5)+1,NA()),ROWS($B$5:D13)),COLUMNS($B$5:D13)),"")} | E13: {=IFERROR(INDEX(BD[],_xlfn.AGGREGATE(15,6,IF(BD[CLASIFICACIÓN]=$B$2,ROW(BD[CLASIFICACIÓN])-ROW('PT2 (FILTRAR)'!$E$5)+1,NA()),ROWS($B$5:E13)),COLUMNS($B$5:E13)),"")} | F13: AGREGAR STATUS
B14: {=IFERROR(INDEX(BD[],_xlfn.AGGREGATE(15,6,IF(BD[CLASIFICACIÓN]=$B$2,ROW(BD[CLASIFICACIÓN])-ROW('PT2 (FILTRAR)'!$E$5)+1,NA()),ROWS($B$5:B14)),COLUMNS($B$5:B14)),"")} | C14: {=IFERROR(INDEX(BD[],_xlfn.AGGREGATE(15,6,IF(BD[CLASIFICACIÓN]=$B$2,ROW(BD[CLASIFICACIÓN])-ROW('PT2 (FILTRAR)'!$E$5)+1,NA()),ROWS($B$5:C14)),COLUMNS($B$5:C14)),"")} | D14: {=IFERROR(INDEX(BD[],_xlfn.AGGREGATE(15,6,IF(BD[CLASIFICACIÓN]=$B$2,ROW(BD[CLASIFICACIÓN])-ROW('PT2 (FILTRAR)'!$E$5)+1,NA()),ROWS($B$5:D14)),COLUMNS($B$5:D14)),"")} | E14: {=IFERROR(INDEX(BD[],_xlfn.AGGREGATE(15,6,IF(BD[CLASIFICACIÓN]=$B$2,ROW(BD[CLASIFICACIÓN])-ROW('PT2 (FILTRAR)'!$E$5)+1,NA()),ROWS($B$5:E14)),COLUMNS($B$5:E14)),"")} | F14: AGREGAR STATUS
B15: {=IFERROR(INDEX(BD[],_xlfn.AGGREGATE(15,6,IF(BD[CLASIFICACIÓN]=$B$2,ROW(BD[CLASIFICACIÓN])-ROW('PT2 (FILTRAR)'!$E$5)+1,NA()),ROWS($B$5:B15)),COLUMNS($B$5:B15)),"")} | C15: {=IFERROR(INDEX(BD[],_xlfn.AGGREGATE(15,6,IF(BD[CLASIFICACIÓN]=$B$2,ROW(BD[CLASIFICACIÓN])-ROW('PT2 (FILTRAR)'!$E$5)+1,NA()),ROWS($B$5:C15)),COLUMNS($B$5:C15)),"")} | D15: {=IFERROR(INDEX(BD[],_xlfn.AGGREGATE(15,6,IF(BD[CLASIFICACIÓN]=$B$2,ROW(BD[CLASIFICACIÓN])-ROW('PT2 (FILTRAR)'!$E$5)+1,NA()),ROWS($B$5:D15)),COLUMNS($B$5:D15)),"")} | E15: {=IFERROR(INDEX(BD[],_xlfn.AGGREGATE(15,6,IF(BD[CLASIFICACIÓN]=$B$2,ROW(BD[CLASIFICACIÓN])-ROW('PT2 (FILTRAR)'!$E$5)+1,NA()),ROWS($B$5:E15)),COLUMNS($B$5:E15)),"")} | F15: AGREGAR STATUS
B16: {=IFERROR(INDEX(BD[],_xlfn.AGGREGATE(15,6,IF(BD[CLASIFICACIÓN]=$B$2,ROW(BD[CLASIFICACIÓN])-ROW('PT2 (FILTRAR)'!$E$5)+1,NA()),ROWS($B$5:B16)),COLUMNS($B$5:B16)),"")} | C16: {=IFERROR(INDEX(BD[],_xlfn.AGGREGATE(15,6,IF(BD[CLASIFICACIÓN]=$B$2,ROW(BD[CLASIFICACIÓN])-ROW('PT2 (FILTRAR)'!$E$5)+1,NA()),ROWS($B$5:C16)),COLUMNS($B$5:C16)),"")} | D16: {=IFERROR(INDEX(BD[],_xlfn.AGGREGATE(15,6,IF(BD[CLASIFICACIÓN]=$B$2,ROW(BD[CLASIFICACIÓN])-ROW('PT2 (FILTRAR)'!$E$5)+1,NA()),ROWS($B$5:D16)),COLUMNS($B$5:D16)),"")} | E16: {=IFERROR(INDEX(BD[],_xlfn.AGGREGATE(15,6,IF(BD[CLASIFICACIÓN]=$B$2,ROW(BD[CLASIFICACIÓN])-ROW('PT2 (FILTRAR)'!$E$5)+1,NA()),ROWS($B$5:E16)),COLUMNS($B$5:E16)),"")} | F16: AGREGAR STATUS
B17: {=IFERROR(INDEX(BD[],_xlfn.AGGREGATE(15,6,IF(BD[CLASIFICACIÓN]=$B$2,ROW(BD[CLASIFICACIÓN])-ROW('PT2 (FILTRAR)'!$E$5)+1,NA()),ROWS($B$5:B17)),COLUMNS($B$5:B17)),"")} | C17: {=IFERROR(INDEX(BD[],_xlfn.AGGREGATE(15,6,IF(BD[CLASIFICACIÓN]=$B$2,ROW(BD[CLASIFICACIÓN])-ROW('PT2 (FILTRAR)'!$E$5)+1,NA()),ROWS($B$5:C17)),COLUMNS($B$5:C17)),"")} | D17: {=IFERROR(INDEX(BD[],_xlfn.AGGREGATE(15,6,IF(BD[CLASIFICACIÓN]=$B$2,ROW(BD[CLASIFICACIÓN])-ROW('PT2 (FILTRAR)'!$E$5)+1,NA()),ROWS($B$5:D17)),COLUMNS($B$5:D17)),"")} | E17: {=IFERROR(INDEX(BD[],_xlfn.AGGREGATE(15,6,IF(BD[CLASIFICACIÓN]=$B$2,ROW(BD[CLASIFICACIÓN])-ROW('PT2 (FILTRAR)'!$E$5)+1,NA()),ROWS($B$5:E17)),COLUMNS($B$5:E17)),"")} | F17: AGREGAR STATUS
B18: {=IFERROR(INDEX(BD[],_xlfn.AGGREGATE(15,6,IF(BD[CLASIFICACIÓN]=$B$2,ROW(BD[CLASIFICACIÓN])-ROW('PT2 (FILTRAR)'!$E$5)+1,NA()),ROWS($B$5:B18)),COLUMNS($B$5:B18)),"")} | C18: {=IFERROR(INDEX(BD[],_xlfn.AGGREGATE(15,6,IF(BD[CLASIFICACIÓN]=$B$2,ROW(BD[CLASIFICACIÓN])-ROW('PT2 (FILTRAR)'!$E$5)+1,NA()),ROWS($B$5:C18)),COLUMNS($B$5:C18)),"")} | D18: {=IFERROR(INDEX(BD[],_xlfn.AGGREGATE(15,6,IF(BD[CLASIFICACIÓN]=$B$2,ROW(BD[CLASIFICACIÓN])-ROW('PT2 (FILTRAR)'!$E$5)+1,NA()),ROWS($B$5:D18)),COLUMNS($B$5:D18)),"")} | E18: {=IFERROR(INDEX(BD[],_xlfn.AGGREGATE(15,6,IF(BD[CLASIFICACIÓN]=$B$2,ROW(BD[CLASIFICACIÓN])-ROW('PT2 (FILTRAR)'!$E$5)+1,NA()),ROWS($B$5:E18)),COLUMNS($B$5:E18)),"")} | F18: AGREGAR STATUS
B19: {=IFERROR(INDEX(BD[],_xlfn.AGGREGATE(15,6,IF(BD[CLASIFICACIÓN]=$B$2,ROW(BD[CLASIFICACIÓN])-ROW('PT2 (FILTRAR)'!$E$5)+1,NA()),ROWS($B$5:B19)),COLUMNS($B$5:B19)),"")} | C19: {=IFERROR(INDEX(BD[],_xlfn.AGGREGATE(15,6,IF(BD[CLASIFICACIÓN]=$B$2,ROW(BD[CLASIFICACIÓN])-ROW('PT2 (FILTRAR)'!$E$5)+1,NA()),ROWS($B$5:C19)),COLUMNS($B$5:C19)),"")} | D19: {=IFERROR(INDEX(BD[],_xlfn.AGGREGATE(15,6,IF(BD[CLASIFICACIÓN]=$B$2,ROW(BD[CLASIFICACIÓN])-ROW('PT2 (FILTRAR)'!$E$5)+1,NA()),ROWS($B$5:D19)),COLUMNS($B$5:D19)),"")} | E19: {=IFERROR(INDEX(BD[],_xlfn.AGGREGATE(15,6,IF(BD[CLASIFICACIÓN]=$B$2,ROW(BD[CLASIFICACIÓN])-ROW('PT2 (FILTRAR)'!$E$5)+1,NA()),ROWS($B$5:E19)),COLUMNS($B$5:E19)),"")} | F19: AGREGAR STATUS
B20: {=IFERROR(INDEX(BD[],_xlfn.AGGREGATE(15,6,IF(BD[CLASIFICACIÓN]=$B$2,ROW(BD[CLASIFICACIÓN])-ROW('PT2 (FILTRAR)'!$E$5)+1,NA()),ROWS($B$5:B20)),COLUMNS($B$5:B20)),"")} | C20: {=IFERROR(INDEX(BD[],_xlfn.AGGREGATE(15,6,IF(BD[CLASIFICACIÓN]=$B$2,ROW(BD[CLASIFICACIÓN])-ROW('PT2 (FILTRAR)'!$E$5)+1,NA()),ROWS($B$5:C20)),COLUMNS($B$5:C20)),"")} | D20: {=IFERROR(INDEX(BD[],_xlfn.AGGREGATE(15,6,IF(BD[CLASIFICACIÓN]=$B$2,ROW(BD[CLASIFICACIÓN])-ROW('PT2 (FILTRAR)'!$E$5)+1,NA()),ROWS($B$5:D20)),COLUMNS($B$5:D20)),"")} | E20: {=IFERROR(INDEX(BD[],_xlfn.AGGREGATE(15,6,IF(BD[CLASIFICACIÓN]=$B$2,ROW(BD[CLASIFICACIÓN])-ROW('PT2 (FILTRAR)'!$E$5)+1,NA()),ROWS($B$5:E20)),COLUMNS($B$5:E20)),"")}
B21: {=IFERROR(INDEX(BD[],_xlfn.AGGREGATE(15,6,IF(BD[CLASIFICACIÓN]=$B$2,ROW(BD[CLASIFICACIÓN])-ROW('PT2 (FILTRAR)'!$E$5)+1,NA()),ROWS($B$5:B21)),COLUMNS($B$5:B21)),"")} | C21: {=IFERROR(INDEX(BD[],_xlfn.AGGREGATE(15,6,IF(BD[CLASIFICACIÓN]=$B$2,ROW(BD[CLASIFICACIÓN])-ROW('PT2 (FILTRAR)'!$E$5)+1,NA()),ROWS($B$5:C21)),COLUMNS($B$5:C21)),"")} | D21: {=IFERROR(INDEX(BD[],_xlfn.AGGREGATE(15,6,IF(BD[CLASIFICACIÓN]=$B$2,ROW(BD[CLASIFICACIÓN])-ROW('PT2 (FILTRAR)'!$E$5)+1,NA()),ROWS($B$5:D21)),COLUMNS($B$5:D21)),"")} | E21: {=IFERROR(INDEX(BD[],_xlfn.AGGREGATE(15,6,IF(BD[CLASIFICACIÓN]=$B$2,ROW(BD[CLASIFICACIÓN])-ROW('PT2 (FILTRAR)'!$E$5)+1,NA()),ROWS($B$5:E21)),COLUMNS($B$5:E21)),"")}
B22: {=IFERROR(INDEX(BD[],_xlfn.AGGREGATE(15,6,IF(BD[CLASIFICACIÓN]=$B$2,ROW(BD[CLASIFICACIÓN])-ROW('PT2 (FILTRAR)'!$E$5)+1,NA()),ROWS($B$5:B22)),COLUMNS($B$5:B22)),"")} | C22: {=IFERROR(INDEX(BD[],_xlfn.AGGREGATE(15,6,IF(BD[CLASIFICACIÓN]=$B$2,ROW(BD[CLASIFICACIÓN])-ROW('PT2 (FILTRAR)'!$E$5)+1,NA()),ROWS($B$5:C22)),COLUMNS($B$5:C22)),"")} | D22: {=IFERROR(INDEX(BD[],_xlfn.AGGREGATE(15,6,IF(BD[CLASIFICACIÓN]=$B$2,ROW(BD[CLASIFICACIÓN])-ROW('PT2 (FILTRAR)'!$E$5)+1,NA()),ROWS($B$5:D22)),COLUMNS($B$5:D22)),"")} | E22: {=IFERROR(INDEX(BD[],_xlfn.AGGREGATE(15,6,IF(BD[CLASIFICACIÓN]=$B$2,ROW(BD[CLASIFICACIÓN])-ROW('PT2 (FILTRAR)'!$E$5)+1,NA()),ROWS($B$5:E22)),COLUMNS($B$5:E22)),"")}
B23: {=IFERROR(INDEX(BD[],_xlfn.AGGREGATE(15,6,IF(BD[CLASIFICACIÓN]=$B$2,ROW(BD[CLASIFICACIÓN])-ROW('PT2 (FILTRAR)'!$E$5)+1,NA()),ROWS($B$5:B23)),COLUMNS($B$5:B23)),"")} | C23: {=IFERROR(INDEX(BD[],_xlfn.AGGREGATE(15,6,IF(BD[CLASIFICACIÓN]=$B$2,ROW(BD[CLASIFICACIÓN])-ROW('PT2 (FILTRAR)'!$E$5)+1,NA()),ROWS($B$5:C23)),COLUMNS($B$5:C23)),"")} | D23: {=IFERROR(INDEX(BD[],_xlfn.AGGREGATE(15,6,IF(BD[CLASIFICACIÓN]=$B$2,ROW(BD[CLASIFICACIÓN])-ROW('PT2 (FILTRAR)'!$E$5)+1,NA()),ROWS($B$5:D23)),COLUMNS($B$5:D23)),"")} | E23: {=IFERROR(INDEX(BD[],_xlfn.AGGREGATE(15,6,IF(BD[CLASIFICACIÓN]=$B$2,ROW(BD[CLASIFICACIÓN])-ROW('PT2 (FILTRAR)'!$E$5)+1,NA()),ROWS($B$5:E23)),COLUMNS($B$5:E23)),"")}
B24: {=IFERROR(INDEX(BD[],_xlfn.AGGREGATE(15,6,IF(BD[CLASIFICACIÓN]=$B$2,ROW(BD[CLASIFICACIÓN])-ROW('PT2 (FILTRAR)'!$E$5)+1,NA()),ROWS($B$5:B24)),COLUMNS($B$5:B24)),"")} | C24: {=IFERROR(INDEX(BD[],_xlfn.AGGREGATE(15,6,IF(BD[CLASIFICACIÓN]=$B$2,ROW(BD[CLASIFICACIÓN])-ROW('PT2 (FILTRAR)'!$E$5)+1,NA()),ROWS($B$5:C24)),COLUMNS($B$5:C24)),"")} | D24: {=IFERROR(INDEX(BD[],_xlfn.AGGREGATE(15,6,IF(BD[CLASIFICACIÓN]=$B$2,ROW(BD[CLASIFICACIÓN])-ROW('PT2 (FILTRAR)'!$E$5)+1,NA()),ROWS($B$5:D24)),COLUMNS($B$5:D24)),"")} | E24: {=IFERROR(INDEX(BD[],_xlfn.AGGREGATE(15,6,IF(BD[CLASIFICACIÓN]=$B$2,ROW(BD[CLASIFICACIÓN])-ROW('PT2 (FILTRAR)'!$E$5)+1,NA()),ROWS($B$5:E24)),COLUMNS($B$5:E24)),"")}
B25: {=IFERROR(INDEX(BD[],_xlfn.AGGREGATE(15,6,IF(BD[CLASIFICACIÓN]=$B$2,ROW(BD[CLASIFICACIÓN])-ROW('PT2 (FILTRAR)'!$E$5)+1,NA()),ROWS($B$5:B25)),COLUMNS($B$5:B25)),"")} | C25: {=IFERROR(INDEX(BD[],_xlfn.AGGREGATE(15,6,IF(BD[CLASIFICACIÓN]=$B$2,ROW(BD[CLASIFICACIÓN])-ROW('PT2 (FILTRAR)'!$E$5)+1,NA()),ROWS($B$5:C25)),COLUMNS($B$5:C25)),"")} | D25: {=IFERROR(INDEX(BD[],_xlfn.AGGREGATE(15,6,IF(BD[CLASIFICACIÓN]=$B$2,ROW(BD[CLASIFICACIÓN])-ROW('PT2 (FILTRAR)'!$E$5)+1,NA()),ROWS($B$5:D25)),COLUMNS($B$5:D25)),"")} | E25: {=IFERROR(INDEX(BD[],_xlfn.AGGREGATE(15,6,IF(BD[CLASIFICACIÓN]=$B$2,ROW(BD[CLASIFICACIÓN])-ROW('PT2 (FILTRAR)'!$E$5)+1,NA()),ROWS($B$5:E25)),COLUMNS($B$5:E25)),"")}
B26: {=IFERROR(INDEX(BD[],_xlfn.AGGREGATE(15,6,IF(BD[CLASIFICACIÓN]=$B$2,ROW(BD[CLASIFICACIÓN])-ROW('PT2 (FILTRAR)'!$E$5)+1,NA()),ROWS($B$5:B26)),COLUMNS($B$5:B26)),"")} | C26: {=IFERROR(INDEX(BD[],_xlfn.AGGREGATE(15,6,IF(BD[CLASIFICACIÓN]=$B$2,ROW(BD[CLASIFICACIÓN])-ROW('PT2 (FILTRAR)'!$E$5)+1,NA()),ROWS($B$5:C26)),COLUMNS($B$5:C26)),"")} | D26: {=IFERROR(INDEX(BD[],_xlfn.AGGREGATE(15,6,IF(BD[CLASIFICACIÓN]=$B$2,ROW(BD[CLASIFICACIÓN])-ROW('PT2 (FILTRAR)'!$E$5)+1,NA()),ROWS($B$5:D26)),COLUMNS($B$5:D26)),"")} | E26: {=IFERROR(INDEX(BD[],_xlfn.AGGREGATE(15,6,IF(BD[CLASIFICACIÓN]=$B$2,ROW(BD[CLASIFICACIÓN])-ROW('PT2 (FILTRAR)'!$E$5)+1,NA()),ROWS($B$5:E26)),COLUMNS($B$5:E26)),"")}
B27: {=IFERROR(INDEX(BD[],_xlfn.AGGREGATE(15,6,IF(BD[CLASIFICACIÓN]=$B$2,ROW(BD[CLASIFICACIÓN])-ROW('PT2 (FILTRAR)'!$E$5)+1,NA()),ROWS($B$5:B27)),COLUMNS($B$5:B27)),"")} | C27: {=IFERROR(INDEX(BD[],_xlfn.AGGREGATE(15,6,IF(BD[CLASIFICACIÓN]=$B$2,ROW(BD[CLASIFICACIÓN])-ROW('PT2 (FILTRAR)'!$E$5)+1,NA()),ROWS($B$5:C27)),COLUMNS($B$5:C27)),"")} | D27: {=IFERROR(INDEX(BD[],_xlfn.AGGREGATE(15,6,IF(BD[CLASIFICACIÓN]=$B$2,ROW(BD[CLASIFICACIÓN])-ROW('PT2 (FILTRAR)'!$E$5)+1,NA()),ROWS($B$5:D27)),COLUMNS($B$5:D27)),"")} | E27: {=IFERROR(INDEX(BD[],_xlfn.AGGREGATE(15,6,IF(BD[CLASIFICACIÓN]=$B$2,ROW(BD[CLASIFICACIÓN])-ROW('PT2 (FILTRAR)'!$E$5)+1,NA()),ROWS($B$5:E27)),COLUMNS($B$5:E27)),"")}
B28: {=IFERROR(INDEX(BD[],_xlfn.AGGREGATE(15,6,IF(BD[CLASIFICACIÓN]=$B$2,ROW(BD[CLASIFICACIÓN])-ROW('PT2 (FILTRAR)'!$E$5)+1,NA()),ROWS($B$5:B28)),COLUMNS($B$5:B28)),"")} | C28: {=IFERROR(INDEX(BD[],_xlfn.AGGREGATE(15,6,IF(BD[CLASIFICACIÓN]=$B$2,ROW(BD[CLASIFICACIÓN])-ROW('PT2 (FILTRAR)'!$E$5)+1,NA()),ROWS($B$5:C28)),COLUMNS($B$5:C28)),"")} | D28: {=IFERROR(INDEX(BD[],_xlfn.AGGREGATE(15,6,IF(BD[CLASIFICACIÓN]=$B$2,ROW(BD[CLASIFICACIÓN])-ROW('PT2 (FILTRAR)'!$E$5)+1,NA()),ROWS($B$5:D28)),COLUMNS($B$5:D28)),"")} | E28: {=IFERROR(INDEX(BD[],_xlfn.AGGREGATE(15,6,IF(BD[CLASIFICACIÓN]=$B$2,ROW(BD[CLASIFICACIÓN])-ROW('PT2 (FILTRAR)'!$E$5)+1,NA()),ROWS($B$5:E28)),COLUMNS($B$5:E28)),"")}
B29: {=IFERROR(INDEX(BD[],_xlfn.AGGREGATE(15,6,IF(BD[CLASIFICACIÓN]=$B$2,ROW(BD[CLASIFICACIÓN])-ROW('PT2 (FILTRAR)'!$E$5)+1,NA()),ROWS($B$5:B29)),COLUMNS($B$5:B29)),"")} | C29: {=IFERROR(INDEX(BD[],_xlfn.AGGREGATE(15,6,IF(BD[CLASIFICACIÓN]=$B$2,ROW(BD[CLASIFICACIÓN])-ROW('PT2 (FILTRAR)'!$E$5)+1,NA()),ROWS($B$5:C29)),COLUMNS($B$5:C29)),"")} | D29: {=IFERROR(INDEX(BD[],_xlfn.AGGREGATE(15,6,IF(BD[CLASIFICACIÓN]=$B$2,ROW(BD[CLASIFICACIÓN])-ROW('PT2 (FILTRAR)'!$E$5)+1,NA()),ROWS($B$5:D29)),COLUMNS($B$5:D29)),"")} | E29: {=IFERROR(INDEX(BD[],_xlfn.AGGREGATE(15,6,IF(BD[CLASIFICACIÓN]=$B$2,ROW(BD[CLASIFICACIÓN])-ROW('PT2 (FILTRAR)'!$E$5)+1,NA()),ROWS($B$5:E29)),COLUMNS($B$5:E29)),"")}
B30: {=IFERROR(INDEX(BD[],_xlfn.AGGREGATE(15,6,IF(BD[CLASIFICACIÓN]=$B$2,ROW(BD[CLASIFICACIÓN])-ROW('PT2 (FILTRAR)'!$E$5)+1,NA()),ROWS($B$5:B30)),COLUMNS($B$5:B30)),"")} | C30: {=IFERROR(INDEX(BD[],_xlfn.AGGREGATE(15,6,IF(BD[CLASIFICACIÓN]=$B$2,ROW(BD[CLASIFICACIÓN])-ROW('PT2 (FILTRAR)'!$E$5)+1,NA()),ROWS($B$5:C30)),COLUMNS($B$5:C30)),"")} | D30: {=IFERROR(INDEX(BD[],_xlfn.AGGREGATE(15,6,IF(BD[CLASIFICACIÓN]=$B$2,ROW(BD[CLASIFICACIÓN])-ROW('PT2 (FILTRAR)'!$E$5)+1,NA()),ROWS($B$5:D30)),COLUMNS($B$5:D30)),"")} | E30: {=IFERROR(INDEX(BD[],_xlfn.AGGREGATE(15,6,IF(BD[CLASIFICACIÓN]=$B$2,ROW(BD[CLASIFICACIÓN])-ROW('PT2 (FILTRAR)'!$E$5)+1,NA()),ROWS($B$5:E30)),COLUMNS($B$5:E30)),"")}
B31: {=IFERROR(INDEX(BD[],_xlfn.AGGREGATE(15,6,IF(BD[CLASIFICACIÓN]=$B$2,ROW(BD[CLASIFICACIÓN])-ROW('PT2 (FILTRAR)'!$E$5)+1,NA()),ROWS($B$5:B31)),COLUMNS($B$5:B31)),"")} | C31: {=IFERROR(INDEX(BD[],_xlfn.AGGREGATE(15,6,IF(BD[CLASIFICACIÓN]=$B$2,ROW(BD[CLASIFICACIÓN])-ROW('PT2 (FILTRAR)'!$E$5)+1,NA()),ROWS($B$5:C31)),COLUMNS($B$5:C31)),"")} | D31: {=IFERROR(INDEX(BD[],_xlfn.AGGREGATE(15,6,IF(BD[CLASIFICACIÓN]=$B$2,ROW(BD[CLASIFICACIÓN])-ROW('PT2 (FILTRAR)'!$E$5)+1,NA()),ROWS($B$5:D31)),COLUMNS($B$5:D31)),"")} | E31: {=IFERROR(INDEX(BD[],_xlfn.AGGREGATE(15,6,IF(BD[CLASIFICACIÓN]=$B$2,ROW(BD[CLASIFICACIÓN])-ROW('PT2 (FILTRAR)'!$E$5)+1,NA()),ROWS($B$5:E31)),COLUMNS($B$5:E31)),"")}
... B271: {=IFERROR(INDEX(BD[],_xlfn.AGGREGATE(15,6,IF(BD[CLASIFICACIÓN]=$B$2,ROW(BD[CLASIFICACIÓN])-ROW('PT2 (FILTRAR)'!$E$5)+1,NA()),ROWS($B$5:B271)),COLUMNS($B$5:B271)),"")} | C271: {=IFERROR(INDEX(BD[],_xlfn.AGGREGATE(15,6,IF(BD[CLASIFICACIÓN]=$B$2,ROW(BD[CLASIFICACIÓN])-ROW('PT2 (FILTRAR)'!$E$5)+1,NA()),ROWS($B$5:C271)),COLUMNS($B$5:C271)),"")} | D271: {=IFERROR(INDEX(BD[],_xlfn.AGGREGATE(15,6,IF(BD[CLASIFICACIÓN]=$B$2,ROW(BD[CLASIFICACIÓN])-ROW('PT2 (FILTRAR)'!$E$5)+1,NA()),ROWS($B$5:D271)),COLUMNS($B$5:D271)),"")} | E271: {=IFERROR(INDEX(BD[],_xlfn.AGGREGATE(15,6,IF(BD[CLASIFICACIÓN]=$B$2,ROW(BD[CLASIFICACIÓN])-ROW('PT2 (FILTRAR)'!$E$5)+1,NA()),ROWS($B$5:E271)),COLUMNS($B$5:E271)),"")}
B272: TOTAL | C272: =+B2 -> COBRANZA JUDICIAL | D272: =SUM(D5:D271) -> 386066

Sheet PT4
B2: MOROSOS
B4: CTA | C4: CONDOMINO | D4: =[1]!'@PERIODO[A]' -> Abril/2026 | E4: CLASIFICACIÓN
B5: {=IFERROR(INDEX(BD[],_xlfn.AGGREGATE(15,6,IF(BD[CLASIFICACIÓN]=$B$2,ROW(BD[CLASIFICACIÓN])-ROW('PT2 (FILTRAR)'!$E$5)+1,NA()),ROWS($B$5:B5)),COLUMNS($B$5:B5)),"")} -> 104-003-023 | C5: {=IFERROR(INDEX(BD[],_xlfn.AGGREGATE(15,6,IF(BD[CLASIFICACIÓN]=$B$2,ROW(BD[CLASIFICACIÓN])-ROW('PT2 (FILTRAR)'!$E$5)+1,NA()),ROWS($B$5:C5)),COLUMNS($B$5:C5)),"")} -> O2-1205 ABRAHAM ROFFE | D5: {=IFERROR(INDEX(BD[],_xlfn.AGGREGATE(15,6,IF(BD[CLASIFICACIÓN]=$B$2,ROW(BD[CLASIFICACIÓN])-ROW('PT2 (FILTRAR)'!$E$5)+1,NA()),ROWS($B$5:D5)),COLUMNS($B$5:D5)),"")} -> 39841 | E5: {=IFERROR(INDEX(BD[],_xlfn.AGGREGATE(15,6,IF(BD[CLASIFICACIÓN]=$B$2,ROW(BD[CLASIFICACIÓN])-ROW('PT2 (FILTRAR)'!$E$5)+1,NA()),ROWS($B$5:E5)),COLUMNS($B$5:E5)),"")} -> MOROSOS
B6: {=IFERROR(INDEX(BD[],_xlfn.AGGREGATE(15,6,IF(BD[CLASIFICACIÓN]=$B$2,ROW(BD[CLASIFICACIÓN])-ROW('PT2 (FILTRAR)'!$E$5)+1,NA()),ROWS($B$5:B6)),COLUMNS($B$5:B6)),"")} -> 104-003-044 | C6: {=IFERROR(INDEX(BD[],_xlfn.AGGREGATE(15,6,IF(BD[CLASIFICACIÓN]=$B$2,ROW(BD[CLASIFICACIÓN])-ROW('PT2 (FILTRAR)'!$E$5)+1,NA()),ROWS($B$5:C6)),COLUMNS($B$5:C6)),"")} -> O2-2206 MOISES ZAGA | D6: {=IFERROR(INDEX(BD[],_xlfn.AGGREGATE(15,6,IF(BD[CLASIFICACIÓN]=$B$2,ROW(BD[CLASIFICACIÓN])-ROW('PT2 (FILTRAR)'!$E$5)+1,NA()),ROWS($B$5:D6)),COLUMNS($B$5:D6)),"")} -> 27288 | E6: {=IFERROR(INDEX(BD[],_xlfn.AGGREGATE(15,6,IF(BD[CLASIFICACIÓN]=$B$2,ROW(BD[CLASIFICACIÓN])-ROW('PT2 (FILTRAR)'!$E$5)+1,NA()),ROWS($B$5:E6)),COLUMNS($B$5:E6)),"")} -> MOROSOS
B7: {=IFERROR(INDEX(BD[],_xlfn.AGGREGATE(15,6,IF(BD[CLASIFICACIÓN]=$B$2,ROW(BD[CLASIFICACIÓN])-ROW('PT2 (FILTRAR)'!$E$5)+1,NA()),ROWS($B$5:B7)),COLUMNS($B$5:B7)),"")} -> 104-001-009 | C7: {=IFERROR(INDEX(BD[],_xlfn.AGGREGATE(15,6,IF(BD[CLASIFICACIÓN]=$B$2,ROW(BD[CLASIFICACIÓN])-ROW('PT2 (FILTRAR)'!$E$5)+1,NA()),ROWS($B$5:C7)),COLUMNS($B$5:C7)),"")} -> A-501 ALEJANDRO GOLDEBERG | D7: {=IFERROR(INDEX(BD[],_xlfn.AGGREGATE(15,6,IF(BD[CLASIFICACIÓN]=$B$2,ROW(BD[CLASIFICACIÓN])-ROW('PT2 (FILTRAR)'!$E$5)+1,NA()),ROWS($B$5:D7)),COLUMNS($B$5:D7)),"")} -> 25000 | E7: {=IFERROR(INDEX(BD[],_xlfn.AGGREGATE(15,6,IF(BD[CLASIFICACIÓN]=$B$2,ROW(BD[CLASIFICACIÓN])-ROW('PT2 (FILTRAR)'!$E$5)+1,NA()),ROWS($B$5:E7)),COLUMNS($B$5:E7)),"")} -> MOROSOS
B8: {=IFERROR(INDEX(BD[],_xlfn.AGGREGATE(15,6,IF(BD[CLASIFICACIÓN]=$B$2,ROW(BD[CLASIFICACIÓN])-ROW('PT2 (FILTRAR)'!$E$5)+1,NA()),ROWS($B$5:B8)),COLUMNS($B$5:B8)),"")} -> 104-001-043 | C8: {=IFERROR(INDEX(BD[],_xlfn.AGGREGATE(15,6,IF(BD[CLASIFICACIÓN]=$B$2,ROW(BD[CLASIFICACIÓN])-ROW('PT2 (FILTRAR)'!$E$5)+1,NA()),ROWS($B$5:C8)),COLUMNS($B$5:C8)),"")} -> A-2201 FREDELLE MUSTRI | D8: {=IFERROR(INDEX(BD[],_xlfn.AGGREGATE(15,6,IF(BD[CLASIFICACIÓN]=$B$2,ROW(BD[CLASIFICACIÓN])-ROW('PT2 (FILTRAR)'!$E$5)+1,NA()),ROWS($B$5:D8)),COLUMNS($B$5:D8)),"")} -> 28188 | E8: {=IFERROR(INDEX(BD[],_xlfn.AGGREGATE(15,6,IF(BD[CLASIFICACIÓN]=$B$2,ROW(BD[CLASIFICACIÓN])-ROW('PT2 (FILTRAR)'!$E$5)+1,NA()),ROWS($B$5:E8)),COLUMNS($B$5:E8)),"")} -> MOROSOS
B9: {=IFERROR(INDEX(BD[],_xlfn.AGGREGATE(15,6,IF(BD[CLASIFICACIÓN]=$B$2,ROW(BD[CLASIFICACIÓN])-ROW('PT2 (FILTRAR)'!$E$5)+1,NA()),ROWS($B$5:B9)),COLUMNS($B$5:B9)),"")} -> 104-003-038 | C9: {=IFERROR(INDEX(BD[],_xlfn.AGGREGATE(15,6,IF(BD[CLASIFICACIÓN]=$B$2,ROW(BD[CLASIFICACIÓN])-ROW('PT2 (FILTRAR)'!$E$5)+1,NA()),ROWS($B$5:C9)),COLUMNS($B$5:C9)),"")} -> O2-1906 JAIME SALEM | D9: {=IFERROR(INDEX(BD[],_xlfn.AGGREGATE(15,6,IF(BD[CLASIFICACIÓN]=$B$2,ROW(BD[CLASIFICACIÓN])-ROW('PT2 (FILTRAR)'!$E$5)+1,NA()),ROWS($B$5:D9)),COLUMNS($B$5:D9)),"")} -> 27153 | E9: {=IFERROR(INDEX(BD[],_xlfn.AGGREGATE(15,6,IF(BD[CLASIFICACIÓN]=$B$2,ROW(BD[CLASIFICACIÓN])-ROW('PT2 (FILTRAR)'!$E$5)+1,NA()),ROWS($B$5:E9)),COLUMNS($B$5:E9)),"")} -> MOROSOS
B10: {=IFERROR(INDEX(BD[],_xlfn.AGGREGATE(15,6,IF(BD[CLASIFICACIÓN]=$B$2,ROW(BD[CLASIFICACIÓN])-ROW('PT2 (FILTRAR)'!$E$5)+1,NA()),ROWS($B$5:B10)),COLUMNS($B$5:B10)),"")} -> 104-004-009 | C10: {=IFERROR(INDEX(BD[],_xlfn.AGGREGATE(15,6,IF(BD[CLASIFICACIÓN]=$B$2,ROW(BD[CLASIFICACIÓN])-ROW('PT2 (FILTRAR)'!$E$5)+1,NA()),ROWS($B$5:C10)),COLUMNS($B$5:C10)),"")} -> C1-507 ROSA TURQUIE | D10: {=IFERROR(INDEX(BD[],_xlfn.AGGREGATE(15,6,IF(BD[CLASIFICACIÓN]=$B$2,ROW(BD[CLASIFICACIÓN])-ROW('PT2 (FILTRAR)'!$E$5)+1,NA()),ROWS($B$5:D10)),COLUMNS($B$5:D10)),"")} -> 27888 | E10: {=IFERROR(INDEX(BD[],_xlfn.AGGREGATE(15,6,IF(BD[CLASIFICACIÓN]=$B$2,ROW(BD[CLASIFICACIÓN])-ROW('PT2 (FILTRAR)'!$E$5)+1,NA()),ROWS($B$5:E10)),COLUMNS($B$5:E10)),"")} -> MOROSOS
B11: {=IFERROR(INDEX(BD[],_xlfn.AGGREGATE(15,6,IF(BD[CLASIFICACIÓN]=$B$2,ROW(BD[CLASIFICACIÓN])-ROW('PT2 (FILTRAR)'!$E$5)+1,NA()),ROWS($B$5:B11)),COLUMNS($B$5:B11)),"")} -> 104-006-021 | C11: {=IFERROR(INDEX(BD[],_xlfn.AGGREGATE(15,6,IF(BD[CLASIFICACIÓN]=$B$2,ROW(BD[CLASIFICACIÓN])-ROW('PT2 (FILTRAR)'!$E$5)+1,NA()),ROWS($B$5:C11)),COLUMNS($B$5:C11)),"")} -> C3-1111 ESTHER ROMANO | D11: {=IFERROR(INDEX(BD[],_xlfn.AGGREGATE(15,6,IF(BD[CLASIFICACIÓN]=$B$2,ROW(BD[CLASIFICACIÓN])-ROW('PT2 (FILTRAR)'!$E$5)+1,NA()),ROWS($B$5:D11)),COLUMNS($B$5:D11)),"")} -> 27956 | E11: {=IFERROR(INDEX(BD[],_xlfn.AGGREGATE(15,6,IF(BD[CLASIFICACIÓN]=$B$2,ROW(BD[CLASIFICACIÓN])-ROW('PT2 (FILTRAR)'!$E$5)+1,NA()),ROWS($B$5:E11)),COLUMNS($B$5:E11)),"")} -> MOROSOS
B12: {=IFERROR(INDEX(BD[],_xlfn.AGGREGATE(15,6,IF(BD[CLASIFICACIÓN]=$B$2,ROW(BD[CLASIFICACIÓN])-ROW('PT2 (FILTRAR)'!$E$5)+1,NA()),ROWS($B$5:B12)),COLUMNS($B$5:B12)),"")} | C12: {=IFERROR(INDEX(BD[],_xlfn.AGGREGATE(15,6,IF(BD[CLASIFICACIÓN]=$B$2,ROW(BD[CLASIFICACIÓN])-ROW('PT2 (FILTRAR)'!$E$5)+1,NA()),ROWS($B$5:C12)),COLUMNS($B$5:C12)),"")} | D12: {=IFERROR(INDEX(BD[],_xlfn.AGGREGATE(15,6,IF(BD[CLASIFICACIÓN]=$B$2,ROW(BD[CLASIFICACIÓN])-ROW('PT2 (FILTRAR)'!$E$5)+1,NA()),ROWS($B$5:D12)),COLUMNS($B$5:D12)),"")} | E12: {=IFERROR(INDEX(BD[],_xlfn.AGGREGATE(15,6,IF(BD[CLASIFICACIÓN]=$B$2,ROW(BD[CLASIFICACIÓN])-ROW('PT2 (FILTRAR)'!$E$5)+1,NA()),ROWS($B$5:E12)),COLUMNS($B$5:E12)),"")}
B13: {=IFERROR(INDEX(BD[],_xlfn.AGGREGATE(15,6,IF(BD[CLASIFICACIÓN]=$B$2,ROW(BD[CLASIFICACIÓN])-ROW('PT2 (FILTRAR)'!$E$5)+1,NA()),ROWS($B$5:B13)),COLUMNS($B$5:B13)),"")} | C13: {=IFERROR(INDEX(BD[],_xlfn.AGGREGATE(15,6,IF(BD[CLASIFICACIÓN]=$B$2,ROW(BD[CLASIFICACIÓN])-ROW('PT2 (FILTRAR)'!$E$5)+1,NA()),ROWS($B$5:C13)),COLUMNS($B$5:C13)),"")} | D13: {=IFERROR(INDEX(BD[],_xlfn.AGGREGATE(15,6,IF(BD[CLASIFICACIÓN]=$B$2,ROW(BD[CLASIFICACIÓN])-ROW('PT2 (FILTRAR)'!$E$5)+1,NA()),ROWS($B$5:D13)),COLUMNS($B$5:D13)),"")} | E13: {=IFERROR(INDEX(BD[],_xlfn.AGGREGATE(15,6,IF(BD[CLASIFICACIÓN]=$B$2,ROW(BD[CLASIFICACIÓN])-ROW('PT2 (FILTRAR)'!$E$5)+1,NA()),ROWS($B$5:E13)),COLUMNS($B$5:E13)),"")}
B14: {=IFERROR(INDEX(BD[],_xlfn.AGGREGATE(15,6,IF(BD[CLASIFICACIÓN]=$B$2,ROW(BD[CLASIFICACIÓN])-ROW('PT2 (FILTRAR)'!$E$5)+1,NA()),ROWS($B$5:B14)),COLUMNS($B$5:B14)),"")} | C14: {=IFERROR(INDEX(BD[],_xlfn.AGGREGATE(15,6,IF(BD[CLASIFICACIÓN]=$B$2,ROW(BD[CLASIFICACIÓN])-ROW('PT2 (FILTRAR)'!$E$5)+1,NA()),ROWS($B$5:C14)),COLUMNS($B$5:C14)),"")} | D14: {=IFERROR(INDEX(BD[],_xlfn.AGGREGATE(15,6,IF(BD[CLASIFICACIÓN]=$B$2,ROW(BD[CLASIFICACIÓN])-ROW('PT2 (FILTRAR)'!$E$5)+1,NA()),ROWS($B$5:D14)),COLUMNS($B$5:D14)),"")} | E14: {=IFERROR(INDEX(BD[],_xlfn.AGGREGATE(15,6,IF(BD[CLASIFICACIÓN]=$B$2,ROW(BD[CLASIFICACIÓN])-ROW('PT2 (FILTRAR)'!$E$5)+1,NA()),ROWS($B$5:E14)),COLUMNS($B$5:E14)),"")}
B15: {=IFERROR(INDEX(BD[],_xlfn.AGGREGATE(15,6,IF(BD[CLASIFICACIÓN]=$B$2,ROW(BD[CLASIFICACIÓN])-ROW('PT2 (FILTRAR)'!$E$5)+1,NA()),ROWS($B$5:B15)),COLUMNS($B$5:B15)),"")} | C15: {=IFERROR(INDEX(BD[],_xlfn.AGGREGATE(15,6,IF(BD[CLASIFICACIÓN]=$B$2,ROW(BD[CLASIFICACIÓN])-ROW('PT2 (FILTRAR)'!$E$5)+1,NA()),ROWS($B$5:C15)),COLUMNS($B$5:C15)),"")} | D15: {=IFERROR(INDEX(BD[],_xlfn.AGGREGATE(15,6,IF(BD[CLASIFICACIÓN]=$B$2,ROW(BD[CLASIFICACIÓN])-ROW('PT2 (FILTRAR)'!$E$5)+1,NA()),ROWS($B$5:D15)),COLUMNS($B$5:D15)),"")} | E15: {=IFERROR(INDEX(BD[],_xlfn.AGGREGATE(15,6,IF(BD[CLASIFICACIÓN]=$B$2,ROW(BD[CLASIFICACIÓN])-ROW('PT2 (FILTRAR)'!$E$5)+1,NA()),ROWS($B$5:E15)),COLUMNS($B$5:E15)),"")}
B16: {=IFERROR(INDEX(BD[],_xlfn.AGGREGATE(15,6,IF(BD[CLASIFICACIÓN]=$B$2,ROW(BD[CLASIFICACIÓN])-ROW('PT2 (FILTRAR)'!$E$5)+1,NA()),ROWS($B$5:B16)),COLUMNS($B$5:B16)),"")} | C16: {=IFERROR(INDEX(BD[],_xlfn.AGGREGATE(15,6,IF(BD[CLASIFICACIÓN]=$B$2,ROW(BD[CLASIFICACIÓN])-ROW('PT2 (FILTRAR)'!$E$5)+1,NA()),ROWS($B$5:C16)),COLUMNS($B$5:C16)),"")} | D16: {=IFERROR(INDEX(BD[],_xlfn.AGGREGATE(15,6,IF(BD[CLASIFICACIÓN]=$B$2,ROW(BD[CLASIFICACIÓN])-ROW('PT2 (FILTRAR)'!$E$5)+1,NA()),ROWS($B$5:D16)),COLUMNS($B$5:D16)),"")} | E16: {=IFERROR(INDEX(BD[],_xlfn.AGGREGATE(15,6,IF(BD[CLASIFICACIÓN]=$B$2,ROW(BD[CLASIFICACIÓN])-ROW('PT2 (FILTRAR)'!$E$5)+1,NA()),ROWS($B$5:E16)),COLUMNS($B$5:E16)),"")}
... B271: {=IFERROR(INDEX(BD[],_xlfn.AGGREGATE(15,6,IF(BD[CLASIFICACIÓN]=$B$2,ROW(BD[CLASIFICACIÓN])-ROW('PT2 (FILTRAR)'!$E$5)+1,NA()),ROWS($B$5:B271)),COLUMNS($B$5:B271)),"")} | C271: {=IFERROR(INDEX(BD[],_xlfn.AGGREGATE(15,6,IF(BD[CLASIFICACIÓN]=$B$2,ROW(BD[CLASIFICACIÓN])-ROW('PT2 (FILTRAR)'!$E$5)+1,NA()),ROWS($B$5:C271)),COLUMNS($B$5:C271)),"")} | D271: {=IFERROR(INDEX(BD[],_xlfn.AGGREGATE(15,6,IF(BD[CLASIFICACIÓN]=$B$2,ROW(BD[CLASIFICACIÓN])-ROW('PT2 (FILTRAR)'!$E$5)+1,NA()),ROWS($B$5:D271)),COLUMNS($B$5:D271)),"")} | E271: {=IFERROR(INDEX(BD[],_xlfn.AGGREGATE(15,6,IF(BD[CLASIFICACIÓN]=$B$2,ROW(BD[CLASIFICACIÓN])-ROW('PT2 (FILTRAR)'!$E$5)+1,NA()),ROWS($B$5:E271)),COLUMNS($B$5:E271)),"")}
B272: TOTAL | C272: =+B2 -> MOROSOS | D272: =SUM(D5:D271) -> 203314

Sheet PT5
B2: DEUDA CORRIENTE
B4: CTA | C4: CONDOMINO | D4: =[1]!'@PERIODO[A]' -> Abril/2026 | E4: CLASIFICACIÓN
B5: {=IFERROR(INDEX(BD[],_xlfn.AGGREGATE(15,6,IF(BD[CLASIFICACIÓN]=$B$2,ROW(BD[CLASIFICACIÓN])-ROW('PT2 (FILTRAR)'!$E$5)+1,NA()),ROWS($B$5:B5)),COLUMNS($B$5:B5)),"")} -> 104-002-045 | C5: {=IFERROR(INDEX(BD[],_xlfn.AGGREGATE(15,6,IF(BD[CLASIFICACIÓN]=$B$2,ROW(BD[CLASIFICACIÓN])-ROW('PT2 (FILTRAR)'!$E$5)+1,NA()),ROWS($B$5:C5)),COLUMNS($B$5:C5)),"")} -> O1-2303 ISAAC HOP | D5: {=IFERROR(INDEX(BD[],_xlfn.AGGREGATE(15,6,IF(BD[CLASIFICACIÓN]=$B$2,ROW(BD[CLASIFICACIÓN])-ROW('PT2 (FILTRAR)'!$E$5)+1,NA()),ROWS($B$5:D5)),COLUMNS($B$5:D5)),"")} -> 13694 | E5: {=IFERROR(INDEX(BD[],_xlfn.AGGREGATE(15,6,IF(BD[CLASIFICACIÓN]=$B$2,ROW(BD[CLASIFICACIÓN])-ROW('PT2 (FILTRAR)'!$E$5)+1,NA()),ROWS($B$5:E5)),COLUMNS($B$5:E5)),"")} -> DEUDA CORRIENTE
B6: {=IFERROR(INDEX(BD[],_xlfn.AGGREGATE(15,6,IF(BD[CLASIFICACIÓN]=$B$2,ROW(BD[CLASIFICACIÓN])-ROW('PT2 (FILTRAR)'!$E$5)+1,NA()),ROWS($B$5:B6)),COLUMNS($B$5:B6)),"")} -> 104-004-013 | C6: {=IFERROR(INDEX(BD[],_xlfn.AGGREGATE(15,6,IF(BD[CLASIFICACIÓN]=$B$2,ROW(BD[CLASIFICACIÓN])-ROW('PT2 (FILTRAR)'!$E$5)+1,NA()),ROWS($B$5:C6)),COLUMNS($B$5:C6)),"")} -> C1-707 CLAUDIA CAMUS | D6: {=IFERROR(INDEX(BD[],_xlfn.AGGREGATE(15,6,IF(BD[CLASIFICACIÓN]=$B$2,ROW(BD[CLASIFICACIÓN])-ROW('PT2 (FILTRAR)'!$E$5)+1,NA()),ROWS($B$5:D6)),COLUMNS($B$5:D6)),"")} -> 13694 | E6: {=IFERROR(INDEX(BD[],_xlfn.AGGREGATE(15,6,IF(BD[CLASIFICACIÓN]=$B$2,ROW(BD[CLASIFICACIÓN])-ROW('PT2 (FILTRAR)'!$E$5)+1,NA()),ROWS($B$5:E6)),COLUMNS($B$5:E6)),"")} -> DEUDA CORRIENTE
B7: {=IFERROR(INDEX(BD[],_xlfn.AGGREGATE(15,6,IF(BD[CLASIFICACIÓN]=$B$2,ROW(BD[CLASIFICACIÓN])-ROW('PT2 (FILTRAR)'!$E$5)+1,NA()),ROWS($B$5:B7)),COLUMNS($B$5:B7)),"")} -> 104-003-051 | C7: {=IFERROR(INDEX(BD[],_xlfn.AGGREGATE(15,6,IF(BD[CLASIFICACIÓN]=$B$2,ROW(BD[CLASIFICACIÓN])-ROW('PT2 (FILTRAR)'!$E$5)+1,NA()),ROWS($B$5:C7)),COLUMNS($B$5:C7)),"")} -> O2-PH05 ABRAHAM CHEREM C | D7: {=IFERROR(INDEX(BD[],_xlfn.AGGREGATE(15,6,IF(BD[CLASIFICACIÓN]=$B$2,ROW(BD[CLASIFICACIÓN])-ROW('PT2 (FILTRAR)'!$E$5)+1,NA()),ROWS($B$5:D7)),COLUMNS($B$5:D7)),"")} -> 300 | E7: {=IFERROR(INDEX(BD[],_xlfn.AGGREGATE(15,6,IF(BD[CLASIFICACIÓN]=$B$2,ROW(BD[CLASIFICACIÓN])-ROW('PT2 (FILTRAR)'!$E$5)+1,NA()),ROWS($B$5:E7)),COLUMNS($B$5:E7)),"")} -> DEUDA CORRIENTE
B8: {=IFERROR(INDEX(BD[],_xlfn.AGGREGATE(15,6,IF(BD[CLASIFICACIÓN]=$B$2,ROW(BD[CLASIFICACIÓN])-ROW('PT2 (FILTRAR)'!$E$5)+1,NA()),ROWS($B$5:B8)),COLUMNS($B$5:B8)),"")} -> 104-004-050 | C8: {=IFERROR(INDEX(BD[],_xlfn.AGGREGATE(15,6,IF(BD[CLASIFICACIÓN]=$B$2,ROW(BD[CLASIFICACIÓN])-ROW('PT2 (FILTRAR)'!$E$5)+1,NA()),ROWS($B$5:C8)),COLUMNS($B$5:C8)),"")} -> C1-2508 SALOMON AMBE | D8: {=IFERROR(INDEX(BD[],_xlfn.AGGREGATE(15,6,IF(BD[CLASIFICACIÓN]=$B$2,ROW(BD[CLASIFICACIÓN])-ROW('PT2 (FILTRAR)'!$E$5)+1,NA()),ROWS($B$5:D8)),COLUMNS($B$5:D8)),"")} -> 13694 | E8: {=IFERROR(INDEX(BD[],_xlfn.AGGREGATE(15,6,IF(BD[CLASIFICACIÓN]=$B$2,ROW(BD[CLASIFICACIÓN])-ROW('PT2 (FILTRAR)'!$E$5)+1,NA()),ROWS($B$5:E8)),COLUMNS($B$5:E8)),"")} -> DEUDA CORRIENTE
B9: {=IFERROR(INDEX(BD[],_xlfn.AGGREGATE(15,6,IF(BD[CLASIFICACIÓN]=$B$2,ROW(BD[CLASIFICACIÓN])-ROW('PT2 (FILTRAR)'!$E$5)+1,NA()),ROWS($B$5:B9)),COLUMNS($B$5:B9)),"")} -> 104-003-043 | C9: {=IFERROR(INDEX(BD[],_xlfn.AGGREGATE(15,6,IF(BD[CLASIFICACIÓN]=$B$2,ROW(BD[CLASIFICACIÓN])-ROW('PT2 (FILTRAR)'!$E$5)+1,NA()),ROWS($B$5:C9)),COLUMNS($B$5:C9)),"")} -> O2-2205 JORGE WATTY | D9: {=IFERROR(INDEX(BD[],_xlfn.AGGREGATE(15,6,IF(BD[CLASIFICACIÓN]=$B$2,ROW(BD[CLASIFICACIÓN])-ROW('PT2 (FILTRAR)'!$E$5)+1,NA()),ROWS($B$5:D9)),COLUMNS($B$5:D9)),"")} -> 500 | E9: {=IFERROR(INDEX(BD[],_xlfn.AGGREGATE(15,6,IF(BD[CLASIFICACIÓN]=$B$2,ROW(BD[CLASIFICACIÓN])-ROW('PT2 (FILTRAR)'!$E$5)+1,NA()),ROWS($B$5:E9)),COLUMNS($B$5:E9)),"")} -> DEUDA CORRIENTE
